File: Chassis/Inserts testing/insert testing with CL/inserts_testing_CloseOUTS1_20250926_114147_1.csv
Results Table 2,,,,,,,,
,Specimen label,Rate 1,Fixture separation,Geometry,Length,Thickness,Width,Diameter
,,(mm/min),(mm),,(mm),(mm),(mm),(mm)
1,speciman 1 closeout,0.05,101.6,Rectangular,101.6,12.7,75.18,
2,speciman 1 closeout,0.05,101.6,Rectangular,101.6,12.7,75.18,
3,speciman 1 closeout,2,101.6,Rectangular,101.6,12.7,75.18,
,,,,,,,,
1,Time,Displacement,Force,,,,,
,(s),(mm),(N),,,,,
,0,0,-0.0007,,6455.6001,1451.348943,,
,0.02,0,-0.1183,,Time,Displacement,Force,
,0.04,0,-0.2594,,(s),(mm),(N),
,0.06,0,-0.2404,,0,0,-13.3664,
,0.08,0,-0.1598,,0.02,0.0001,-13.3043,
,0.1,0,-0.0902,,0.04,0.0004,-13.1025,
,0.12,0,-0.0075,,0.06,0.001,-12.8594,
,0.14,0,0.0101,,0.08,0.0017,-12.8083,
,0.16,0,0.0756,,0.1,0.0023,-12.8886,
,0.18,0,0.0325,,0.12,0.003,-13.0476,
,0.2,0,-0.1501,,0.14,0.0036,-13.02,
,0.22,0.0001,-0.1684,,0.16,0.0043,-13.0207,
,0.24,0.0001,-0.2021,,0.18,0.005,-12.9918,
,0.26,0.0001,-0.0424,,0.2,0.0057,-13.0758,
,0.28,0.0001,-0.0629,,0.22,0.0063,-13.022,
,0.3,0.0001,-0.1932,,0.24,0.0069,-12.9156,
,0.32,0.0001,-0.1782,,0.26,0.0076,-12.9684,
,0.34,0.0001,-0.2821,,0.28,0.0082,-12.9266,
,0.36,0.0001,-0.2698,,0.3,0.0089,-13.0063,
,0.38,0.0001,-0.0104,,0.32,0.0096,-13.0023,
,0.4,0.0001,0.0024,,0.34,0.0103,-13.0889,
,0.42,0.0001,-0.2055,,0.36,0.011,-13.0511,
,0.44,0.0002,-0.3507,,0.38,0.0116,-13.1202,
,0.46,0.0002,-0.3826,,0.4,0.0123,-13.0638,
,0.48,0.0002,-0.1547,,0.42,0.0129,-13.1364,
,0.5,0.0002,-0.053,,0.44,0.0136,-13.1988,
,0.52,0.0002,0.0689,,0.46,0.0144,-13.0737,
,0.54,0.0002,0.0642,,0.48,0.0151,-12.9329,
,0.56,0.0002,0.0317,,0.5,0.0157,-12.8998,
,0.58,0.0003,-0.0184,,0.52,0.0164,-12.984,
,0.6,0.0003,0.0952,,0.54,0.017,-13.0332,
,0.62,0.0003,-0.0679,,0.56,0.0176,-13.188,
,0.64,0.0003,-0.2095,,0.58,0.0183,-13.1594,
,0.66,0.0004,-0.0784,,0.6,0.019,-13.0545,
,0.68,0.0004,-0.0587,,0.62,0.0198,-13.116,
,0.7,0.0004,-0.0962,,0.64,0.0204,-13.1901,
,0.72,0.0004,-0.0633,,0.66,0.021,-13.2565,
,0.74,0.0005,-0.0512,,0.68,0.0216,-13.164,
,0.76,0.0005,0.027,,0.7,0.0222,-13.0374,
,0.78,0.0005,0.0562,,0.72,0.0229,-12.9553,
,0.8,0.0005,0.0971,,0.74,0.0236,-12.9407,
,0.82,0.0006,0.1111,,0.76,0.0244,-12.9423,
,0.84,0.0006,0.0998,,0.78,0.0251,-13.0946,
,0.86,0.0006,-0.0148,,0.8,0.0257,-13.1398,
,0.88,0.0006,0.0098,,0.82,0.0263,-13.0404,
,0.9,0.0006,0.1374,,0.84,0.027,-12.9726,
,0.92,0.0007,0.1163,,0.86,0.0276,-12.9203,
,0.94,0.0007,-0.115,,0.88,0.0283,-12.8987,
,0.96,0.0007,-0.142,,0.9,0.0291,-13.0538,
,0.98,0.0007,-0.0304,,0.92,0.0298,-13.2118,
,1,0.0008,-0.1457,,0.94,0.0304,-13.1784,
,1.02,0.0008,-0.0963,,0.96,0.031,-13.1114,
,1.04,0.0008,0.0721,,0.98,0.0316,-13.0858,
,1.06,0.0008,0.1098,,1,0.0322,-13.0999,
,1.08,0.0008,0.1213,,1.02,0.0329,-12.8815,
,1.1,0.0008,0.1117,,1.04,0.0336,-12.8554,
,1.12,0.0009,0.051,,1.06,0.0343,-12.7405,
,1.14,0.0009,-0.0729,,1.08,0.0349,-12.5731,
,1.16,0.0009,-0.0686,,1.1,0.0356,-12.4745,
,1.18,0.0009,0.0185,,1.12,0.0362,-12.603,
,1.2,0.0009,-0.0304,,1.14,0.0368,-12.5818,
,1.22,0.001,-0.0048,,1.16,0.0375,-12.4764,
,1.24,0.001,0.0327,,1.18,0.0383,-12.6151,
,1.26,0.001,0.0642,,1.2,0.039,-12.662,
,1.28,0.001,0.0818,,1.22,0.0397,-12.7441,
,1.3,0.001,0.1072,,1.24,0.0404,-12.7336,
,1.32,0.0011,0.0139,,1.26,0.041,-12.7152,
,1.34,0.0011,-0.0558,,1.28,0.0416,-12.6182,
,1.36,0.0011,-0.102,,1.3,0.0423,-12.6697,
,1.38,0.0011,-0.0434,,1.32,0.043,-12.5012,
,1.4,0.0011,-0.0071,,1.34,0.0437,-12.4678,
,1.42,0.0011,0.1597,,1.36,0.0444,-12.409,
,1.44,0.0012,0.0691,,1.38,0.045,-12.54,
,1.46,0.0012,0.1029,,1.4,0.0456,-12.6232,
,1.48,0.0012,0.0117,,1.42,0.0462,-12.4856,
,1.5,0.0012,-0.0228,,1.44,0.0468,-12.264,
,1.52,0.0012,0.0193,,1.46,0.0475,-12.2421,
,1.54,0.0012,0.0988,,1.48,0.0483,-12.4208,
,1.56,0.0013,0.2144,,1.5,0.049,-12.4793,
,1.58,0.0013,0.1343,,1.52,0.0497,-12.4361,
,1.6,0.0013,0.1174,,1.54,0.0503,-12.3719,
,1.62,0.0013,0.0352,,1.56,0.0509,-12.4064,
,1.64,0.0013,0.0705,,1.58,0.0515,-12.4334,
,1.66,0.0014,0.1147,,1.6,0.0522,-12.3726,
,1.68,0.0014,0.0534,,1.62,0.0529,-12.336,
,1.7,0.0014,-0.0028,,1.64,0.0536,-12.1999,
,1.72,0.0014,-0.1594,,1.66,0.0543,-12.1479,
,1.74,0.0014,-0.0877,,1.68,0.0549,-12.1763,
,1.76,0.0014,-0.1176,,1.7,0.0555,-12.1923,
,1.78,0.0015,-0.1173,,1.72,0.0562,-12.3206,
,1.8,0.0015,-0.1375,,1.74,0.0568,-12.2847,
,1.82,0.0015,-0.0059,,1.76,0.0576,-12.2924,
,1.84,0.0015,0.0598,,1.78,0.0583,-12.2583,
,1.86,0.0015,0.1248,,1.8,0.059,-12.3157,
,1.88,0.0015,0.0927,,1.82,0.0596,-12.4189,
,1.9,0.0016,0.04,,1.84,0.0602,-12.3609,
,1.92,0.0016,0.0333,,1.86,0.0609,-12.3424,
,1.94,0.0016,0.0218,,1.88,0.0615,-12.2601,
,1.96,0.0016,0.0528,,1.9,0.0622,-12.1248,
,1.98,0.0016,0.1623,,1.92,0.063,-12.0646,
,2,0.0016,0.1239,,1.94,0.0637,-12.0363,
,2.02,0.0017,0.0085,,1.96,0.0643,-11.9427,
,2.04,0.0017,-0.0855,,1.98,0.0649,-12.0276,
,2.06,0.0017,0.034,,2,0.0656,-12.1197,
,2.08,0.0017,0.0257,,2.02,0.0662,-12.0995,
,2.1,0.0017,0.0529,,2.04,0.0669,-12.1074,
,2.12,0.0017,0.3136,,2.06,0.0677,-12.0678,
,2.14,0.0017,0.2785,,2.08,0.0684,-12.063,
,2.16,0.0018,0.1197,,2.1,0.069,-12.0829,
,2.18,0.0018,0.0664,,2.12,0.0697,-12.1134,
,2.2,0.0018,0.0339,,2.14,0.0703,-12.1315,
,2.22,0.0018,-0.0506,,2.16,0.0709,-12.0319,
,2.24,0.0018,-0.2304,,2.18,0.0716,-11.8786,
,2.26,0.0019,-0.1894,,2.2,0.0723,-11.9072,
,2.28,0.0019,-0.0782,,2.22,0.0731,-11.9323,
,2.3,0.0019,-0.0531,,2.24,0.0737,-11.8008,
,2.32,0.0019,0.0098,,2.26,0.0744,-11.8052,
,2.34,0.0019,-0.0007,,2.28,0.075,-11.842,
,2.36,0.0019,0.0117,,2.3,0.0756,-11.8217,
,2.38,0.002,0.1188,,2.32,0.0763,-11.9202,
,2.4,0.002,0.2537,,2.34,0.077,-11.7779,
,2.42,0.002,0.1347,,2.36,0.0778,-11.84,
,2.44,0.002,0.036,,2.38,0.0784,-11.8053,
,2.46,0.002,-0.0016,,2.4,0.0791,-11.6826,
,2.48,0.002,0.1023,,2.42,0.0796,-11.6651,
,2.5,0.0021,0.0046,,2.44,0.0802,-11.6721,
,2.52,0.0021,-0.2394,,2.46,0.0809,-11.7371,
,2.54,0.0021,-0.1528,,2.48,0.0816,-11.6501,
,2.56,0.0021,-0.0977,,2.5,0.0823,-11.517,
,2.58,0.0021,-0.2759,,2.52,0.083,-11.5026,
,2.6,0.0021,-0.161,,2.54,0.0836,-11.4514,
,2.62,0.0022,0.0369,,2.56,0.0843,-11.5674,
,2.64,0.0022,0.1366,,2.58,0.0849,-11.7234,
,2.66,0.0022,0.0251,,2.6,0.0856,-11.5756,
,2.68,0.0022,-0.0537,,2.62,0.0863,-11.542,
,2.7,0.0022,-0.1327,,2.64,0.0871,-11.2982,
,2.72,0.0022,-0.0369,,2.66,0.0878,-11.2803,
,2.74,0.0022,-0.0345,,2.68,0.0884,-11.3573,
,2.76,0.0023,0.0142,,2.7,0.089,-11.3538,
,2.78,0.0023,-0.0363,,2.72,0.0896,-11.4545,
,2.8,0.0023,-0.0158,,2.74,0.0903,-11.356,
,2.82,0.0023,-0.0832,,2.76,0.091,-11.412,
,2.84,0.0023,-0.0911,,2.78,0.0917,-11.583,
,2.86,0.0023,-0.0741,,2.8,0.0924,-11.5076,
,2.88,0.0024,-0.0263,,2.82,0.093,-11.6174,
,2.9,0.0024,0.071,,2.84,0.0936,-11.6013,
,2.92,0.0024,-0.0074,,2.86,0.0942,-11.4761,
,2.94,0.0024,0.105,,2.88,0.0949,-11.4338,
,2.96,0.0024,0.1095,,2.9,0.0955,-11.5488,
,2.98,0.0024,-0.0598,,2.92,0.0963,-11.6598,
,3,0.0025,-0.0771,,2.94,0.097,-11.5622,
,3.02,0.0025,0.0323,,2.96,0.0977,-11.4545,
,3.04,0.0025,-0.0007,,2.98,0.0984,-11.4491,
,3.06,0.0025,0.0318,,3,0.099,-11.5851,
,3.08,0.0025,0.0447,,3.02,0.0996,-11.6754,
,3.1,0.0025,-0.0482,,3.04,0.1003,-11.4275,
,3.12,0.0026,-0.0343,,3.06,0.101,-11.4721,
,3.14,0.0026,0.0684,,3.08,0.1017,-11.5789,
,3.16,0.0026,0.1712,,3.1,0.1024,-11.6889,
,3.18,0.0026,0.1423,,3.12,0.103,-11.719,
,3.2,0.0026,0.0292,,3.14,0.1036,-11.5527,
,3.22,0.0026,-0.1104,,3.16,0.1042,-11.4889,
,3.24,0.0027,-0.0675,,3.18,0.1048,-11.4613,
,3.26,0.0027,-0.1009,,3.2,0.1055,-11.3676,
,3.28,0.0027,-0.0244,,3.22,0.1062,-11.4215,
,3.3,0.0027,-0.0744,,3.24,0.1069,-11.5229,
,3.32,0.0027,-0.2827,,3.26,0.1076,-11.4775,
,3.34,0.0027,-0.1338,,3.28,0.1082,-11.4507,
,3.36,0.0028,-0.0177,,3.3,0.1088,-11.537,
,3.38,0.0028,0.0457,,3.32,0.1095,-11.4225,
,3.4,0.0028,0.1277,,3.34,0.1102,-11.4601,
,3.42,0.0028,0.1148,,3.36,0.1109,-11.5546,
,3.44,0.0028,0.0678,,3.38,0.1116,-11.6073,
,3.46,0.0028,-0.1303,,3.4,0.1123,-11.5291,
,3.48,0.0029,-0.1591,,3.42,0.1129,-11.4297,
,3.5,0.0029,0.0676,,3.44,0.1136,-11.3428,
,3.52,0.0029,0.085,,3.46,0.1142,-11.4234,
,3.54,0.0029,-0.0918,,3.48,0.1149,-11.5974,
,3.56,0.0029,-0.17,,3.5,0.1156,-11.5553,
,3.58,0.0029,-0.1688,,3.52,0.1164,-11.3064,
,3.6,0.003,-0.1524,,3.54,0.117,-11.3067,
,3.62,0.003,-0.0258,,3.56,0.1177,-11.4672,
,3.64,0.003,-0.0198,,3.58,0.1183,-11.5682,
,3.66,0.003,0.0007,,3.6,0.1189,-11.3907,
,3.68,0.003,-0.005,,3.62,0.1195,-11.4361,
,3.7,0.003,-0.0707,,3.64,0.1203,-11.5145,
,3.72,0.0031,0.0119,,3.66,0.121,-11.3918,
,3.74,0.0031,-0.1212,,3.68,0.1217,-11.4455,
,3.76,0.0031,-0.0952,,3.7,0.1223,-11.5418,
,3.78,0.0031,0.037,,3.72,0.1229,-11.5431,
,3.8,0.0031,0.1125,,3.74,0.1236,-11.5673,
,3.82,0.0031,0.0835,,3.76,0.1242,-11.6159,
,3.84,0.0032,-0.0961,,3.78,0.1249,-11.5351,
,3.86,0.0032,-0.1064,,3.8,0.1257,-11.4983,
,3.88,0.0032,-0.1245,,3.82,0.1264,-11.3719,
,3.9,0.0032,0.0123,,3.84,0.1271,-11.2806,
,3.92,0.0032,0.1882,,3.86,0.1277,-11.4102,
,3.94,0.0033,0.1624,,3.88,0.1283,-11.5344,
,3.96,0.0033,0.1356,,3.9,0.1289,-11.5273,
,3.98,0.0033,0.1088,,3.92,0.1296,-11.6159,
,4,0.0033,0.0181,,3.94,0.1303,-11.6256,
,4.02,0.0033,0.0108,,3.96,0.131,-11.4467,
,4.04,0.0033,0.0256,,3.98,0.1317,-11.4791,
,4.06,0.0034,0.1628,,4,0.1323,-11.6009,
,4.08,0.0034,0.1868,,4.02,0.1329,-11.7148,
,4.1,0.0034,-0.0005,,4.04,0.1336,-11.6124,
,4.12,0.0034,0.0226,,4.06,0.1342,-11.7115,
,4.14,0.0034,-0.0433,,4.08,0.135,-11.6716,
,4.16,0.0034,0.0199,,4.1,0.1357,-11.5686,
,4.18,0.0035,0.1072,,4.12,0.1364,-11.5572,
,4.2,0.0035,0.124,,4.14,0.137,-11.5954,
,4.22,0.0035,0.1954,,4.16,0.1377,-11.5318,
,4.24,0.0035,0.1037,,4.18,0.1383,-11.4525,
,4.26,0.0035,-0.1583,,4.2,0.1389,-11.4117,
,4.28,0.0035,-0.0864,,4.22,0.1396,-11.4103,
,4.3,0.0036,-0.0067,,4.24,0.1403,-11.4675,
,4.32,0.0036,0.0344,,4.26,0.141,-11.2853,
,4.34,0.0036,0.0172,,4.28,0.1417,-11.2501,
,4.36,0.0036,0.0504,,4.3,0.1423,-11.3628,
,4.38,0.0036,-0.0627,,4.32,0.1429,-11.3903,
,4.4,0.0036,-0.1232,,4.34,0.1436,-11.4544,
,4.42,0.0037,0.0254,,4.36,0.1443,-11.5462,
,4.44,0.0037,0.0274,,4.38,0.145,-11.5518,
,4.46,0.0037,0.1456,,4.4,0.1458,-11.424,
,4.48,0.0037,0.1914,,4.42,0.1464,-11.2721,
,4.5,0.0037,0.2183,,4.44,0.147,-11.3004,
,4.52,0.0037,0.0833,,4.46,0.1477,-11.364,
,4.54,0.0038,0.0062,,4.48,0.1483,-11.4316,
,4.56,0.0038,-0.1014,,4.5,0.149,-11.4334,
,4.58,0.0038,-0.2444,,4.52,0.1497,-11.581,
,4.6,0.0038,-0.1533,,4.54,0.1504,-11.5668,
,4.62,0.0038,0.0389,,4.56,0.151,-11.5085,
,4.64,0.0038,0.1253,,4.58,0.1517,-11.4853,
,4.66,0.0039,-0.027,,4.6,0.1523,-11.5887,
,4.68,0.0039,0.0473,,4.62,0.1529,-11.5532,
,4.7,0.0039,0.1298,,4.64,0.1535,-11.43,
,4.72,0.0039,0.1024,,4.66,0.1542,-11.4662,
,4.74,0.0039,0.0012,,4.68,0.1549,-11.54,
,4.76,0.0039,-0.0331,,4.7,0.1556,-11.4815,
,4.78,0.004,-0.0346,,4.72,0.1563,-11.5023,
,4.8,0.004,-0.1027,,4.74,0.1569,-11.3789,
,4.82,0.004,-0.1024,,4.76,0.1576,-11.2372,
,4.84,0.004,0.0128,,4.78,0.1582,-11.2245,
,4.86,0.004,0.0761,,4.8,0.1589,-11.3257,
,4.88,0.0041,0.0476,,4.82,0.1597,-11.3683,
,4.9,0.0041,-0.0298,,4.84,0.1604,-11.2619,
,4.92,0.0041,-0.0688,,4.86,0.161,-11.2845,
,4.94,0.0041,-0.0979,,4.88,0.1616,-11.2653,
,4.96,0.0041,0.0065,,4.9,0.1622,-11.3731,
,4.98,0.0041,0.0754,,4.92,0.1629,-11.3768,
,5,0.0042,-0.0038,,4.94,0.1636,-11.351,
,5.02,0.0042,-0.0826,,4.96,0.1643,-11.2703,
,5.04,0.0042,0.0309,,4.98,0.165,-11.3254,
,5.06,0.0042,-0.0161,,5,0.1656,-11.1754,
,5.08,0.0042,0.0848,,5.02,0.1663,-11.0657,
,5.1,0.0043,0.0634,,5.04,0.1669,-11.1375,
,5.12,0.0043,-0.0828,,5.06,0.1675,-11.2535,
,5.14,0.0043,-0.0171,,5.08,0.1682,-11.359,
,5.16,0.0043,0.0502,,5.1,0.1689,-11.3312,
,5.18,0.0043,0.1837,,5.12,0.1696,-11.2889,
,5.2,0.0043,0.1651,,5.14,0.1703,-11.274,
,5.22,0.0044,0.0629,,5.16,0.171,-11.1029,
,5.24,0.0044,-0.0605,,5.18,0.1716,-11.1004,
,5.26,0.0044,-0.0639,,5.2,0.1722,-11.2264,
,5.28,0.0044,-0.0732,,5.22,0.1729,-11.2499,
,5.3,0.0044,-0.1697,,5.24,0.1736,-11.2767,
,5.32,0.0044,-0.2593,,5.26,0.1744,-11.1622,
,5.34,0.0045,0.0094,,5.28,0.1751,-11.0966,
,5.36,0.0045,0.2395,,5.3,0.1757,-11.0306,
,5.38,0.0045,0.0694,,5.32,0.1763,-11.1258,
,5.4,0.0045,0.0439,,5.34,0.1769,-11.1644,
,5.42,0.0045,0.0562,,5.36,0.1775,-11.0625,
,5.44,0.0045,0.0715,,5.38,0.1782,-11.1229,
,5.46,0.0046,0.1128,,5.4,0.1789,-11.0499,
,5.48,0.0046,0.0324,,5.42,0.1796,-11.0824,
,5.5,0.0046,0.0425,,5.44,0.1803,-11.1479,
,5.52,0.0046,-0.0003,,5.46,0.1809,-11.2649,
,5.54,0.0046,-0.0272,,5.48,0.1815,-11.2133,
,5.56,0.0046,-0.1335,,5.5,0.1822,-11.0975,
,5.58,0.0047,-0.237,,5.52,0.1829,-11.0017,
,5.6,0.0047,-0.0999,,5.54,0.1836,-10.9661,
,5.62,0.0047,-0.1463,,5.56,0.1844,-10.956,
,5.64,0.0047,-0.1589,,5.58,0.1851,-11.035,
,5.66,0.0047,-0.0581,,5.6,0.1857,-11.0237,
,5.68,0.0047,-0.0344,,5.62,0.1863,-10.9682,
,5.7,0.0048,-0.0975,,5.64,0.187,-11.0721,
,5.72,0.0048,0.0101,,5.66,0.1876,-11.0836,
,5.74,0.0048,-0.015,,5.68,0.1884,-11.0177,
,5.76,0.0048,-0.0753,,5.7,0.1891,-10.8321,
,5.78,0.0048,0.0975,,5.72,0.1897,-10.7909,
,5.8,0.0049,0.1262,,5.74,0.1903,-10.8083,
,5.82,0.0049,0.1058,,5.76,0.191,-10.8928,
,5.84,0.0049,0.0763,,5.78,0.1916,-10.889,
,5.86,0.0049,0.009,,5.8,0.1923,-10.8787,
,5.88,0.0049,0.1239,,5.82,0.193,-10.7203,
,5.9,0.0049,0.1709,,5.84,0.1937,-10.6921,
,5.92,0.005,0.1991,,5.86,0.1944,-10.6697,
,5.94,0.005,0.1387,,5.88,0.1951,-10.5868,
,5.96,0.005,0.2002,,5.9,0.1957,-10.8091,
,5.98,0.005,0.1724,,5.92,0.1963,-10.8847,
,6,0.005,0.0552,,5.94,0.1969,-10.9238,
,6.02,0.005,-0.0518,,5.96,0.1976,-10.8093,
,6.04,0.0051,0.0287,,5.98,0.1984,-10.674,
,6.06,0.0051,0.0133,,6,0.1991,-10.532,
,6.08,0.0051,-0.1319,,6.02,0.1997,-10.5643,
,6.1,0.0051,-0.0805,,6.04,0.2003,-10.5455,
,6.12,0.0051,-0.0029,,6.06,0.201,-10.7202,
,6.14,0.0051,-0.1017,,6.08,0.2016,-10.6822,
,6.16,0.0052,0.0263,,6.1,0.2023,-10.5122,
,6.18,0.0052,0.0872,,6.12,0.203,-10.394,
,6.2,0.0052,0.2738,,6.14,0.2037,-10.2695,
,6.22,0.0052,0.1108,,6.16,0.2044,-10.1607,
,6.24,0.0052,-0.071,,6.18,0.205,-10.3379,
,6.26,0.0052,-0.1092,,6.2,0.2056,-10.4416,
,6.28,0.0053,0.0419,,6.22,0.2062,-10.4234,
,6.3,0.0053,0.031,,6.24,0.2069,-10.4189,
,6.32,0.0053,0.0047,,6.26,0.2076,-10.318,
,6.34,0.0053,-0.0073,,6.28,0.2083,-10.1843,
,6.36,0.0053,0.0658,,6.3,0.209,-10.1419,
,6.38,0.0053,0.0336,,6.32,0.2096,-10.269,
,6.4,0.0054,-0.0967,,6.34,0.2102,-10.3166,
,6.42,0.0054,-0.1079,,6.36,0.2109,-10.2687,
,6.44,0.0054,-0.0316,,6.38,0.2115,-10.1529,
,6.46,0.0054,0.0133,,6.4,0.2123,-10.063,
,6.48,0.0054,-0.0365,,6.42,0.213,-10.0721,
,6.5,0.0055,-0.088,,6.44,0.2137,-9.9623,
,6.52,0.0055,-0.0495,,6.46,0.2143,-9.8795,
,6.54,0.0055,0.0763,,6.48,0.2149,-9.9535,
,6.56,0.0055,0.1467,,6.5,0.2156,-9.9459,
,6.58,0.0055,0.1334,,6.52,0.2162,-9.8618,
,6.6,0.0055,0.0485,,6.54,0.2169,-9.711,
,6.62,0.0056,0.0072,,6.56,0.2177,-9.6677,
,6.64,0.0056,0.011,,6.58,0.2184,-9.6651,
,6.66,0.0056,0.0237,,6.6,0.219,-9.4985,
,6.68,0.0056,0.0096,,6.62,0.2196,-9.3986,
,6.7,0.0056,-0.1099,,6.64,0.2202,-9.4077,
,6.72,0.0056,-0.2018,,6.66,0.2209,-9.4467,
,6.74,0.0057,-0.1698,,6.68,0.2216,-9.5722,
,6.76,0.0057,-0.0287,,6.7,0.2223,-9.5353,
,6.78,0.0057,0.0462,,6.72,0.223,-9.3381,
,6.8,0.0057,-0.0395,,6.74,0.2237,-9.1676,
,6.82,0.0057,0.007,,6.76,0.2243,-9.1025,
,6.84,0.0057,0.0827,,6.78,0.2249,-9.2416,
,6.86,0.0058,-0.0284,,6.8,0.2255,-9.3947,
,6.88,0.0058,-0.193,,6.82,0.2262,-9.3197,
,6.9,0.0058,-0.1695,,6.84,0.2268,-9.0761,
,6.92,0.0058,-0.0395,,6.86,0.2276,-8.9439,
,6.94,0.0058,-0.0962,,6.88,0.2282,-8.878,
,6.96,0.0058,-0.1672,,6.9,0.2289,-8.6972,
,6.98,0.0059,-0.1773,,6.92,0.2295,-8.5195,
,7,0.0059,-0.0856,,6.94,0.2302,-8.5218,
,7.02,0.0059,0.0046,,6.96,0.2309,-8.369,
,7.04,0.0059,0.0649,,6.98,0.2316,-8.0592,
,7.06,0.0059,0.1143,,7,0.2323,-7.944,
,7.08,0.0059,0.0923,,7.02,0.233,-7.7387,
,7.1,0.006,-0.026,,7.04,0.2337,-7.6284,
,7.12,0.006,0.0291,,7.06,0.2343,-7.443,
,7.14,0.006,-0.0789,,7.08,0.2349,-7.4001,
,7.16,0.006,-0.2599,,7.1,0.2356,-7.311,
,7.18,0.006,-0.241,,7.12,0.2362,-7.223,
,7.2,0.006,-0.0501,,7.14,0.2369,-7.18,
,7.22,0.0061,0.0607,,7.16,0.2376,-6.9587,
,7.24,0.0061,0.1094,,7.18,0.2383,-6.6609,
,7.26,0.0061,0.1914,,7.2,0.2389,-6.3688,
,7.28,0.0061,-0.0584,,7.22,0.2395,-6.2441,
,7.3,0.0061,-0.1042,,7.24,0.2402,-5.9362,
,7.32,0.0061,-0.0586,,7.26,0.2409,-5.5258,
,7.34,0.0062,-0.005,,7.28,0.2416,-5.0032,
,7.36,0.0062,0.0053,,7.3,0.2424,-4.3723,
,7.38,0.0062,0.0321,,7.32,0.2431,-3.9832,
,7.4,0.0062,-0.0247,,7.34,0.2437,-3.587,
,7.42,0.0062,0.0394,,7.36,0.2443,-3.3007,
,7.44,0.0062,-0.0401,,7.38,0.245,-2.7883,
,7.46,0.0063,-0.0602,,7.4,0.2456,-2.3379,
,7.48,0.0063,0.0601,,7.42,0.2464,-1.6623,
,7.5,0.0063,0.0806,,7.44,0.2471,-1.2094,
,7.52,0.0063,0.2016,,7.46,0.2478,-0.6126,
,7.54,0.0063,0.0608,,7.48,0.2484,-0.1957,
,7.56,0.0063,-0.0831,,7.5,0.249,0.2981,
,7.58,0.0064,0.0306,,7.52,0.2496,0.8369,
,7.6,0.0064,0.1486,,7.54,0.2502,1.5065,
,7.62,0.0064,0.2756,,7.56,0.2509,2.3209,
,7.64,0.0064,0.205,,7.58,0.2516,2.946,
,7.66,0.0064,0.0832,,7.6,0.2523,3.6398,
,7.68,0.0064,0.0392,,7.62,0.253,4.2483,
,7.7,0.0065,-0.0337,,7.64,0.2536,4.8414,
,7.72,0.0065,0.0534,,7.66,0.2542,5.3881,
,7.74,0.0065,0.1361,,7.68,0.2549,5.9542,
,7.76,0.0065,0.0541,,7.7,0.2556,6.4862,
,7.78,0.0065,-0.0352,,7.72,0.2563,7.0728,
,7.8,0.0065,-0.2108,,7.74,0.257,7.6098,
,7.82,0.0066,-0.2373,,7.76,0.2577,8.4155,
,7.84,0.0066,-0.1021,,7.78,0.2583,8.9055,
,7.86,0.0066,0.0768,,7.8,0.259,9.3947,
,7.88,0.0066,0.1808,,7.82,0.2596,10.023,
,7.9,0.0066,0.1996,,7.84,0.2603,10.5756,
,7.92,0.0066,0.0578,,7.86,0.261,11.2342,
,7.94,0.0067,0.0043,,7.88,0.2617,11.9929,
,7.96,0.0067,-0.1277,,7.9,0.2624,12.6528,
,7.98,0.0067,-0.0725,,7.92,0.263,13.1547,
,8,0.0067,-0.0834,,7.94,0.2636,13.5368,
,8.02,0.0067,-0.01,,7.96,0.2642,14.2108,
,8.04,0.0067,-0.0321,,7.98,0.2649,14.8156,
,8.06,0.0068,-0.1231,,8,0.2656,15.4065,
,8.08,0.0068,-0.089,,8.02,0.2664,15.9258,
,8.1,0.0068,-0.095,,8.04,0.267,16.3338,
,8.12,0.0068,-0.0948,,8.06,0.2677,16.623,
,8.14,0.0068,-0.0049,,8.08,0.2683,17.0403,
,8.16,0.0068,0.1237,,8.1,0.2689,17.6296,
,8.18,0.0069,-0.2002,,8.12,0.2696,18.062,
,8.2,0.0069,-0.2032,,8.14,0.2703,18.6776,
,8.22,0.0069,-0.1175,,8.16,0.271,19.114,
,8.24,0.0069,-0.1448,,8.18,0.2717,19.5593,
,8.26,0.0069,-0.0988,,8.2,0.2724,20.0401,
,8.28,0.0069,-0.0325,,8.22,0.273,20.4972,
,8.3,0.007,0.0178,,8.24,0.2736,20.8217,
,8.32,0.007,0.0382,,8.26,0.2742,21.4008,
,8.34,0.007,0.0039,,8.28,0.2749,21.7671,
,8.36,0.007,0.0862,,8.3,0.2756,22.0854,
,8.38,0.007,0.0584,,8.32,0.2763,22.4423,
,8.4,0.007,0.0301,,8.34,0.277,23.0156,
,8.42,0.0071,-0.0398,,8.36,0.2776,23.4773,
,8.44,0.0071,-0.0345,,8.38,0.2782,23.8564,
,8.46,0.0071,0.0077,,8.4,0.2788,24.2355,
,8.48,0.0071,-0.0928,,8.42,0.2795,24.646,
,8.5,0.0071,-0.1013,,8.44,0.2802,25.2373,
,8.52,0.0071,-0.025,,8.46,0.281,25.83,
,8.54,0.0072,-0.0807,,8.48,0.2817,26.3602,
,8.56,0.0072,-0.0171,,8.5,0.2823,26.6588,
,8.58,0.0072,0.0609,,8.52,0.2829,26.9896,
,8.6,0.0072,0.0583,,8.54,0.2835,27.2584,
,8.62,0.0072,-0.1952,,8.56,0.2842,27.7283,
,8.64,0.0072,-0.2766,,8.58,0.2849,28.1653,
,8.66,0.0073,-0.104,,8.6,0.2856,28.607,
,8.68,0.0073,0.0764,,8.62,0.2863,29.056,
,8.7,0.0073,0.1523,,8.64,0.2869,29.6012,
,8.72,0.0073,-0.0152,,8.66,0.2875,30.2109,
,8.74,0.0073,-0.1433,,8.68,0.2882,30.719,
,8.76,0.0073,-0.1089,,8.7,0.2888,31.3904,
,8.78,0.0074,-0.0089,,8.72,0.2896,32.1584,
,8.8,0.0074,-0.0823,,8.74,0.2903,33.0334,
,8.82,0.0074,-0.0456,,8.76,0.2911,34.0879,
,8.84,0.0074,-0.0003,,8.78,0.2917,35.1003,
,8.86,0.0074,-0.0251,,8.8,0.2923,36.1619,
,8.88,0.0074,-0.0629,,8.82,0.2929,37.322,
,8.9,0.0075,-0.0232,,8.84,0.2936,38.4666,
,8.92,0.0075,-0.0441,,8.86,0.2943,39.5497,
,8.94,0.0075,0.0378,,8.88,0.295,40.9256,
,8.96,0.0075,0.0638,,8.9,0.2957,42.2983,
,8.98,0.0075,0.1976,,8.92,0.2963,43.5183,
,9,0.0075,0.1726,,8.94,0.297,44.8774,
,9.02,0.0076,0.0498,,8.96,0.2976,46.2689,
,9.04,0.0076,-0.063,,8.98,0.2982,47.8149,
,9.06,0.0076,0.0705,,9,0.2989,49.5384,
,9.08,0.0076,0.0761,,9.02,0.2996,51.613,
,9.1,0.0076,0.0587,,9.04,0.3003,53.6427,
,9.12,0.0076,0.0089,,9.06,0.301,55.4577,
,9.14,0.0077,0.0273,,9.08,0.3016,57.0571,
,9.16,0.0077,0.0258,,9.1,0.3023,58.5872,
,9.18,0.0077,0.0015,,9.12,0.3029,60.4002,
,9.2,0.0077,0.0929,,9.14,0.3036,62.4678,
,9.22,0.0077,0.0619,,9.16,0.3043,64.8423,
,9.24,0.0077,0.045,,9.18,0.305,67.4137,
,9.26,0.0078,0.0701,,9.2,0.3057,69.6936,
,9.28,0.0078,0.0258,,9.22,0.3064,71.8382,
,9.3,0.0078,0.0578,,9.24,0.307,74.1506,
,9.32,0.0078,-0.1514,,9.26,0.3076,76.414,
,9.34,0.0078,-0.2008,,9.28,0.3083,79.105,
,9.36,0.0078,-0.0007,,9.3,0.309,82.0501,
,9.38,0.0079,-0.0078,,9.32,0.3097,84.9166,
,9.4,0.0079,-0.0531,,9.34,0.3104,87.4175,
,9.42,0.0079,0.0699,,9.36,0.311,89.6472,
,9.44,0.0079,0.0617,,9.38,0.3116,91.8985,
,9.46,0.0079,0.0476,,9.4,0.3122,94.1543,
,9.48,0.0079,0.0593,,9.42,0.3129,96.5684,
,9.5,0.008,0.0993,,9.44,0.3136,99.2281,
,9.52,0.008,-0.0272,,9.46,0.3143,102.1251,
,9.54,0.008,-0.0287,,9.48,0.315,104.8633,
,9.56,0.008,-0.1533,,9.5,0.3157,107.3945,
,9.58,0.008,-0.1008,,9.52,0.3164,109.7664,
,9.6,0.008,-0.0326,,9.54,0.317,111.9675,
,9.62,0.0081,0.0566,,9.56,0.3176,114.1646,
,9.64,0.0081,0.0158,,9.58,0.3183,116.7635,
,9.66,0.0081,0.0964,,9.6,0.3191,119.6931,
,9.68,0.0081,0.0497,,9.62,0.3198,122.428,
,9.7,0.0081,-0.0454,,9.64,0.3205,124.9319,
,9.72,0.0082,0.023,,9.66,0.3211,126.9972,
,9.74,0.0082,0.0134,,9.68,0.3217,128.8831,
,9.76,0.0082,0.0336,,9.7,0.3223,131.1458,
,9.78,0.0082,0.0216,,9.72,0.3229,133.4538,
,9.8,0.0082,0.0311,,9.74,0.3236,136.0047,
,9.82,0.0082,-0.0486,,9.76,0.3243,138.6446,
,9.84,0.0083,-0.0194,,9.78,0.325,141.0991,
,9.86,0.0083,0.1117,,9.8,0.3256,143.4044,
,9.88,0.0083,0.044,,9.82,0.3262,145.432,
,9.9,0.0083,-0.1014,,9.84,0.3268,147.5208,
,9.92,0.0083,-0.1904,,9.86,0.3275,149.9169,
,9.94,0.0083,-0.2272,,9.88,0.3282,152.6152,
,9.96,0.0084,-0.0772,,9.9,0.329,155.2881,
,9.98,0.0084,0.0518,,9.92,0.3297,157.9404,
,10,0.0084,-0.0001,,9.94,0.3304,160.1146,
,10.02,0.0084,-0.0429,,9.96,0.331,162.0125,
,10.04,0.0084,0.0008,,9.98,0.3316,164.2347,
,10.06,0.0084,0.1532,,10,0.3323,166.4892,
,10.08,0.0085,0.1166,,10.02,0.3329,168.9128,
,10.1,0.0085,-0.0502,,10.04,0.3337,171.5209,
,10.12,0.0085,-0.3055,,10.06,0.3344,173.8456,
,10.14,0.0085,-0.0516,,10.08,0.335,175.7853,
,10.16,0.0085,0.0232,,10.1,0.3356,177.6783,
,10.18,0.0085,0.1062,,10.12,0.3362,179.7156,
,10.2,0.0086,0.0388,,10.14,0.3368,181.9124,
,10.22,0.0086,-0.013,,10.16,0.3375,184.3248,
,10.24,0.0086,-0.0745,,10.18,0.3382,186.8831,
,10.26,0.0086,-0.0381,,10.2,0.339,189.4946,
,10.28,0.0086,-0.0128,,10.22,0.3397,191.7659,
,10.3,0.0086,-0.0623,,10.24,0.3403,193.8142,
,10.32,0.0087,-0.0103,,10.26,0.3409,195.904,
,10.34,0.0087,-0.027,,10.28,0.3415,198.0599,
,10.36,0.0087,-0.0759,,10.3,0.3422,200.3672,
,10.38,0.0087,-0.0747,,10.32,0.3429,202.8589,
,10.4,0.0087,-0.1066,,10.34,0.3436,205.4671,
,10.42,0.0087,-0.1883,,10.36,0.3443,207.6433,
,10.44,0.0088,-0.1097,,10.38,0.345,209.6782,
,10.46,0.0088,0.0299,,10.4,0.3456,211.6167,
,10.48,0.0088,0.1427,,10.42,0.3462,213.5745,
,10.5,0.0088,0.153,,10.44,0.3469,215.8294,
,10.52,0.0088,0.0885,,10.46,0.3475,218.2506,
,10.54,0.0088,0.1291,,10.48,0.3483,220.7191,
,10.56,0.0089,0.1057,,10.5,0.349,223.1875,
,10.58,0.0089,0.0438,,10.52,0.3497,225.536,
,10.6,0.0089,0.0246,,10.54,0.3503,227.471,
,10.62,0.0089,0.0689,,10.56,0.3509,229.561,
,10.64,0.0089,0.1225,,10.58,0.3515,231.8764,
,10.66,0.009,0.1329,,10.6,0.3522,234.1564,
,10.68,0.009,-0.0279,,10.62,0.3529,236.689,
,10.7,0.009,-0.0977,,10.64,0.3536,239.2022,
,10.72,0.009,-0.2382,,10.66,0.3543,241.499,
,10.74,0.009,-0.0816,,10.68,0.3549,243.6676,
,10.76,0.009,0.097,,10.7,0.3556,245.816,
,10.78,0.0091,0.0353,,10.72,0.3562,248.5623,
,10.8,0.0091,-0.0813,,10.74,0.3569,251.5176,
,10.82,0.0091,-0.1074,,10.76,0.3576,254.7424,
,10.84,0.0091,-0.1224,,10.78,0.3584,258.521,
,10.86,0.0091,0.0019,,10.8,0.3591,261.9078,
,10.88,0.0091,-0.0162,,10.82,0.3597,265.1397,
,10.9,0.0092,0.0196,,10.84,0.3603,268.4922,
,10.92,0.0092,0.0807,,10.86,0.3609,271.7552,
,10.94,0.0092,0.0977,,10.88,0.3616,275.2096,
,10.96,0.0092,0.0235,,10.9,0.3623,279.1645,
,10.98,0.0092,-0.0282,,10.92,0.363,283.045,
,11,0.0092,-0.0379,,10.94,0.3637,286.9167,
,11.02,0.0093,0.0232,,10.96,0.3644,290.4554,
,11.04,0.0093,-0.067,,10.98,0.365,293.5623,
,11.06,0.0093,-0.2211,,11,0.3656,296.8828,
,11.08,0.0093,-0.1686,,11.02,0.3663,300.5794,
,11.1,0.0093,0.0551,,11.04,0.367,304.6595,
,11.12,0.0094,0.0659,,11.06,0.3677,308.7723,
,11.14,0.0094,0.129,,11.08,0.3685,312.7597,
,11.16,0.0094,0.1387,,11.1,0.3691,316.3181,
,11.18,0.0094,-0.0156,,11.12,0.3697,319.7224,
,11.2,0.0094,-0.0169,,11.14,0.3703,322.7273,
,11.22,0.0094,-0.0408,,11.16,0.3709,325.9608,
,11.24,0.0095,-0.031,,11.18,0.3716,329.6903,
,11.26,0.0095,0.008,,11.2,0.3723,333.6961,
,11.28,0.0095,0.0467,,11.22,0.373,337.7028,
,11.3,0.0095,-0.004,,11.24,0.3736,341.5046,
,11.32,0.0095,-0.0385,,11.26,0.3743,345.178,
,11.34,0.0095,-0.1188,,11.28,0.3749,348.5618,
,11.36,0.0096,-0.1617,,11.3,0.3756,352.1917,
,11.38,0.0096,-0.1419,,11.32,0.3763,356.2078,
,11.4,0.0096,0.107,,11.34,0.377,360.5061,
,11.42,0.0096,0.0598,,11.36,0.3777,364.742,
,11.44,0.0096,-0.065,,11.38,0.3784,368.737,
,11.46,0.0096,0.0092,,11.4,0.3791,372.0168,
,11.48,0.0097,0.0025,,11.42,0.3797,375.2354,
,11.5,0.0097,0.0122,,11.44,0.3803,378.7829,
,11.52,0.0097,0.1142,,11.46,0.3809,382.6538,
,11.54,0.0097,0.1067,,11.48,0.3816,386.6252,
,11.56,0.0097,0.1048,,11.5,0.3823,390.6772,
,11.58,0.0097,0.0922,,11.52,0.383,394.3443,
,11.6,0.0098,0.1089,,11.54,0.3836,397.7231,
,11.62,0.0098,0.1135,,11.56,0.3842,401.0901,
,11.64,0.0098,0.0857,,11.58,0.3849,404.6451,
,11.66,0.0098,0.0719,,11.6,0.3855,408.4047,
,11.68,0.0098,0.136,,11.62,0.3862,412.5729,
,11.7,0.0098,0.0533,,11.64,0.387,416.7909,
,11.72,0.0099,0.0376,,11.66,0.3877,421.0203,
,11.74,0.0099,0.0889,,11.68,0.3884,424.8983,
,11.76,0.0099,0.005,,11.7,0.389,428.3343,
,11.78,0.0099,-0.0996,,11.72,0.3896,431.7768,
,11.8,0.0099,0.0251,,11.74,0.3903,435.406,
,11.82,0.01,0.0159,,11.76,0.3909,439.2049,
,11.84,0.01,-0.0535,,11.78,0.3917,443.3232,
,11.86,0.01,0.0153,,11.8,0.3924,447.4257,
,11.88,0.01,0.0672,,11.82,0.393,451.048,
,11.9,0.01,-0.1061,,11.84,0.3937,454.5195,
,11.92,0.01,-0.1103,,11.86,0.3942,457.8223,
,11.94,0.0101,0.0038,,11.88,0.3948,461.1429,
,11.96,0.0101,0.0372,,11.9,0.3955,464.9116,
,11.98,0.0101,0.0986,,11.92,0.3962,468.9038,
,12,0.0101,0.0264,,11.94,0.3969,473.0253,
,12.02,0.0101,-0.0104,,11.96,0.3976,476.9434,
,12.04,0.0101,-0.059,,11.98,0.3982,480.6925,
,12.06,0.0102,-0.1396,,12,0.3989,484.3874,
,12.08,0.0102,-0.0166,,12.02,0.3995,488.0573,
,12.1,0.0102,0.0038,,12.04,0.4001,491.762,
,12.12,0.0102,0.1146,,12.06,0.4009,495.9318,
,12.14,0.0102,0.2384,,12.08,0.4016,500.2932,
,12.16,0.0102,0.0544,,12.1,0.4023,504.4325,
,12.18,0.0103,-0.163,,12.12,0.403,508.2125,
,12.2,0.0103,-0.0671,,12.14,0.4036,511.8685,
,12.22,0.0103,0.1539,,12.16,0.4042,515.4279,
,12.24,0.0103,0.2565,,12.18,0.4049,519.3026,
,12.26,0.0103,0.1381,,12.2,0.4056,523.3809,
,12.28,0.0103,0.0092,,12.22,0.4063,527.7169,
,12.3,0.0104,0.0326,,12.24,0.407,531.9637,
,12.32,0.0104,0.0056,,12.26,0.4077,535.6854,
,12.34,0.0104,-0.1278,,12.28,0.4083,539.1709,
,12.36,0.0104,-0.2144,,12.3,0.4089,542.8547,
,12.38,0.0104,-0.1263,,12.32,0.4095,546.8759,
,12.4,0.0104,-0.0292,,12.34,0.4102,550.9388,
,12.42,0.0105,0.1027,,12.36,0.4109,555.209,
,12.44,0.0105,0.0823,,12.38,0.4116,559.5555,
,12.46,0.0105,-0.0061,,12.4,0.4123,563.5556,
,12.48,0.0105,0.0737,,12.42,0.413,567.229,
,12.5,0.0105,0.0715,,12.44,0.4136,570.9031,
,12.52,0.0105,-0.0393,,12.46,0.4142,574.6766,
,12.54,0.0106,-0.0691,,12.48,0.4149,578.9444,
,12.56,0.0106,-0.1493,,12.5,0.4156,583.452,
,12.58,0.0106,-0.1523,,12.52,0.4164,588.0488,
,12.6,0.0106,-0.1946,,12.54,0.4171,592.4963,
,12.62,0.0106,-0.1873,,12.56,0.4177,596.3473,
,12.64,0.0107,-0.1257,,12.58,0.4184,599.874,
,12.66,0.0107,-0.1358,,12.6,0.419,603.5753,
,12.68,0.0107,-0.0406,,12.62,0.4196,607.352,
,12.7,0.0107,0.0724,,12.64,0.4203,611.4547,
,12.72,0.0107,0.0328,,12.66,0.421,615.8764,
,12.74,0.0107,0.0118,,12.68,0.4217,620.2971,
,12.76,0.0107,-0.1614,,12.7,0.4223,624.2938,
,12.78,0.0108,-0.0838,,12.72,0.423,628.0383,
,12.8,0.0108,-0.031,,12.74,0.4236,632.005,
,12.82,0.0108,0.0004,,12.76,0.4242,636.1776,
,12.84,0.0108,0.0425,,12.78,0.4249,640.6427,
,12.86,0.0108,-0.0923,,12.8,0.4257,645.2342,
,12.88,0.0109,-0.132,,12.82,0.4264,649.6737,
,12.9,0.0109,0.0957,,12.84,0.4271,653.7796,
,12.92,0.0109,0.202,,12.86,0.4277,657.5706,
,12.94,0.0109,0.01,,12.88,0.4283,661.2873,
,12.96,0.0109,0.0418,,12.9,0.4289,665.3325,
,12.98,0.0109,-0.0012,,12.92,0.4296,669.7465,
,13,0.011,-0.0113,,12.94,0.4303,674.098,
,13.02,0.011,-0.0016,,12.96,0.431,678.7133,
,13.04,0.011,0.016,,12.98,0.4317,683.057,
,13.06,0.011,0.03,,13,0.4323,686.8976,
,13.08,0.011,-0.038,,13.02,0.4329,690.7809,
,13.1,0.011,-0.0018,,13.04,0.4336,694.9071,
,13.12,0.0111,0.1258,,13.06,0.4342,699.3746,
,13.14,0.0111,0.1088,,13.08,0.435,704.1531,
,13.16,0.0111,-0.044,,13.1,0.4357,708.9446,
,13.18,0.0111,-0.1029,,13.12,0.4364,713.3669,
,13.2,0.0111,0.0644,,13.14,0.4371,717.4749,
,13.22,0.0111,0.1652,,13.16,0.4377,721.3713,
,13.24,0.0112,0.1269,,13.18,0.4383,725.212,
,13.26,0.0112,0.141,,13.2,0.4389,729.4229,
,13.28,0.0112,-0.0485,,13.22,0.4396,733.9113,
,13.3,0.0112,0.0286,,13.24,0.4404,738.6727,
,13.32,0.0112,0.1711,,13.26,0.4411,743.1062,
,13.34,0.0112,0.097,,13.28,0.4417,747.2538,
,13.36,0.0113,0.0337,,13.3,0.4423,751.056,
,13.38,0.0113,0.0879,,13.32,0.4429,754.9805,
,13.4,0.0113,0.0652,,13.34,0.4435,759.1603,
,13.42,0.0113,-0.136,,13.36,0.4442,763.6343,
,13.44,0.0113,-0.1477,,13.38,0.4449,768.1752,
,13.46,0.0113,-0.1933,,13.4,0.4456,772.8007,
,13.48,0.0114,-0.135,,13.42,0.4463,777.3747,
,13.5,0.0114,-0.1975,,13.44,0.447,781.5714,
,13.52,0.0114,-0.1599,,13.46,0.4476,785.6181,
,13.54,0.0114,-0.0265,,13.48,0.4482,789.9019,
,13.56,0.0114,-0.0044,,13.5,0.4489,794.4816,
,13.58,0.0114,0.0465,,13.52,0.4496,799.2388,
,13.6,0.0115,-0.0059,,13.54,0.4504,803.982,
,13.62,0.0115,-0.0472,,13.56,0.451,808.4246,
,13.64,0.0115,0.0566,,13.58,0.4517,812.3552,
,13.66,0.0115,0.0386,,13.6,0.4523,816.2029,
,13.68,0.0115,0.0172,,13.62,0.4529,820.3471,
,13.7,0.0115,0.0207,,13.64,0.4535,824.8475,
,13.72,0.0116,-0.0306,,13.66,0.4542,829.561,
,13.74,0.0116,0.0507,,13.68,0.455,834.392,
,13.76,0.0116,0.1067,,13.7,0.4556,838.9065,
,13.78,0.0116,0.1112,,13.72,0.4563,842.9953,
,13.8,0.0116,0.1084,,13.74,0.4569,846.9028,
,13.82,0.0116,-0.003,,13.76,0.4575,850.8877,
,13.84,0.0117,-0.0035,,13.78,0.4581,855.2797,
,13.86,0.0117,0.0056,,13.8,0.4588,860.0244,
,13.88,0.0117,-0.1224,,13.82,0.4596,865.1101,
,13.9,0.0117,-0.1588,,13.84,0.4603,869.952,
,13.92,0.0117,-0.1185,,13.86,0.461,874.4379,
,13.94,0.0117,0.1015,,13.88,0.4616,878.4473,
,13.96,0.0118,0.0757,,13.9,0.4622,882.5886,
,13.98,0.0118,0.0793,,13.92,0.4629,887.0779,
,14,0.0118,-0.1311,,13.94,0.4636,892.0211,
,14.02,0.0118,-0.1793,,13.96,0.4643,896.8396,
,14.04,0.0118,-0.0038,,13.98,0.465,901.8168,
,14.06,0.0118,-0.0227,,14,0.4657,906.3347,
,14.08,0.0119,-0.1191,,14.02,0.4664,910.3329,
,14.1,0.0119,-0.0816,,14.04,0.467,914.355,
,14.12,0.0119,0.0297,,14.06,0.4676,918.4199,
,14.14,0.0119,0.0998,,14.08,0.4682,922.816,
,14.16,0.0119,0.1113,,14.1,0.4689,927.5396,
,14.18,0.0119,0.0452,,14.12,0.4696,932.4517,
,14.2,0.012,-0.084,,14.14,0.4703,936.9694,
,14.22,0.012,-0.1845,,14.16,0.4709,941.2762,
,14.24,0.012,-0.0436,,14.18,0.4716,945.5938,
,14.26,0.012,0.1474,,14.2,0.4722,949.9431,
,14.28,0.012,0.1435,,14.22,0.4729,954.5021,
,14.3,0.012,0.0865,,14.24,0.4736,959.5214,
,14.32,0.0121,0.0687,,14.26,0.4743,964.873,
,14.34,0.0121,0.0293,,14.28,0.4751,969.7444,
,14.36,0.0121,-0.0135,,14.3,0.4757,974.1836,
,14.38,0.0121,-0.0716,,14.32,0.4763,978.1036,
,14.4,0.0121,-0.0632,,14.34,0.477,982.3984,
,14.42,0.0121,0.0734,,14.36,0.4776,987.0684,
,14.44,0.0122,-0.0123,,14.38,0.4783,991.947,
,14.46,0.0122,-0.0248,,14.4,0.479,996.8724,
,14.48,0.0122,-0.116,,14.42,0.4797,1001.5562,
,14.5,0.0122,0.0471,,14.44,0.4804,1005.9907,
,14.52,0.0122,0.0738,,14.46,0.481,1010.3077,
,14.54,0.0122,-0.1148,,14.48,0.4816,1014.3839,
,14.56,0.0123,-0.1886,,14.5,0.4822,1018.7427,
,14.58,0.0123,-0.0551,,14.52,0.4829,1023.6698,
,14.6,0.0123,-0.0606,,14.54,0.4836,1029.0496,
,14.62,0.0123,-0.0164,,14.56,0.4844,1034.3401,
,14.64,0.0123,-0.0574,,14.58,0.4851,1039.0088,
,14.66,0.0123,0.0278,,14.6,0.4857,1043.3054,
,14.68,0.0124,0.0275,,14.62,0.4863,1047.4037,
,14.7,0.0124,-0.1075,,14.64,0.4869,1051.7146,
,14.72,0.0124,-0.1456,,14.66,0.4876,1056.4482,
,14.74,0.0124,-0.0933,,14.68,0.4883,1061.6519,
,14.76,0.0124,-0.0797,,14.7,0.489,1066.8091,
,14.78,0.0124,-0.1697,,14.72,0.4897,1071.6195,
,14.8,0.0125,-0.064,,14.74,0.4904,1076.0696,
,14.82,0.0125,-0.0572,,14.76,0.491,1080.2761,
,14.84,0.0125,-0.0595,,14.78,0.4916,1084.5111,
,14.86,0.0125,0.0026,,14.8,0.4923,1089.288,
,14.88,0.0125,-0.0667,,14.82,0.493,1093.9828,
,14.9,0.0125,0.0601,,14.84,0.4937,1099.1323,
,14.92,0.0126,0.0387,,14.86,0.4944,1104.1807,
,14.94,0.0126,0.0067,,14.88,0.495,1108.688,
,14.96,0.0126,0.1202,,14.9,0.4957,1113.0189,
,14.98,0.0126,-0.0636,,14.92,0.4963,1117.3882,
,15,0.0126,-0.1883,,14.94,0.4969,1122.052,
,15.02,0.0126,-0.1075,,14.96,0.4976,1127.0114,
,15.04,0.0127,0.0781,,14.98,0.4983,1132.2399,
,15.06,0.0127,0.0968,,15,0.499,1137.1345,
,15.08,0.0127,-0.0233,,15.02,0.4997,1141.5842,
,15.1,0.0127,-0.0117,,15.04,0.5003,1145.7926,
,15.12,0.0127,0.1446,,15.06,0.5009,1150.092,
,15.14,0.0127,0.0513,,15.08,0.5016,1154.5916,
,15.16,0.0128,-0.0771,,15.1,0.5022,1159.5344,
,15.18,0.0128,-0.126,,15.12,0.503,1164.6406,
,15.2,0.0128,-0.1383,,15.14,0.5037,1169.6664,
,15.22,0.0128,-0.0609,,15.16,0.5043,1174.505,
,15.24,0.0128,0.0375,,15.18,0.505,1178.951,
,15.26,0.0128,0.0945,,15.2,0.5056,1183.2393,
,15.28,0.0129,0.0058,,15.22,0.5062,1187.5984,
,15.3,0.0129,-0.1257,,15.24,0.5069,1192.3779,
,15.32,0.0129,-0.128,,15.26,0.5076,1197.6189,
,15.34,0.0129,-0.0373,,15.28,0.5083,1202.8572,
,15.36,0.0129,-0.1377,,15.3,0.509,1207.7725,
,15.38,0.0129,-0.0046,,15.32,0.5096,1212.124,
,15.4,0.013,-0.0734,,15.34,0.5102,1216.2148,
,15.42,0.013,-0.0598,,15.36,0.5109,1220.5681,
,15.44,0.013,0.013,,15.38,0.5115,1225.2458,
,15.46,0.013,0.0082,,15.4,0.5122,1230.4232,
,15.48,0.013,0.0225,,15.42,0.513,1235.7384,
,15.5,0.013,0.1316,,15.44,0.5137,1240.6718,
,15.52,0.0131,0.1926,,15.46,0.5144,1245.292,
,15.54,0.0131,-0.0482,,15.48,0.515,1249.442,
,15.56,0.0131,-0.0194,,15.5,0.5156,1253.5865,
,15.58,0.0131,0.0208,,15.52,0.5162,1257.9016,
,15.6,0.0131,0.2058,,15.54,0.5168,1262.743,
,15.62,0.0131,0.1427,,15.56,0.5175,1267.8834,
,15.64,0.0132,0.1222,,15.58,0.5182,1272.8306,
,15.66,0.0132,0.0897,,15.6,0.5189,1277.3258,
,15.68,0.0132,-0.0529,,15.62,0.5196,1281.6709,
,15.7,0.0132,-0.016,,15.64,0.5202,1286.0682,
,15.72,0.0132,-0.0052,,15.66,0.5209,1290.7316,
,15.74,0.0132,-0.0906,,15.68,0.5216,1295.946,
,15.76,0.0133,-0.0875,,15.7,0.5223,1301.2339,
,15.78,0.0133,0.0502,,15.72,0.523,1306.4574,
,15.8,0.0133,-0.0002,,15.74,0.5237,1311.2883,
,15.82,0.0133,0.0382,,15.76,0.5244,1315.5294,
,15.84,0.0133,-0.0045,,15.78,0.525,1319.6171,
,15.86,0.0134,0.1413,,15.8,0.5256,1323.677,
,15.88,0.0134,0.2014,,15.82,0.5262,1328.3036,
,15.9,0.0134,0.0505,,15.84,0.5269,1333.3575,
,15.92,0.0134,-0.056,,15.86,0.5276,1338.3684,
,15.94,0.0134,0.1071,,15.88,0.5283,1343.0494,
,15.96,0.0134,-0.041,,15.9,0.5289,1347.2181,
,15.98,0.0135,-0.1428,,15.92,0.5295,1351.5354,
,16,0.0135,-0.1717,,15.94,0.5302,1355.8115,
,16.02,0.0135,-0.1609,,15.96,0.5308,1360.5739,
,16.04,0.0135,-0.081,,15.98,0.5315,1365.6426,
,16.06,0.0135,0.0208,,16,0.5323,1370.7583,
,16.08,0.0135,0.0675,,16.02,0.533,1375.7466,
,16.1,0.0136,0.0009,,16.04,0.5337,1380.3187,
,16.12,0.0136,0.0525,,16.06,0.5343,1384.5671,
,16.14,0.0136,0.0631,,16.08,0.535,1388.899,
,16.154,0.0136,0.057,,16.1,0.5356,1393.3051,
2,Time,Displacement,Force,,16.12,0.5363,1398.0144,
,(s),(mm),(N),,16.14,0.5371,1403.1833,
,0.4,0.0001,0.0565,,16.56,0.551,1495.2288,
,0.82,0.0004,0.0241,,16.98,0.5649,1584.0642,
,1.24,0.0009,0.5729,,17.4,0.5788,1670.5524,
,1.66,0.0013,0.9235,,17.82,0.5929,1753.5781,
,2.08,0.0017,1.406,,18.24,0.607,1836.6907,
,2.5,0.002,1.7723,,18.66,0.621,1918.2009,
,2.92,0.0024,2.3845,,19.08,0.635,1998.72,
,3.34,0.0027,3.0468,,19.5,0.649,2080.4927,
,3.76,0.0031,3.8833,,19.92,0.663,2160.4763,
,4.18,0.0035,4.3933,,20.34,0.6769,2242.2007,
,4.6,0.0038,5.0589,,20.76,0.6909,2323.2703,
,5.02,0.0042,5.8135,,21.18,0.7049,2405.4895,
,5.44,0.0046,6.3351,,21.6,0.719,2485.3916,
,5.86,0.0049,7.1458,,22.02,0.7329,2566.9265,
,6.28,0.0053,7.7083,,22.44,0.7469,2647.5776,
,6.7,0.0056,8.4401,,22.86,0.7609,2729.7922,
,7.12,0.0059,8.9853,,23.28,0.7751,2811.3748,
,7.54,0.0063,9.6615,,23.7,0.789,2891.552,
,7.96,0.0067,10.2246,,24.12,0.803,2972.1201,
,8.38,0.007,10.8921,,24.54,0.8169,3051.7061,
,8.8,0.0074,11.573,,24.96,0.8309,3132.5042,
,9.22,0.0077,12.6003,,25.38,0.8449,3212.3284,
,9.64,0.0081,13.2358,,25.8,0.8589,3291.0759,
,10.06,0.0085,13.8428,,26.22,0.873,3371.2693,
,10.48,0.0088,14.8373,,26.64,0.8871,3445.0342,
,10.9,0.0092,15.4243,,27.06,0.9011,3520.4111,
,11.32,0.0095,16.4086,,27.48,0.915,3598.8774,
,11.74,0.0099,17.3127,,27.9,0.9289,3678.7075,
,12.16,0.0102,18.1105,,28.32,0.943,3759.6663,
,12.58,0.0106,19.2735,,28.74,0.9569,3837.2363,
,13,0.0109,20.7831,,29.16,0.9709,3917.7749,
,13.42,0.0113,22.2617,,29.58,0.9849,3997.3623,
,13.84,0.0116,23.5585,,30,0.999,4078.9993,
,14.26,0.012,24.801,,30.42,1.013,4158.0469,
,14.68,0.0124,25.9228,,30.84,1.027,4237.9648,
,15.1,0.0127,26.997,,31.26,1.041,4316.8037,
,15.52,0.0131,27.7028,,31.68,1.055,4394.606,
,15.94,0.0135,27.8062,,32.1,1.069,4470.8921,
,16.36,0.0138,28.2219,,32.52,1.0829,4545.7637,
,16.78,0.0142,28.5255,,32.94,1.0969,4618.563,
,17.2,0.0145,28.5835,,33.36,1.1108,4692.2212,
,17.62,0.0149,29.15,,33.78,1.1249,4763.0811,
,18.04,0.0152,29.4304,,34.2,1.139,4826.0859,
,18.46,0.0156,29.641,,34.62,1.153,4895.7549,
,18.88,0.0159,29.9361,,35.04,1.167,4966.208,
,19.3,0.0163,29.9913,,35.46,1.181,5033.9692,
,19.72,0.0166,30.3091,,35.88,1.1949,5099.6606,
,20.14,0.017,30.8942,,36.3,1.2089,5166.0811,
,20.56,0.0173,31.2826,,36.72,1.2229,5234.7383,
,20.98,0.0177,31.4286,,37.14,1.237,5302.6738,
,21.4,0.0181,32.096,,37.56,1.251,5368.6899,
,21.82,0.0184,32.2332,,37.98,1.265,5434.6226,
,22.24,0.0188,32.5292,,38.4,1.279,5499.2095,
,22.66,0.0191,33.0098,,38.82,1.293,5563.5942,
,23.08,0.0195,33.6053,,39.24,1.3071,5627.6455,
,23.5,0.0198,33.7674,,39.66,1.321,5689.3779,
,23.92,0.0202,34.3903,,40.08,1.335,5749.7017,
,24.34,0.0205,34.8525,,40.5,1.349,5807.4624,
,24.76,0.0209,35.3155,,40.92,1.3629,5861.9009,
,25.18,0.0212,35.8604,,41.34,1.3769,5910.7197,
,25.6,0.0216,36.4432,,41.76,1.3909,5948.2163,
,26.02,0.022,36.9009,,42.18,1.4051,5999.645,
,26.44,0.0223,37.2342,,42.6,1.419,6045.4546,
,26.86,0.0227,37.7558,,43.02,1.4331,6091.1567,
,27.28,0.023,38.2149,,43.44,1.4469,6127.5386,
,27.7,0.0234,38.5226,,43.86,1.4609,6167.0156,
,28.12,0.0238,39.2532,,44.28,1.4749,6204.29,
,28.54,0.0241,39.5937,,44.7,1.4889,6239.7046,
,28.96,0.0245,40.031,,45.12,1.5029,6268.2568,
,29.38,0.0248,40.5054,,45.54,1.5169,6298.8818,
,29.8,0.0252,40.8508,,45.96,1.5311,6321.9004,
,30.22,0.0255,41.1503,,46.38,1.545,6345.1313,
,30.64,0.0259,41.6843,,46.8,1.5589,6365.3325,
,31.06,0.0262,42.058,,47.22,1.573,6383.8838,
,31.48,0.0266,42.3692,,47.64,1.587,6404.1509,
,31.9,0.0269,42.4815,,48.06,1.601,6425.7158,
,32.32,0.0273,43.0778,,48.48,1.6149,6440.0576,
,32.74,0.0277,43.5068,,48.9,1.6289,6447.646,
,33.16,0.028,43.9096,,49.32,1.6429,6454.6841,
,33.58,0.0284,44.2858,,49.74,1.657,6412.6597,
,34,0.0287,44.6611,,50.16,1.671,6251.563,
,34.42,0.0291,45.0317,,50.58,1.6851,630.2096,
,34.84,0.0294,45.3664,,51,1.6991,713.3731,
,35.26,0.0298,45.7082,,51.42,1.713,786.1807,
,35.68,0.0301,46.031,,51.84,1.7269,849.8162,
,36.1,0.0305,46.5585,,52.26,1.7409,903.0862,
,36.52,0.0308,46.8891,,52.68,1.7549,945.7589,
,36.94,0.0312,47.1378,,53.1,1.769,979.2614,
,37.36,0.0315,47.7495,,53.52,1.783,1003.9325,
,37.78,0.0319,48.1957,,53.94,1.797,1018.8975,
,38.2,0.0323,48.4538,,54.36,1.8111,1026.8992,
,38.62,0.0326,48.9701,,54.78,1.8249,1032.7494,
,39.04,0.033,49.1744,,,,,
,39.46,0.0334,49.5274,,,,,
,39.88,0.0337,49.8927,,,,,
,40.3,0.0341,50.3971,,,,,
,40.72,0.0344,50.5505,,,,,
,41.14,0.0348,51.0098,,,,,
,41.56,0.0351,51.3113,,,,,
,41.98,0.0355,51.7284,,,,,
,42.4,0.0358,51.8743,,,,,
,42.82,0.0362,52.522,,,,,
,43.24,0.0365,52.683,,,,,
,43.66,0.0369,53.0802,,,,,
,44.08,0.0373,53.4449,,,,,
,44.5,0.0376,53.7878,,,,,
,44.92,0.038,54.1065,,,,,
,45.34,0.0383,54.1939,,,,,
,45.76,0.0387,54.5621,,,,,
,46.18,0.039,54.7759,,,,,
[...]
,26.8,0.8923,3470.377,,,,,
,26.84,0.8936,3477.0234,,,,,
,26.88,0.895,3484.9028,,,,,
,26.92,0.8964,3493.0613,,,,,
,26.96,0.8977,3500.2229,,,,,
,27,0.899,3507.6575,,,,,
,27.04,0.9004,3516.3235,,,,,
,27.08,0.9018,3523.8218,,,,,
,27.12,0.903,3530.0344,,,,,
,27.16,0.9043,3537.3586,,,,,
,27.2,0.9056,3545.4712,,,,,
,27.24,0.9069,3552.5686,,,,,
,27.28,0.9082,3559.437,,,,,
,27.32,0.9096,3568.0913,,,,,
,27.36,0.911,3576.2888,,,,,
,27.4,0.9123,3583.0259,,,,,
,27.44,0.9136,3590.5249,,,,,
,27.48,0.915,3598.8774,,,,,
,27.52,0.9163,3605.9395,,,,,
,27.56,0.9175,3612.5742,,,,,
,27.6,0.9189,3620.8694,,,,,
,27.64,0.9203,3629.9207,,,,,
,27.68,0.9216,3636.8054,,,,,
,27.72,0.9229,3643.8159,,,,,
,27.76,0.9243,3652.3755,,,,,
,27.8,0.9257,3660.2449,,,,,
,27.84,0.9269,3667.1282,,,,,
,27.88,0.9282,3674.6152,,,,,
,27.92,0.9296,3682.9348,,,,,
,27.96,0.931,3690.5688,,,,,
,28,0.9322,3697.5574,,,,,
,28.04,0.9336,3705.426,,,,,
,28.08,0.935,3713.6719,,,,,
,28.12,0.9363,3720.7454,,,,,
,28.16,0.9376,3728.0872,,,,,
,28.2,0.939,3736.9814,,,,,
,28.24,0.9403,3744.7192,,,,,
,28.28,0.9416,3751.395,,,,,
,28.32,0.943,3759.6663,,,,,
,28.36,0.9444,3766.7356,,,,,
,28.4,0.9457,3772.4197,,,,,
,28.44,0.947,3779.8264,,,,,
,28.48,0.9484,3788.3159,,,,,
,28.52,0.9498,3796.6226,,,,,
,28.56,0.951,3803.0271,,,,,
,28.6,0.9522,3810.1663,,,,,
,28.64,0.9536,3818.3767,,,,,
,28.68,0.955,3825.9971,,,,,
,28.72,0.9562,3833.2466,,,,,
,28.76,0.9576,3841.6182,,,,,
,28.8,0.9591,3850.2935,,,,,
,28.84,0.9603,3856.9927,,,,,
,28.88,0.9616,3864.1018,,,,,
,28.92,0.963,3872.3889,,,,,
,28.96,0.9643,3879.7234,,,,,
,29,0.9655,3886.6863,,,,,
,29.04,0.9669,3894.2234,,,,,
,29.08,0.9684,3903.0205,,,,,
,29.12,0.9697,3910.6882,,,,,
,29.16,0.9709,3917.7749,,,,,
,29.2,0.9723,3925.8918,,,,,
,29.24,0.9737,3934.2925,,,,,
,29.28,0.9749,3940.7883,,,,,
,29.32,0.9762,3947.4741,,,,,
,29.36,0.9776,3955.7825,,,,,
,29.4,0.9789,3963.4448,,,,,
,29.44,0.9802,3970.4424,,,,,
,29.48,0.9815,3978.2986,,,,,
,29.52,0.983,3986.7432,,,,,
,29.56,0.9843,3994.0347,,,,,
,29.6,0.9855,4001.0535,,,,,
,29.64,0.9869,4009.4041,,,,,
,29.68,0.9883,4017.7319,,,,,
,29.72,0.9896,4024.3789,,,,,
,29.76,0.9909,4031.8604,,,,,
,29.8,0.9923,4040.2693,,,,,
,29.84,0.9937,4048.2114,,,,,
,29.88,0.9949,4055.123,,,,,
,29.92,0.9963,4063.2102,,,,,
,29.96,0.9978,4072.0657,,,,,
,30,0.999,4078.9993,,,,,
,30.04,1.0003,4085.7581,,,,,
,30.08,1.0016,4093.8203,,,,,
,30.12,1.003,4101.4546,,,,,
,30.16,1.0043,4108.3047,,,,,
,30.2,1.0056,4115.9937,,,,,
,30.24,1.007,4124.8379,,,,,
,30.28,1.0084,4131.9722,,,,,
,30.32,1.0096,4138.6558,,,,,
,30.36,1.011,4146.5898,,,,,
,30.4,1.0123,4154.5303,,,,,
,30.44,1.0136,4161.5449,,,,,
,30.48,1.0149,4168.7485,,,,,
,30.52,1.0164,4177.7891,,,,,
,30.56,1.0178,4185.7759,,,,,
,30.6,1.019,4192.2363,,,,,
,30.64,1.0203,4200.0488,,,,,
,30.68,1.0217,4208.2822,,,,,
,30.72,1.023,4215.1919,,,,,
,30.76,1.0242,4222.0337,,,,,
,30.8,1.0256,4229.7495,,,,,
,30.84,1.027,4237.9648,,,,,
,30.88,1.0282,4244.8428,,,,,
,30.92,1.0296,4252.3833,,,,,
,30.96,1.031,4260.7954,,,,,
,31,1.0323,4267.8911,,,,,
,31.04,1.0335,4274.6079,,,,,
,31.08,1.0349,4282.1616,,,,,
,31.12,1.0363,4290.46,,,,,
,31.16,1.0376,4297.272,,,,,
,31.2,1.0388,4304.1768,,,,,
,31.24,1.0402,4312.4976,,,,,
,31.28,1.0416,4320.7383,,,,,
,31.32,1.0429,4327.3926,,,,,
,31.36,1.0443,4335.0146,,,,,
,31.4,1.0457,4343.5229,,,,,
,31.44,1.047,4350.5947,,,,,
,31.48,1.0482,4357.0371,,,,,
,31.52,1.0496,4364.3799,,,,,
,31.56,1.0509,4372.0322,,,,,
,31.6,1.0522,4379.104,,,,,
,31.64,1.0535,4386.252,,,,,
,31.68,1.055,4394.606,,,,,
,31.72,1.0564,4402.2891,,,,,
,31.76,1.0576,4408.4424,,,,,
,31.8,1.059,4415.9526,,,,,
,31.84,1.0604,4424.0088,,,,,
,31.88,1.0616,4430.665,,,,,
,31.92,1.0629,4437.1245,,,,,
,31.96,1.0643,4445.2183,,,,,
,32,1.0657,4453.4419,,,,,
,32.04,1.067,4459.7192,,,,,
,32.08,1.0683,4466.7173,,,,,
,32.12,1.0697,4474.9902,,,,,
,32.16,1.0711,4482.3555,,,,,
,32.2,1.0723,4488.6255,,,,,
,32.24,1.0736,4495.9282,,,,,
,32.28,1.075,4504.1816,,,,,
,32.32,1.0763,4510.7778,,,,,
,32.36,1.0776,4517.228,,,,,
,32.4,1.079,4525.1465,,,,,
,32.44,1.0803,4532.4595,,,,,
,32.48,1.0816,4538.6689,,,,,
,32.52,1.0829,4545.7637,,,,,
,32.56,1.0843,4554.3047,,,,,
,32.6,1.0857,4561.168,,,,,
,32.64,1.0869,4567.23,,,,,
,32.68,1.0883,4574.8354,,,,,
,32.72,1.0897,4582.4331,,,,,
,32.76,1.0909,4588.8467,,,,,
,32.8,1.0922,4595.3604,,,,,
,32.84,1.0937,4603.3237,,,,,
,32.88,1.095,4610.3726,,,,,
,32.92,1.0962,4615.7954,,,,,
,32.96,1.0975,4622.0688,,,,,
,33,1.0989,4629.7393,,,,,
,33.04,1.1002,4636.7334,,,,,
,33.08,1.1015,4643.4004,,,,,
,33.12,1.1029,4651.043,,,,,
,33.16,1.1044,4659.0298,,,,,
,33.2,1.1056,4665.2432,,,,,
,33.24,1.1069,4671.4888,,,,,
,33.28,1.1083,4678.9502,,,,,
,33.32,1.1096,4686.0469,,,,,
,33.36,1.1108,4692.2212,,,,,
,33.4,1.1122,4699.9746,,,,,
,33.44,1.1137,4708.5361,,,,,
,33.48,1.115,4715.1631,,,,,
,33.52,1.1163,4721.5342,,,,,
,33.56,1.1177,4729.3164,,,,,
,33.6,1.1191,4736.8071,,,,,
,33.64,1.1203,4742.79,,,,,
,33.68,1.1216,4748.2266,,,,,
,33.72,1.123,4755.1431,,,,,
,33.76,1.1243,4760.8418,,,,,
,33.8,1.1256,4764.4517,,,,,
,33.84,1.1269,4768.1577,,,,,
,33.88,1.1283,4775.1016,,,,,
,33.92,1.1296,4781.0654,,,,,
,33.96,1.1309,4786.9702,,,,,
,34,1.1323,4793.6123,,,,,
,34.04,1.1337,4799.6099,,,,,
,34.08,1.1349,4805.3657,,,,,
,34.12,1.1363,4812.0762,,,,,
,34.16,1.1377,4819.6475,,,,,
,34.2,1.139,4826.0859,,,,,
,34.24,1.1402,4831.936,,,,,
,34.28,1.1416,4839.0117,,,,,
,34.32,1.1431,4847.0264,,,,,
,34.36,1.1444,4853.2114,,,,,
,34.4,1.1456,4859.4082,,,,,
,34.44,1.147,4865.749,,,,,
,34.48,1.1483,4871.9453,,,,,
,34.52,1.1495,4877.6387,,,,,
,34.56,1.1509,4884.5171,,,,,
,34.6,1.1523,4892.2563,,,,,
,34.64,1.1536,4898.8423,,,,,
,34.68,1.1548,4905.0552,,,,,
,34.72,1.1562,4912.2822,,,,,
,34.76,1.1576,4919.4185,,,,,
,34.8,1.1589,4925.4604,,,,,
,34.84,1.1602,4932.3472,,,,,
,34.88,1.1617,4940.4443,,,,,
,34.92,1.1631,4946.333,,,,,
,34.96,1.1643,4952.0107,,,,,
,35,1.1656,4959.2124,,,,,
,35.04,1.167,4966.208,,,,,
,35.08,1.1683,4971.1396,,,,,
,35.12,1.1696,4977.3574,,,,,
,35.16,1.1709,4984.6685,,,,,
,35.2,1.1723,4991.6372,,,,,
,35.24,1.1736,4997.5391,,,,,
,35.28,1.1749,5004.2739,,,,,
,35.32,1.1764,5011.5835,,,,,
,35.36,1.1777,5017.1802,,,,,
,35.4,1.1789,5022.6675,,,,,
,35.44,1.1803,5029.9717,,,,,
,35.48,1.1817,5037.418,,,,,
,35.52,1.183,5043.1064,,,,,
,35.56,1.1842,5049.3809,,,,,
,35.6,1.1857,5056.8545,,,,,
,35.64,1.1871,5064.0825,,,,,
,35.68,1.1883,5069.7627,,,,,
,35.72,1.1897,5076.0723,,,,,
,35.76,1.1911,5082.4248,,,,,
,35.8,1.1924,5088.1089,,,,,
,35.84,1.1936,5093.2847,,,,,
,35.88,1.1949,5099.6606,,,,,
,35.92,1.1963,5105.1675,,,,,
,35.96,1.1975,5111.2598,,,,,
,36,1.1988,5118.0361,,,,,
,36.04,1.2003,5125.7896,,,,,
,36.08,1.2017,5132.4878,,,,,
,36.12,1.2029,5136.813,,,,,
,36.16,1.2043,5143.6567,,,,,
,36.2,1.2057,5150.6377,,,,,
,36.24,1.2069,5156.1357,,,,,
,36.28,1.2082,5162.3872,,,,,
,36.32,1.2096,5169.8076,,,,,
,36.36,1.211,5177.0205,,,,,
,36.4,1.2123,5182.7866,,,,,
,36.44,1.2136,5189.4097,,,,,
,36.48,1.215,5196.7847,,,,,
,36.52,1.2163,5203.0122,,,,,
,36.56,1.2176,5208.9014,,,,,
,36.6,1.2189,5215.457,,,,,
,36.64,1.2203,5222.8438,,,,,
,36.68,1.2216,5228.9102,,,,,
,36.72,1.2229,5234.7383,,,,,
,36.76,1.2243,5241.9023,,,,,
,36.8,1.2256,5248.7368,,,,,
,36.84,1.2269,5254.2378,,,,,
,36.88,1.2282,5260.5112,,,,,
,36.92,1.2297,5268.0107,,,,,
,36.96,1.231,5273.9409,,,,,
,37,1.2323,5279.5132,,,,,
,37.04,1.2337,5286.7793,,,,,
,37.08,1.2351,5294.0625,,,,,
,37.12,1.2364,5299.8008,,,,,
,37.16,1.2376,5305.7339,,,,,
,37.2,1.2391,5313.022,,,,,
,37.24,1.2404,5319.333,,,,,
,37.28,1.2416,5324.6221,,,,,
,37.32,1.2429,5330.7012,,,,,
,37.36,1.2443,5337.3428,,,,,
,37.4,1.2456,5343.4126,,,,,
,37.44,1.2469,5349.2275,,,,,
,37.48,1.2483,5356.4644,,,,,
,37.52,1.2497,5363.2417,,,,,
,37.56,1.251,5368.6899,,,,,
,37.6,1.2523,5374.5215,,,,,
,37.64,1.2537,5381.4678,,,,,
,37.68,1.2549,5387.2598,,,,,
,37.72,1.2562,5392.8799,,,,,
,37.76,1.2576,5399.7256,,,,,
,37.8,1.259,5407.2427,,,,,
,37.84,1.2603,5413.0562,,,,,
,37.88,1.2616,5418.7803,,,,,
,37.92,1.263,5425.8438,,,,,
,37.96,1.2644,5432.043,,,,,
,38,1.2656,5437.0405,,,,,
,38.04,1.2669,5442.5771,,,,,
,38.08,1.2683,5449.5005,,,,,
,38.12,1.2696,5455.2632,,,,,
,38.16,1.2708,5460.8369,,,,,
,38.2,1.2722,5467.4292,,,,,
,38.24,1.2736,5474.2397,,,,,
,38.28,1.2749,5479.9702,,,,,
,38.32,1.2762,5485.7544,,,,,
,38.36,1.2776,5492.8843,,,,,
,38.4,1.279,5499.2095,,,,,
,38.44,1.2802,5504.6113,,,,,
,38.48,1.2816,5510.7383,,,,,
,38.52,1.283,5517.7754,,,,,
,38.56,1.2843,5523.6914,,,,,
,38.6,1.2856,5529.2065,,,,,
,38.64,1.287,5536.415,,,,,
,38.68,1.2884,5543.1812,,,,,
,38.72,1.2897,5548.3135,,,,,
,38.76,1.291,5553.876,,,,,
,38.8,1.2923,5560.4121,,,,,
,38.84,1.2937,5566.3486,,,,,
,38.88,1.2949,5571.5098,,,,,
,38.92,1.2963,5578.1138,,,,,
,38.96,1.2977,5584.8247,,,,,
,39,1.299,5590.5415,,,,,
,39.04,1.3002,5595.8013,,,,,
,39.08,1.3016,5602.4507,,,,,
,39.12,1.303,5608.7705,,,,,
,39.16,1.3043,5614.228,,,,,
,39.2,1.3056,5620.1665,,,,,
,39.24,1.3071,5627.6455,,,,,
,39.28,1.3084,5633.6396,,,,,
,39.32,1.3096,5638.5713,,,,,
,39.36,1.311,5644.7568,,,,,
,39.4,1.3124,5651.2051,,,,,
,39.44,1.3136,5656.271,,,,,
,39.48,1.3149,5661.5044,,,,,
,39.52,1.3163,5668.2593,,,,,
,39.56,1.3177,5674.6289,,,,,
,39.6,1.3189,5679.793,,,,,
,39.64,1.3202,5685.7529,,,,,
,39.68,1.3217,5692.4932,,,,,
,39.72,1.323,5697.8223,,,,,
,39.76,1.3242,5703.0083,,,,,
,39.8,1.3256,5709.0996,,,,,
,39.84,1.327,5715.5249,,,,,
,39.88,1.3282,5720.6567,,,,,
,39.92,1.3295,5725.8311,,,,,
,39.96,1.3309,5732.5361,,,,,
,40,1.3323,5738.7407,,,,,
,40.04,1.3336,5743.8486,,,,,
,40.08,1.335,5749.7017,,,,,
,40.12,1.3364,5756.2129,,,,,
,40.16,1.3377,5761.4263,,,,,
,40.2,1.3389,5765.707,,,,,
,40.24,1.3403,5771.3511,,,,,
,40.28,1.3416,5777.1431,,,,,
,40.32,1.3429,5782.2412,,,,,
,40.36,1.3442,5787.5181,,,,,
,40.4,1.3457,5794.3174,,,,,
,40.44,1.347,5799.9121,,,,,
,40.48,1.3483,5804.7422,,,,,
,40.52,1.3497,5810.5991,,,,,
,40.56,1.351,5816.5625,,,,,
,40.6,1.3523,5821.2812,,,,,
,40.64,1.3536,5826.2275,,,,,
,40.68,1.355,5832.4868,,,,,
,40.72,1.3564,5838.1377,,,,,
,40.76,1.3576,5842.418,,,,,
,40.8,1.359,5847.0835,,,,,
,40.84,1.3604,5852.9023,,,,,
,40.88,1.3617,5857.6831,,,,,
,40.92,1.3629,5861.9009,,,,,
,40.96,1.3643,5867.2812,,,,,
,41,1.3657,5872.8301,,,,,
,41.04,1.367,5877.1875,,,,,
,41.08,1.3682,5881.6841,,,,,
,41.12,1.3696,5887.0029,,,,,
,41.16,1.371,5891.8511,,,,,
,41.2,1.3722,5895.9971,,,,,
,41.24,1.3736,5900.3486,,,,,
,41.28,1.375,5905.084,,,,,
,41.32,1.3763,5909.1074,,,,,
,41.36,1.3775,5912.7471,,,,,
,41.4,1.3789,5918.0884,,,,,
,41.44,1.3803,5923.313,,,,,
,41.48,1.3816,5922.8477,,,,,
,41.52,1.3829,5923.9546,,,,,
,41.56,1.3843,5926.1392,,,,,
,41.6,1.3857,5929.8569,,,,,
,41.64,1.3869,5933.5972,,,,,
,41.68,1.3882,5938.2988,,,,,
,41.72,1.3896,5943.7222,,,,,
,41.76,1.3909,5948.2163,,,,,
,41.8,1.3922,5952.0869,,,,,
,41.84,1.3936,5957.8799,,,,,
,41.88,1.395,5963.7847,,,,,
,41.92,1.3963,5967.5601,,,,,
,41.96,1.3976,5972.4043,,,,,
,42,1.399,5977.8672,,,,,
,42.04,1.4003,5982.1011,,,,,
,42.08,1.4015,5986.1812,,,,,
,42.12,1.4029,5991.8745,,,,,
,42.16,1.4044,5997.6812,,,,,
,42.2,1.4057,6001.5488,,,,,
,42.24,1.407,6005.8623,,,,,
,42.28,1.4084,6011.3887,,,,,
,42.32,1.4098,6015.9858,,,,,
,42.36,1.411,6019.3198,,,,,
,42.4,1.4123,6023.5234,,,,,
,42.44,1.4137,6028.2881,,,,,
,42.48,1.415,6032.6533,,,,,
,42.52,1.4162,6036.4702,,,,,
,42.56,1.4176,6041.397,,,,,
,42.6,1.419,6045.4546,,,,,
,42.64,1.4203,6049.3892,,,,,
,42.68,1.4216,6053.1577,,,,,
,42.72,1.423,6058.54,,,,,
,42.76,1.4244,6063.0562,,,,,
,42.8,1.4256,6066.2437,,,,,
,42.84,1.4269,6070.9565,,,,,
,42.88,1.4284,6075.8433,,,,,
,42.92,1.4296,6079.4458,,,,,
,42.96,1.4309,6083.3457,,,,,
,43,1.4323,6088.4268,,,,,
,43.04,1.4337,6093.2661,,,,,
,43.08,1.435,6096.1455,,,,,
,43.12,1.4363,6099.5547,,,,,
,43.16,1.4376,6103.1021,,,,,
,43.2,1.4389,6105.0503,,,,,
,43.24,1.4402,6108.2344,,,,,
,43.28,1.4415,6112.4438,,,,,
,43.32,1.443,6115.8569,,,,,
,43.36,1.4443,6119.4712,,,,,
,43.4,1.4455,6122.7661,,,,,
,43.44,1.4469,6127.5386,,,,,
,43.48,1.4482,6131.6553,,,,,
,43.52,1.4495,6134.7554,,,,,
,43.56,1.4509,6138.9805,,,,,
,43.6,1.4523,6144.0381,,,,,
,43.64,1.4537,6148.0811,,,,,
,43.68,1.4549,6151.2051,,,,,
,43.72,1.4563,6155.0566,,,,,
,43.76,1.4577,6158.9194,,,,,
,43.8,1.4589,6161.6963,,,,,
,43.84,1.4602,6164.8525,,,,,
,43.88,1.4616,6169.3853,,,,,
,43.92,1.463,6173.3047,,,,,
,43.96,1.4643,6176.3608,,,,,
,44,1.4656,6180.3691,,,,,
,44.04,1.467,6184.9287,,,,,
,44.08,1.4683,6188.1226,,,,,
,44.12,1.4696,6190.3486,,,,,
,44.16,1.471,6194.0283,,,,,
,44.2,1.4724,6198.1099,,,,,
,44.24,1.4736,6200.9116,,,,,
,44.28,1.4749,6204.29,,,,,
,44.32,1.4763,6209.1445,,,,,
,44.36,1.4777,6212.8984,,,,,
,44.4,1.479,6215.0645,,,,,
,44.44,1.4804,6219.0503,,,,,
,44.48,1.4818,6223.7593,,,,,
,44.52,1.4831,6226.4961,,,,,
,44.56,1.4843,6229.0601,,,,,
,44.6,1.4856,6231.6602,,,,,
,44.64,1.487,6234.8774,,,,,
,44.68,1.4882,6238.0562,,,,,
,44.72,1.4895,6241.749,,,,,
,44.76,1.491,6246.1313,,,,,
,44.8,1.4923,6249.3452,,,,,
,44.84,1.4936,6250.5171,,,,,
,44.88,1.495,6250.9165,,,,,
,44.92,1.4963,6253.896,,,,,
,44.96,1.4975,6256.2554,,,,,
,45,1.4988,6258.7036,,,,,
,45.04,1.5003,6262.73,,,,,
,45.08,1.5017,6266.2705,,,,,
,45.12,1.5029,6268.2568,,,,,
,45.16,1.5042,6271.5547,,,,,
,45.2,1.5057,6274.5698,,,,,
,45.24,1.507,6277.2578,,,,,
,45.28,1.5082,6279.584,,,,,
,45.32,1.5096,6282.9209,,,,,
,45.36,1.511,6286.4468,,,,,
,45.4,1.5123,6288.7275,,,,,
,45.44,1.5135,6291.3916,,,,,
,45.48,1.515,6295.062,,,,,
,45.52,1.5163,6297.8862,,,,,
,45.56,1.5175,6299.4404,,,,,
,45.6,1.5189,6300.6079,,,,,
,45.64,1.5204,6303.501,,,,,
,45.68,1.5217,6305.335,,,,,
,45.72,1.5229,6306.4248,,,,,
,45.76,1.5243,6309.2739,,,,,
,45.8,1.5257,6312.4971,,,,,
,45.84,1.527,6313.9414,,,,,
,45.88,1.5283,6316.3555,,,,,
,45.92,1.5298,6319.6509,,,,,
,45.96,1.5311,6321.9004,,,,,
,46,1.5323,6322.9336,,,,,
,46.04,1.5336,6325.1431,,,,,
,46.08,1.535,6327.9717,,,,,
,46.12,1.5363,6329.6968,,,,,
,46.16,1.5376,6331.9438,,,,,
,46.2,1.539,6335.5327,,,,,
,46.24,1.5404,6338.1709,,,,,
,46.28,1.5416,6339.6299,,,,,
,46.32,1.5429,6341.626,,,,,
,46.36,1.5443,6344.2759,,,,,
,46.4,1.5456,6345.9141,,,,,
,46.44,1.5469,6347.4819,,,,,
,46.48,1.5483,6350.4023,,,,,
,46.52,1.5497,6353.3022,,,,,
,46.56,1.551,6354.7163,,,,,
,46.6,1.5523,6356.5396,,,,,
,46.64,1.5537,6359.1919,,,,,
,46.68,1.555,6360.165,,,,,
,46.72,1.5562,6360.7812,,,,,
,46.76,1.5575,6362.6968,,,,,
,46.8,1.5589,6365.3325,,,,,
,46.84,1.5602,6367.1382,,,,,
,46.88,1.5615,6368.4517,,,,,
,46.92,1.5629,6370.6411,,,,,
,46.96,1.5643,6370.8647,,,,,
,47,1.5656,6372.106,,,,,
,47.04,1.5669,6374.6357,,,,,
,47.08,1.5683,6377.2969,,,,,
,47.12,1.5696,6379.2183,,,,,
,47.16,1.5709,6379.9351,,,,,
,47.2,1.5722,6382.2588,,,,,
,47.24,1.5737,6385.0767,,,,,
,47.28,1.575,6386.4238,,,,,
,47.32,1.5762,6387.4082,,,,,
,47.36,1.5777,6389.7617,,,,,
,47.4,1.5791,6392.1953,,,,,
,47.44,1.5803,6393.1206,,,,,
,47.48,1.5816,6394.9414,,,,,
,47.52,1.583,6397.7358,,,,,
,47.56,1.5843,6399.5771,,,,,
,47.6,1.5856,6401.0928,,,,,
,47.64,1.587,6404.1509,,,,,
,47.68,1.5884,6407.2876,,,,,
,47.72,1.5896,6408.54,,,,,
,47.76,1.5909,6410.2041,,,,,
,47.8,1.5923,6413.1118,,,,,
,47.84,1.5937,6415.397,,,,,
,47.88,1.5949,6416.8096,,,,,
,47.92,1.5963,6418.9644,,,,,
,47.96,1.5978,6422.2158,,,,,
,48,1.5991,6423.8638,,,,,
,48.04,1.6003,6424.9551,,,,,
,48.08,1.6017,6426.896,,,,,
,48.12,1.6031,6428.4487,,,,,
,48.16,1.6043,6429.585,,,,,
,48.2,1.6055,6430.5952,,,,,
,48.24,1.6069,6433.168,,,,,
,48.28,1.6083,6434.7051,,,,,
,48.32,1.6095,6435.4365,,,,,
,48.36,1.6109,6436.4111,,,,,
,48.4,1.6123,6438.2417,,,,,
,48.44,1.6136,6438.9751,,,,,
,48.48,1.6149,6440.0576,,,,,
,48.52,1.6163,6441.9282,,,,,
,48.56,1.6176,6442.8687,,,,,
,48.6,1.6189,6440.085,,,,,
,48.64,1.6202,6440.7954,,,,,
,48.68,1.6216,6442.9863,,,,,
,48.72,1.623,6443.4023,,,,,
,48.76,1.6242,6443.8931,,,,,
,48.8,1.6256,6445.5063,,,,,
,48.84,1.6271,6447.4976,,,,,
,48.88,1.6283,6447.7368,,,,,
,48.92,1.6296,6447.9141,,,,,
,48.96,1.6309,6449.377,,,,,
,49,1.6323,6450.291,,,,,
,49.04,1.6335,6450.4639,,,,,
,49.08,1.6349,6451.7012,,,,,
,49.12,1.6364,6453.5806,,,,,
,49.16,1.6377,6454.0498,,,,,
,49.2,1.6389,6454.1094,,,,,
,49.24,1.6403,6454.9624,,,,,
,49.28,1.6417,6455.6001,,,,,
,49.32,1.6429,6454.6841,,,,,
,49.36,1.6442,6454.5156,,,,,
,49.4,1.6457,6455.3037,,,,,
,49.44,1.6471,6455.0303,,,,,
,49.48,1.6483,6452.8413,,,,,
,49.52,1.6497,6444.0898,,,,,
,49.56,1.6511,6438.9897,,,,,
,49.6,1.6524,6434.4966,,,,,
,49.64,1.6536,6429.1558,,,,,
,49.68,1.655,6423.1045,,,,,
,49.72,1.6564,6416.9287,,,,,
,49.76,1.6576,6407.9517,,,,,
,49.8,1.6589,6398.8804,,,,,
,49.84,1.6603,6389.6982,,,,,
,49.88,1.6616,6378.1338,,,,,
,49.92,1.6629,6365.0278,,,,,
,49.96,1.6643,6351.5747,,,,,
,50,1.6657,6337.4927,,,,,
,50.04,1.667,6320.4302,,,,,
,50.08,1.6682,6301.7026,,,,,
,50.12,1.6697,6280.502,,,,,
,50.16,1.671,6251.563,,,,,
,50.2,1.6723,6207.1792,,,,,
,50.24,1.6736,6024.4771,,,,,
,50.28,1.6753,1127.738,,,,,
,50.32,1.6766,362.1035,,,,,
,50.36,1.6777,571.6218,,,,,
,50.4,1.679,592.2579,,,,,
,50.44,1.6804,596.9716,,,,,
,50.48,1.6816,606.4768,,,,,
,50.52,1.6829,615.7671,,,,,
,50.56,1.6844,625.363,,,,,
,50.6,1.6857,634.1654,,,,,
,50.64,1.687,641.9904,,,,,
,50.68,1.6883,650.35,,,,,
,50.72,1.6897,658.86,,,,,
,50.76,1.6909,666.4828,,,,,
,50.8,1.6922,673.9675,,,,,
,50.84,1.6936,682.4977,,,,,
,50.88,1.6951,690.7823,,,,,
,50.92,1.6964,697.9495,,,,,
,50.96,1.6977,705.5044,,,,,
,51,1.6991,713.3731,,,,,
,51.04,1.7004,720.6764,,,,,
,51.08,1.7016,727.0406,,,,,
,51.12,1.7029,734.4091,,,,,
,51.16,1.7043,741.9733,,,,,
,51.2,1.7056,748.5432,,,,,
,51.24,1.7069,754.9979,,,,,
,51.28,1.7083,762.6088,,,,,
,51.32,1.7097,769.6595,,,,,
,51.36,1.711,775.9388,,,,,
,51.4,1.7123,782.5037,,,,,
,51.44,1.7137,789.8242,,,,,
,51.48,1.715,795.8683,,,,,
,51.52,1.7163,801.5878,,,,,
,51.56,1.7176,808.2972,,,,,
,51.6,1.719,814.9894,,,,,
,51.64,1.7203,820.5524,,,,,
,51.68,1.7216,826.3399,,,,,
,51.72,1.723,833.2936,,,,,
,51.76,1.7244,839.225,,,,,
,51.8,1.7256,844.1722,,,,,
,51.84,1.7269,849.8162,,,,,
,51.88,1.7283,855.7053,,,,,
,51.92,1.7296,860.6451,,,,,
,51.96,1.7308,865.9348,,,,,
,52,1.7322,871.3857,,,,,
,52.04,1.7337,877.3248,,,,,
,52.08,1.7349,881.7116,,,,,
,52.12,1.7362,886.5095,,,,,
,52.16,1.7376,891.8463,,,,,
,52.2,1.7389,896.6329,,,,,
,52.24,1.7402,900.8036,,,,,
,52.28,1.7416,905.8013,,,,,
,52.32,1.7431,911.1187,,,,,
,52.36,1.7444,914.9222,,,,,
,52.4,1.7456,918.7906,,,,,
,52.44,1.747,923.2855,,,,,
,52.48,1.7483,927.595,,,,,
,52.52,1.7496,930.8937,,,,,
,52.56,1.7509,934.4501,,,,,
,52.6,1.7523,939.026,,,,,
,52.64,1.7536,942.8603,,,,,
,52.68,1.7549,945.7589,,,,,
,52.72,1.7563,949.5819,,,,,
,52.76,1.7577,953.7259,,,,,
,52.8,1.759,956.6448,,,,,
,52.84,1.7603,959.6998,,,,,
,52.88,1.7617,963.671,,,,,
,52.92,1.763,966.5671,,,,,
,52.96,1.7643,968.684,,,,,
,53,1.7656,971.7443,,,,,
,53.04,1.7671,975.3799,,,,,
,53.08,1.7684,978.1636,,,,,
,53.12,1.7696,980.4244,,,,,
,53.16,1.7711,983.6562,,,,,
,53.2,1.7725,986.8379,,,,,
,53.24,1.7737,988.5198,,,,,
,53.28,1.7749,990.2104,,,,,
,53.32,1.7763,992.9654,,,,,
,53.36,1.7776,995.1688,,,,,
,53.4,1.7788,996.9047,,,,,
,53.44,1.7802,999.5134,,,,,
,53.48,1.7817,1002.486,,,,,
,53.52,1.783,1003.9325,,,,,
,53.56,1.7843,1005.1819,,,,,
,53.6,1.7857,1007.5351,,,,,
,53.64,1.787,1009.3698,,,,,
,53.68,1.7882,1010.1835,,,,,
,53.72,1.7895,1011.7951,,,,,
,53.76,1.791,1014.215,,,,,
,53.8,1.7923,1015.7717,,,,,
,53.84,1.7936,1016.3039,,,,,
,53.88,1.7949,1017.4357,,,,,
,53.92,1.7963,1018.6484,,,,,
,53.96,1.7976,1018.8692,,,,,
,54,1.7988,1019.2991,,,,,
,54.04,1.8002,1020.3183,,,,,
,54.08,1.8016,1021.5913,,,,,
,54.12,1.8029,1021.8744,,,,,
,54.16,1.8042,1021.9735,,,,,
,54.2,1.8056,1022.9393,,,,,
,54.24,1.8069,1023.5281,,,,,
,54.28,1.8082,1024.0273,,,,,
,54.32,1.8096,1025.5452,,,,,
,54.36,1.8111,1026.8992,,,,,
,54.4,1.8123,1026.8817,,,,,
,54.44,1.8136,1027.4764,,,,,
,54.48,1.8151,1028.621,,,,,
,54.52,1.8164,1029.1514,,,,,
,54.56,1.8176,1029.2325,,,,,
,54.6,1.819,1030.0355,,,,,
,54.64,1.8204,1031.2004,,,,,
,54.68,1.8217,1031.2096,,,,,
,54.72,1.8229,1031.0303,,,,,
,54.76,1.8242,1032.1505,,,,,
,54.8,1.8256,1033.183,,,,,
,54.84,1.8269,1033.3965,,,,,
,54.88,1.8282,1034.1188,,,,,
,54.92,1.8297,1035.2808,,,,,
,54.944,1.8306,1035.5406,,,,,