File: Chassis/Inserts testing/shear testing_NO_CL/insert_test_150kN_samp1_20250915_161744_1.csv
Results Table 2,,,,,,,,,,
,Specimen label,Rate 1,Fixture separation,Geometry,Length,Thickness,Width,Diameter,,
,,(mm/min),(mm),,(mm),(mm),(mm),(mm),,
1,,2,101.6,Rectangular,101.6,12.7,76.2,,,
,,,,,,,,,,
1,Time,Displacement,Force (sample 1),,,,,,,
,(s),(mm),(N),,,Max Force (N),Max force (Lbf),,avg maxforce (N),avg max force
,0,0,-0.1362,,,5742.7456,1291.084892,,5683.6797,1277.805688
,0.14,0.0019,0.2437,,,,,,,
,0.28,0.0075,0.4479,,,,,,,
,0.42,0.0122,0.4287,,,,,,,
,0.56,0.0169,0.3592,,,,,,,
,0.7,0.0215,0.5773,,,,,,,
,0.84,0.0262,0.448,,,,,,,
,0.98,0.0309,0.423,,,,,,,
,1.12,0.0355,0.8695,,,,,,,
,1.26,0.0402,0.2115,,,,,,,
,1.4,0.0449,0.5314,,,,,,,
,1.54,0.0495,0.59,,,,,,,
,1.68,0.0543,0.6666,,,,,,,
,1.82,0.0589,0.9914,,,,,,,
,1.96,0.0635,0.9999,,,,,,,
,2.1,0.0683,0.6234,,,,,,,
,2.24,0.0729,0.9446,,,,,,,
,2.38,0.0775,0.8749,,,,,,,
,2.52,0.0822,0.9424,,,,,,,
,2.66,0.0868,0.849,,,,,,,
,2.8,0.0915,0.8203,,,,,,,
,2.94,0.0962,0.9234,,,,,,,
,3.08,0.1008,0.7551,,,,,,,
,3.22,0.1056,0.803,,,,,,,
,3.36,0.1102,0.9973,,,,,,,
,3.5,0.1148,0.9347,,,,,,,
,3.64,0.1196,1.1228,,,,,,,
,3.78,0.1241,1.0376,,,,,,,
,3.92,0.1288,1.3798,,,,,,,
,4.06,0.1336,1.1135,,,,,,,
,4.2,0.1382,1.0834,,,,,,,
,4.34,0.1428,1.502,,,,,,,
,4.48,0.1476,1.748,,,,,,,
,4.62,0.1522,2.2731,,,,,,,
,4.76,0.1568,3.0322,,,,,,,
,4.9,0.1615,2.7174,,,,,,,
,5.04,0.1662,2.9121,,,,,,,
,5.18,0.1708,2.8328,,,,,,,
,5.32,0.1755,3.1608,,,,,,,
,5.46,0.1802,2.4445,,,,,,,
,5.6,0.1849,2.8406,,,,,,,
,5.74,0.1896,2.9023,,,,,,,
,5.88,0.1942,2.8301,,,,,,,
,6.02,0.1989,2.8466,,,,,,,
,6.16,0.2035,2.832,,,,,,,
,6.3,0.2081,2.939,,,,,,,
,6.44,0.2129,2.8696,,,,,,,
,6.58,0.2176,3.0039,,,,,,,
,6.72,0.2222,3.082,,,,,,,
,6.86,0.227,3.1006,,,,,,,
,7,0.2316,2.881,,,,,,,
,7.14,0.2361,3.4016,,,,,,,
,7.28,0.2409,3.3791,,,,,,,
,7.42,0.2455,3.2855,,,,,,,
,7.56,0.2501,3.5133,,,,,,,
,7.7,0.2549,3.4442,,,,,,,
,7.84,0.2595,3.4876,,,,,,,
,7.98,0.2642,3.4848,,,,,,,
,8.12,0.2689,3.4322,,,,,,,
,8.26,0.2735,3.3734,,,,,,,
,8.4,0.2782,3.447,,,,,,,
,8.54,0.2829,3.4603,,,,,,,
,8.68,0.2874,3.6522,,,,,,,
,8.82,0.2922,3.8725,,,,,,,
,8.96,0.2969,3.835,,,,,,,
,9.1,0.3015,3.7532,,,,,,,
,9.24,0.3063,3.4365,,,,,,,
,9.38,0.3109,3.3639,,,,,,,
,9.52,0.3155,3.7986,,,,,,,
,9.66,0.3203,3.6384,,,,,,,
,9.8,0.3248,3.4165,,,,,,,
,9.94,0.3295,3.6084,,,,,,,
,10.08,0.3342,3.6261,,,,,,,
,10.22,0.3389,3.5878,,,,,,,
,10.36,0.3436,3.5759,,,,,,,
,10.5,0.3482,3.5979,,,,,,,
,10.64,0.3529,3.3996,,,,,,,
,10.78,0.3575,3.3557,,,,,,,
,10.92,0.3621,3.7433,,,,,,,
,11.06,0.3668,4.0735,,,,,,,
,11.2,0.3715,4.6566,,,,,,,
,11.34,0.3762,6.7206,,,,,,,
,11.48,0.3808,8.3128,,,,,,,
,11.62,0.3856,8.8751,,,,,,,
,11.76,0.3902,9.6461,,,,,,,
,11.9,0.3948,10.7596,,,,,,,
,12.04,0.3995,11.0077,,,,,,,
,12.18,0.4042,12.102,,,,,,,
,12.32,0.4088,12.6274,,,,,,,
,12.46,0.4136,12.8157,,,,,,,
,12.6,0.4182,13.2988,,,,,,,
,12.74,0.4228,13.1441,,,,,,,
,12.88,0.4276,13.7088,,,,,,,
,13.02,0.4322,13.7855,,,,,,,
,13.16,0.4368,14.3329,,,,,,,
,13.3,0.4416,14.2228,,,,,,,
,13.44,0.4461,14.4347,,,,,,,
,13.58,0.4509,14.2072,,,,,,,
,13.72,0.4555,14.7641,,,,,,,
,13.86,0.4601,14.8388,,,,,,,
,14,0.465,15.3869,,,,,,,
,14.14,0.4696,15.3625,,,,,,,
,14.28,0.4741,15.3766,,,,,,,
,14.42,0.4789,15.3558,,,,,,,
,14.56,0.4835,15.5593,,,,,,,
,14.7,0.4881,15.7318,,,,,,,
,14.84,0.4929,15.7911,,,,,,,
,14.98,0.4975,15.8848,,,,,,,
,15.12,0.5022,16.203,,,,,,,
,15.26,0.507,16.2958,,,,,,,
,15.4,0.5115,16.3994,,,,,,,
,15.54,0.5162,16.2508,,,,,,,
,15.68,0.5209,16.6236,,,,,,,
,15.82,0.5255,16.1934,,,,,,,
,15.96,0.5302,16.3643,,,,,,,
,16.1,0.5348,16.5761,,,,,,,
,16.24,0.5395,16.5741,,,,,,,
,16.38,0.5443,18.2787,,,,,,,
,16.52,0.5489,21.891,,,,,,,
,16.66,0.5535,25.9089,,,,,,,
,16.8,0.5582,29.9412,,,,,,,
,16.94,0.5629,34.4001,,,,,,,
,17.08,0.5675,39.2252,,,,,,,
,17.22,0.5722,44.1998,,,,,,,
,17.36,0.5769,49.2305,,,,,,,
,17.5,0.5815,54.9045,,,,,,,
,17.64,0.5863,59.861,,,,,,,
,17.78,0.5909,64.6453,,,,,,,
,17.92,0.5955,70.0531,,,,,,,
,18.06,0.6002,74.2078,,,,,,,
,18.2,0.6049,78.4504,,,,,,,
,18.34,0.6095,84.8206,,,,,,,
,18.48,0.6142,93.4413,,,,,,,
,18.62,0.6189,103.2138,,,,,,,
,18.76,0.6235,113.2612,,,,,,,
,18.9,0.6282,122.7454,,,,,,,
,19.04,0.6328,134.8615,,,,,,,
,19.18,0.6375,150.176,,,,,,,
,19.32,0.6422,166.0793,,,,,,,
,19.46,0.6468,182.3108,,,,,,,
,19.6,0.6516,199.5719,,,,,,,
,19.74,0.6562,216.7021,,,,,,,
,19.88,0.6608,235.1006,,,,,,,
,20.02,0.6656,256.1729,,,,,,,
,20.16,0.6702,276.5017,,,,,,,
,20.3,0.6749,297.7229,,,,,,,
,20.44,0.6796,319.7747,,,,,,,
,20.58,0.6842,341.6113,,,,,,,
,20.72,0.6888,364.7158,,,,,,,
,20.86,0.6936,388.1489,,,,,,,
,21,0.6982,411.6867,,,,,,,
,21.14,0.7029,435.1421,,,,,,,
,21.28,0.7075,459.2416,,,,,,,
,21.42,0.7122,483.9404,,,,,,,
,21.56,0.7169,509.5614,,,,,,,
,21.7,0.7215,534.6383,,,,,,,
,21.84,0.7262,559.925,,,,,,,
,21.98,0.7309,585.3923,,,,,,,
,22.12,0.7355,610.7377,,,,,,,
,22.26,0.7402,636.1461,,,,,,,
,22.4,0.7449,661.0066,,,,,,,
,22.54,0.7496,684.9293,,,,,,,
,22.68,0.7542,708.382,,,,,,,
,22.82,0.7589,731.7988,,,,,,,
,22.96,0.7635,755.0612,,,,,,,
,23.1,0.7682,776.8641,,,,,,,
,23.24,0.7729,798.4386,,,,,,,
,23.38,0.7775,819.1904,,,,,,,
,23.52,0.7822,839.9089,,,,,,,
,23.66,0.7869,861.6589,,,,,,,
,23.8,0.7915,882.6489,,,,,,,
,23.94,0.7962,903.1498,,,,,,,
,24.08,0.8009,924.9691,,,,,,,
,24.22,0.8055,946.4684,,,,,,,
,24.36,0.8102,967.2563,,,,,,,
,24.5,0.8149,989.1735,,,,,,,
,24.64,0.8195,1011.2346,,,,,,,
,24.78,0.8243,1035.1134,,,,,,,
,24.92,0.8289,1058.2535,,,,,,,
,25.06,0.8335,1079.9056,,,,,,,
,25.2,0.8383,1105.192,,,,,,,
,25.34,0.8429,1128.1503,,,,,,,
,25.48,0.8475,1150.4596,,,,,,,
,25.62,0.8522,1175.6775,,,,,,,
,25.76,0.8568,1199.705,,,,,,,
,25.9,0.8615,1225.2792,,,,,,,
,26.04,0.8663,1250.7893,,,,,,,
,26.18,0.8708,1274.4998,,,,,,,
,26.32,0.8755,1299.5996,,,,,,,
,26.46,0.8802,1324.9592,,,,,,,
,26.6,0.8848,1350.4594,,,,,,,
,26.74,0.8895,1376.5266,,,,,,,
,26.88,0.8942,1400.5656,,,,,,,
,27.02,0.8988,1425.634,,,,,,,
,27.16,0.9036,1452.7986,,,,,,,
,27.3,0.9082,1477.6495,,,,,,,
,27.44,0.9128,1504.0444,,,,,,,
,27.58,0.9176,1530.8329,,,,,,,
,27.72,0.9222,1556.5116,,,,,,,
,27.86,0.9268,1583.7195,,,,,,,
,28,0.9315,1610.6139,,,,,,,
,28.14,0.9362,1637.6553,,,,,,,
,28.28,0.9409,1663.3297,,,,,,,
,28.42,0.9455,1689.8621,,,,,,,
,28.56,0.9502,1717.166,,,,,,,
,28.7,0.9548,1743.7477,,,,,,,
,28.84,0.9595,1771.7372,,,,,,,
,28.98,0.9642,1798.713,,,,,,,
,29.12,0.9688,1826.0173,,,,,,,
,29.26,0.9736,1854.2117,,,,,,,
,29.4,0.9782,1881.6383,,,,,,,
,29.54,0.9829,1908.8752,,,,,,,
,29.68,0.9876,1937.062,,,,,,,
,29.82,0.9922,1964.0668,,,,,,,
,29.96,0.9969,1991.3844,,,,,,,
,30.1,1.0015,2018.6433,,,,,,,
,30.24,1.0061,2046.2943,,,,,,,
,30.38,1.0109,2075.3274,,,,,,,
,30.52,1.0155,2102.8835,,,,,,,
,30.66,1.0201,2130.3254,,,,,,,
,30.8,1.025,2160.2202,,,,,,,
,30.94,1.0296,2187.3853,,,,,,,
,31.08,1.0342,2213.6514,,,,,,,
,31.22,1.0389,2241.9492,,,,,,,
,31.36,1.0435,2269.4658,,,,,,,
,31.5,1.0482,2297.7534,,,,,,,
,31.64,1.0529,2326.3818,,,,,,,
,31.78,1.0575,2353.7119,,,,,,,
,31.92,1.0623,2383.0823,,,,,,,
,32.06,1.0669,2411.3096,,,,,,,
,32.2,1.0715,2438.9878,,,,,,,
,32.34,1.0762,2468.8567,,,,,,,
,32.48,1.0808,2496.0266,,,,,,,
,32.62,1.0855,2524.1023,,,,,,,
,32.76,1.0903,2553.2937,,,,,,,
,32.9,1.0948,2580.7244,,,,,,,
,33.04,1.0995,2609.7527,,,,,,,
,33.18,1.1043,2638.6465,,,,,,,
,33.32,1.1089,2665.8181,,,,,,,
,33.46,1.1135,2694.2009,,,,,,,
,33.6,1.1182,2722.3384,,,,,,,
,33.74,1.1229,2750.7302,,,,,,,
,33.88,1.1275,2776.7163,,,,,,,
,34.02,1.1322,2803.9346,,,,,,,
,34.16,1.1368,2831.1965,,,,,,,
,34.3,1.1416,2859.3875,,,,,,,
,34.44,1.1462,2886.6567,,,,,,,
,34.58,1.1509,2914.2363,,,,,,,
,34.72,1.1555,2942.7043,,,,,,,
,34.86,1.1602,2970.5903,,,,,,,
,35,1.1648,2998.5303,,,,,,,
,35.14,1.1695,3027.5383,,,,,,,
,35.28,1.1742,3054.8611,,,,,,,
,35.42,1.1788,3082.676,,,,,,,
,35.56,1.1836,3111.2434,,,,,,,
,35.7,1.1882,3138.2493,,,,,,,
,35.84,1.1928,3165.3154,,,,,,,
,35.98,1.1976,3193.9438,,,,,,,
,36.12,1.2022,3221.0869,,,,,,,
,36.26,1.2068,3247.5295,,,,,,,
,36.4,1.2116,3275.3787,,,,,,,
,36.54,1.2162,3300.3779,,,,,,,
,36.68,1.2209,3327.491,,,,,,,
,36.82,1.2256,3354.1111,,,,,,,
,36.96,1.2301,3380.0251,,,,,,,
,37.1,1.2349,3407.4292,,,,,,,
,37.24,1.2395,3434.0867,,,,,,,
,37.38,1.2441,3459.5486,,,,,,,
,37.52,1.2489,3487.1206,,,,,,,
,37.66,1.2535,3513.5208,,,,,,,
,37.8,1.2582,3540.3518,,,,,,,
,37.94,1.263,3568.0881,,,,,,,
,38.08,1.2675,3593.6418,,,,,,,
,38.22,1.2722,3619.2852,,,,,,,
,38.36,1.2769,3645.73,,,,,,,
,38.5,1.2815,3670.8215,,,,,,,
,38.64,1.2862,3697.2327,,,,,,,
,38.78,1.2909,3723.229,,,,,,,
,38.92,1.2955,3748.1865,,,,,,,
,39.06,1.3002,3774.0146,,,,,,,
,39.2,1.3049,3799.4658,,,,,,,
,39.34,1.3095,3824.4792,,,,,,,
,39.48,1.3142,3850.1064,,,,,,,
,39.62,1.3188,3874.7688,,,,,,,
,39.76,1.3235,3900.1672,,,,,,,
,39.9,1.3282,3925.7161,,,,,,,
,40.04,1.3329,3950.9558,,,,,,,
,40.18,1.3375,3975.73,,,,,,,
,40.32,1.3422,4001.3887,,,,,,,
,40.46,1.3469,4025.7153,,,,,,,
,40.6,1.3515,4050.238,,,,,,,
,40.74,1.3562,4075.5425,,,,,,,
,40.88,1.3609,4100.2769,,,,,,,
,41.02,1.3655,4124.4087,,,,,,,
,41.16,1.3702,4149.7559,,,,,,,
,41.3,1.3749,4173.4062,,,,,,,
,41.44,1.3795,4197.2578,,,,,,,
,41.58,1.3843,4222.5386,,,,,,,
,41.72,1.3889,4245.3379,,,,,,,
,41.86,1.3935,4268.2183,,,,,,,
,42,1.3982,4292.0205,,,,,,,
,42.14,1.4028,4315.0073,,,,,,,
,42.28,1.4076,4338.9409,,,,,,,
,42.42,1.4122,4361.1548,,,,,,,
,42.56,1.4168,4383.6934,,,,,,,
,42.7,1.4216,4407.3984,,,,,,,
,42.84,1.4262,4430.3232,,,,,,,
,42.98,1.4308,4452.2939,,,,,,,
,43.12,1.4356,4475.7021,,,,,,,
,43.26,1.4401,4497.3091,,,,,,,
,43.4,1.4448,4519.834,,,,,,,
,43.54,1.4496,4542.4199,,,,,,,
,43.68,1.4542,4553.894,,,,,,,
,43.82,1.4589,4572.7949,,,,,,,
,43.96,1.4636,4594.4326,,,,,,,
,44.1,1.4682,4613.8389,,,,,,,
,44.24,1.4729,4627.7056,,,,,,,
,44.38,1.4775,4645.9507,,,,,,,
,44.52,1.4822,4582.2246,,,,,,,
,44.66,1.4869,4574.2671,,,,,,,
,44.8,1.4915,4585.8179,,,,,,,
,44.94,1.4962,4604.6606,,,,,,,
,45.08,1.5009,4624.4375,,,,,,,
,45.22,1.5055,4644.1333,,,,,,,
,45.36,1.5102,4664.2021,,,,,,,
,45.5,1.5149,4680.7744,,,,,,,
,45.64,1.5195,4700.8452,,,,,,,
,45.78,1.5241,4721.9219,,,,,,,
,45.92,1.5289,4743.3022,,,,,,,
,46.06,1.5335,4764.7153,,,,,,,
,46.2,1.5382,4785.4409,,,,,,,
,46.34,1.5429,4805.8647,,,,,,,
,46.48,1.5476,4826.2017,,,,,,,
,46.62,1.5521,4844.3135,,,,,,,
,46.76,1.5569,4864.415,,,,,,,
,46.9,1.5615,4883.9155,,,,,,,
,47.04,1.5661,4898.7559,,,,,,,
,47.18,1.5709,4916.313,,,,,,,
,47.32,1.5755,4923.5493,,,,,,,
,47.46,1.5802,4939.6914,,,,,,,
,47.6,1.5849,4953.1694,,,,,,,
,47.74,1.5895,4968.6406,,,,,,,
,47.88,1.5942,4986.0562,,,,,,,
,48.02,1.5989,5002.5513,,,,,,,
,48.16,1.6034,5018.7329,,,,,,,
,48.3,1.6082,5036.4312,,,,,,,
,48.44,1.6129,5052.7925,,,,,,,
,48.58,1.6175,5069.0718,,,,,,,
,48.72,1.6223,5086.8384,,,,,,,
,48.86,1.6269,5101.9785,,,,,,,
,49,1.6315,5118.5063,,,,,,,
,49.14,1.6362,5134.2178,,,,,,,
,49.28,1.6408,5150.0527,,,,,,,
,49.42,1.6455,5165.2959,,,,,,,
,49.56,1.6503,5181.9731,,,,,,,
,49.7,1.6548,5196.5239,,,,,,,
,49.84,1.6596,5211.6152,,,,,,,
,49.98,1.6642,5226.1201,,,,,,,
,50.12,1.6688,5239.6782,,,,,,,
,50.26,1.6736,5255.0732,,,,,,,
,50.4,1.6781,5268.3179,,,,,,,
,50.54,1.6828,5282.3032,,,,,,,
,50.68,1.6876,5296.79,,,,,,,
,50.82,1.6922,5309.9814,,,,,,,
,50.96,1.6968,5323.3457,,,,,,,
,51.1,1.7016,5338.4863,,,,,,,
,51.24,1.7062,5351.0537,,,,,,,
,51.38,1.7108,5364.3428,,,,,,,
,51.52,1.7155,5377.6348,,,,,,,
,51.66,1.7202,5388.7153,,,,,,,
,51.8,1.7248,5401.3066,,,,,,,
,51.94,1.7295,5414.0254,,,,,,,
,52.08,1.7342,5426.8286,,,,,,,
,52.22,1.7389,5439.0166,,,,,,,
,52.36,1.7436,5451.73,,,,,,,
,52.5,1.7482,5463.8496,,,,,,,
,52.64,1.7528,5474.8345,,,,,,,
,52.78,1.7575,5483.2612,,,,,,,
,52.92,1.7622,5495.4253,,,,,,,
,53.06,1.7669,5507.3975,,,,,,,
,53.2,1.7715,5519.5669,,,,,,,
,53.34,1.7761,5530.7959,,,,,,,
,53.48,1.781,5543.8198,,,,,,,
,53.62,1.7856,5554.3901,,,,,,,
,53.76,1.7901,5565.4844,,,,,,,
,53.9,1.7949,5577.2603,,,,,,,
,54.04,1.7995,5587.4883,,,,,,,
,54.18,1.8041,5597.582,,,,,,,
,54.32,1.8089,5608.811,,,,,,,
,54.46,1.8135,5618.438,,,,,,,
,54.6,1.8182,5628.7817,,,,,,,
,54.74,1.8229,5638.7905,,,,,,,
,54.88,1.8275,5647.2051,,,,,,,
,55.02,1.8322,5656.5278,,,,,,,
,55.16,1.8368,5664.4478,,,,,,,
,55.3,1.8415,5671.7969,,,,,,,
,55.44,1.8462,5679.96,,,,,,,
,55.58,1.8508,5686.3159,,,,,,,
,55.72,1.8555,5693.2695,,,,,,,
,55.86,1.8603,5701.0347,,,,,,,
,56,1.8649,5706.4194,,,,,,,
,56.14,1.8695,5711.0405,,,,,,,
,56.28,1.8742,5715.7969,,,,,,,
,56.42,1.8788,5719.894,,,,,,,
,56.56,1.8835,5723.71,,,,,,,
,56.7,1.8882,5728.7705,,,,,,,
,56.84,1.8929,5732.4971,,,,,,,
,56.98,1.8975,5735.4253,,,,,,,
,57.12,1.9022,5737.9429,,,,,,,
,57.26,1.9069,5739.2056,,,,,,,
,57.4,1.9115,5740.7031,,,,,,,
,57.54,1.9162,5742.0508,,,,,,,
,57.68,1.9208,5741.71,,,,,,,
,57.82,1.9255,5738.7183,,,,,,,
,57.96,1.9302,5738.5215,,,,,,,
,58.1,1.9348,5737.7573,,,,,,,
,58.24,1.9396,5729.9443,,,,,,,
,58.38,1.9442,5727.1528,,,,,,,
,58.52,1.9488,5725.4194,,,,,,,
,58.66,1.9536,5725.9595,,,,,,,
,58.8,1.9582,5726.0327,,,,,,,
,58.94,1.9628,5724.4077,,,,,,,
,59.08,1.9676,5726.1943,,,,,,,
,59.22,1.9722,5725.9507,,,,,,,
,59.36,1.9768,5725.8779,,,,,,,
,59.5,1.9816,5726.5859,,,,,,,
,59.64,1.9862,5726.0957,,,,,,,
,59.78,1.9908,5725.4541,,,,,,,
,59.92,1.9956,5724.6504,,,,,,,
,60.06,2.0002,5723.6929,,,,,,,
,60.2,2.0048,5721.3252,,,,,,,
,60.34,2.0095,5720.1118,,,,,,,
,60.48,2.0142,5713.124,,,,,,,
,60.62,2.0189,5710.3164,,,,,,,
,60.76,2.0236,5701.7085,,,,,,,
,60.9,2.0282,5678.4155,,,,,,,
,61.04,2.0329,5667.4038,,,,,,,
,61.18,2.0375,5653.4126,,,,,,,
,61.32,2.0422,5638.8926,,,,,,,
,61.46,2.0469,5626.251,,,,,,,
,61.6,2.0515,5594.4644,,,,,,,
,61.74,2.0562,5566.6509,,,,,,,
,61.88,2.061,5545.0884,,,,,,,
,62.02,2.0655,5525.8433,,,,,,,
,62.16,2.0702,5508.5181,,,,,,,
,62.3,2.0749,5477.1919,,,,,,,
,62.44,2.0795,5457.3755,,,,,,,
,62.58,2.0842,5428.252,,,,,,,
,62.72,2.0888,5402.709,,,,,,,
,62.86,2.0935,5381.6899,,,,,,,
,63,2.0982,5361.8467,,,,,,,
,63.14,2.1029,5344.3076,,,,,,,
,63.28,2.1075,5327.5674,,,,,,,
,63.42,2.1122,5312.1494,,,,,,,
,63.56,2.1169,5298.6152,,,,,,,
,63.7,2.1215,5284.9834,,,,,,,
,63.84,2.1262,5272.1265,,,,,,,
,63.98,2.1309,5259.8291,,,,,,,
,64.12,2.1355,5239.6865,,,,,,,
,64.26,2.1403,5219.6353,,,,,,,
,64.4,2.1449,5181.5981,,,,,,,
,64.54,2.1495,5148.2705,,,,,,,
,64.68,2.1542,5118.248,,,,,,,
,64.82,2.1589,5087.6221,,,,,,,
,64.96,2.1635,5055.1377,,,,,,,
,65.1,2.1683,5018.9136,,,,,,,
,65.24,2.1729,4489.7778,,,,,,,
,65.38,2.1775,4104.9883,,,,,,,
,65.52,2.1823,3964.4409,,,,,,,
,65.66,2.1868,3884.4424,,,,,,,
,65.8,2.1916,3827.6416,,,,,,,
,65.94,2.1962,3778.3264,,,,,,,
,66.08,2.2008,3742.4927,,,,,,,
,66.22,2.2056,3716.5366,,,,,,,
,66.36,2.2102,3692.2192,,,,,,,
,66.5,2.2148,3671.0222,,,,,,,
,66.64,2.2196,3652.7083,,,,,,,
,66.78,2.2242,3636.1968,,,,,,,
,66.92,2.2289,3623.4058,,,,,,,
,67.06,2.2336,3611.2,,,,,,,
,67.2,2.2381,3595.0364,,,,,,,
,67.34,2.2429,3581.0349,,,,,,,
,67.48,2.2476,3572.0393,,,,,,,
,67.62,2.2522,3566.3086,,,,,,,
,67.76,2.2569,3560.0706,,,,,,,
,67.9,2.2616,3556.7698,,,,,,,
,68.04,2.2662,3554.5122,,,,,,,
,68.18,2.2709,3552.7603,,,,,,,
,68.32,2.2755,3551.1948,,,,,,,
,68.46,2.2802,3551.0054,,,,,,,
,68.6,2.2849,3547.8621,,,,,,,
,68.74,2.2895,3544.105,,,,,,,
,68.88,2.2941,3543.4351,,,,,,,
,69.02,2.2989,3545.0312,,,,,,,
,69.16,2.3036,3544.4065,,,,,,,
,69.3,2.3081,3544.8586,,,,,,,
,69.44,2.3129,3547.2065,,,,,,,
,69.58,2.3175,3549.9172,,,,,,,
,69.72,2.3222,3551.9873,,,,,,,
,69.86,2.3269,3555.5798,,,,,,,
,70,2.3316,3557.2295,,,,,,,
,70.14,2.3362,3557.4446,,,,,,,
,70.28,2.341,3558.7405,,,,,,,
,70.42,2.3456,3558.4417,,,,,,,
,70.56,2.3502,3556.6587,,,,,,,
,70.7,2.3549,3556.7166,,,,,,,
,70.84,2.3595,3556.4524,,,,,,,
,70.98,2.3642,3556.5056,,,,,,,
,71.12,2.3689,3556.6636,,,,,,,
,71.26,2.3735,3555.7139,,,,,,,
,71.4,2.3783,3556.2551,,,,,,,
,71.54,2.3829,3554.0752,,,,,,,
,71.68,2.3875,3552.0779,,,,,,,
,71.82,2.3922,3552.7354,,,,,,,
,71.96,2.3968,3551.4126,,,,,,,
,72.1,2.4015,3549.8464,,,,,,,
,72.24,2.4063,3548.1477,,,,,,,
,72.38,2.4108,3543.6313,,,,,,,
,72.52,2.4155,3541.0813,,,,,,,
,72.66,2.4203,3539.0186,,,,,,,
,72.8,2.4249,3527.4666,,,,,,,
,72.94,2.4295,3523.1919,,,,,,,
,73.08,2.4342,3519.4473,,,,,,,
,73.22,2.4388,3516.854,,,,,,,
,73.36,2.4435,3515.6267,,,,,,,
,73.5,2.4482,3514.4229,,,,,,,
,73.64,2.4529,3513.5994,,,,,,,
,73.78,2.4576,3514.7295,,,,,,,
,73.92,2.4622,3514.3865,,,,,,,
,74.06,2.4668,3515.502,,,,,,,
,74.2,2.4715,3517.1125,,,,,,,
,74.34,2.4762,3519.5745,,,,,,,
,74.48,2.4808,3521.2292,,,,,,,
,74.62,2.4855,3523.4036,,,,,,,
,74.76,2.4902,3525.896,,,,,,,
,74.9,2.4949,3517.1143,,,,,,,
,75.04,2.4996,3518.2493,,,,,,,
,75.18,2.5042,3516.9519,,,,,,,
,75.32,2.5088,3512.4875,,,,,,,
,75.46,2.5136,3513.1743,,,,,,,
,75.6,2.5182,3469.8933,,,,,,,
,75.74,2.5228,3433.8547,,,,,,,
,75.88,2.5276,3428.1118,,,,,,,
,76.02,2.5322,3426.5681,,,,,,,
,76.16,2.5369,3425.3774,,,,,,,
,76.3,2.5416,3416.8149,,,,,,,
,76.44,2.5461,3414.8838,,,,,,,
,76.58,2.5509,3416.6079,,,,,,,
,76.72,2.5555,3419.2197,,,,,,,
,76.86,2.5601,3422.8804,,,,,,,
,77,2.5649,3428.8132,,,,,,,
,77.14,2.5695,3433.4888,,,,,,,
,77.28,2.5742,3438.9753,,,,,,,
,77.42,2.579,3446.1123,,,,,,,
,77.56,2.5835,3452.6345,,,,,,,
,77.7,2.5882,3458.0002,,,,,,,
,77.84,2.5929,3464.0771,,,,,,,
,77.98,2.5975,3470.532,,,,,,,
,78.12,2.6022,3477.415,,,,,,,
,78.26,2.6069,3484.4375,,,,,,,
,78.4,2.6115,3490.4678,,,,,,,
,78.54,2.6162,3487.6479,,,,,,,
,78.68,2.6209,3490.2166,,,,,,,
,78.82,2.6255,3493.863,,,,,,,
,78.96,2.6302,3498.3484,,,,,,,
,79.1,2.6348,3501.698,,,,,,,
,79.24,2.6395,3505.2471,,,,,,,
,79.38,2.6442,3509.2275,,,,,,,
,79.52,2.6488,3511.1399,,,,,,,
,79.66,2.6535,3513.7273,,,,,,,
,79.8,2.6583,3518.187,,,,,,,
,79.94,2.6629,3521.1406,,,,,,,
,80.08,2.6675,3525.2698,,,,,,,
,80.22,2.6722,3528.7024,,,,,,,
,80.36,2.6769,3532.9316,,,,,,,
,80.5,2.6815,3536.7239,,,,,,,
,80.64,2.6862,3540.2615,,,,,,,
,80.78,2.6909,3543.7849,,,,,,,
,80.92,2.6955,3544.8208,,,,,,,
,81.06,2.7002,3544.4883,,,,,,,
,81.2,2.7049,3546.5134,,,,,,,
,81.34,2.7095,3549.1191,,,,,,,
,81.48,2.7142,3551.7539,,,,,,,
,81.62,2.7188,3554.0054,,,,,,,
,81.76,2.7235,3557.1123,,,,,,,
,81.9,2.7282,3558.8469,,,,,,,
,82.04,2.7328,3559.2908,,,,,,,
,82.18,2.7376,3561.3311,,,,,,,
,82.32,2.7422,3562.5823,,,,,,,
,82.46,2.7468,3563.6526,,,,,,,
,82.6,2.7516,3555.8291,,,,,,,
,82.74,2.7562,3538.1492,,,,,,,
,82.88,2.7608,3522.3887,,,,,,,
,83.02,2.7656,3518.6389,,,,,,,
,83.16,2.7702,3516.551,,,,,,,
,83.3,2.7749,3516.644,,,,,,,
,83.44,2.7796,3518.2834,,,,,,,
,83.58,2.7842,3518.1367,,,,,,,
,83.72,2.7889,3515.282,,,,,,,
,83.86,2.7935,3513.6687,,,,,,,
,84,2.7981,3515.3538,,,,,,,
,84.14,2.8029,3518.2556,,,,,,,
,84.28,2.8075,3520.5234,,,,,,,
,84.42,2.8122,3524.0183,,,,,,,
,84.56,2.817,3528.375,,,,,,,
,84.7,2.8215,3531.3821,,,,,,,
,84.84,2.8262,3526.4126,,,,,,,
,84.98,2.8309,3528.1736,,,,,,,
,85.12,2.8355,3530.8303,,,,,,,
,85.26,2.8401,3534.2874,,,,,,,
,85.4,2.8449,3538.3018,,,,,,,
,85.54,2.8496,3542.1858,,,,,,,
,85.68,2.8542,3546.0042,,,,,,,
,85.82,2.8589,3550.0605,,,,,,,
,85.96,2.8636,3554.1836,,,,,,,
,86.1,2.8682,3552.228,,,,,,,
,86.24,2.8728,3544.2908,,,,,,,
,86.38,2.8775,3543.3359,,,,,,,
,86.52,2.8822,3543.3042,,,,,,,
,86.66,2.8869,3544.1724,,,,,,,
,86.8,2.8915,3523.4158,,,,,,,
,86.94,2.8962,3519.7415,,,,,,,
,87.08,2.9009,3518.2441,,,,,,,
,87.22,2.9055,3517.8672,,,,,,,
,87.36,2.9102,3519.1145,,,,,,,
,87.5,2.9149,3517.7551,,,,,,,
,87.64,2.9194,3512.7925,,,,,,,
,87.78,2.9243,3510.3469,,,,,,,
,87.92,2.9289,3509.3564,,,,,,,
,88.06,2.9335,3509.199,,,,,,,
,88.2,2.9383,3445.2195,,,,,,,
,88.34,2.9429,3432.3762,,,,,,,
,88.48,2.9475,3432.1404,,,,,,,
,88.62,2.9522,3436.7065,,,,,,,
,88.76,2.9568,3442.1843,,,,,,,
,88.9,2.9615,3448.9641,,,,,,,
,89.04,2.9662,3437.4485,,,,,,,
,89.18,2.9708,3441.4658,,,,,,,
,89.32,2.9756,3448.8586,,,,,,,
,89.46,2.9802,3455.8047,,,,,,,
,89.6,2.9848,3463.2068,,,,,,,
,89.74,2.9896,3472.4023,,,,,,,
,89.88,2.9942,3476.0295,,,,,,,
,90.02,2.9988,3483.3777,,,,,,,
,90.16,3.0036,3492.0547,,,,,,,
,90.3,3.0082,3499.6028,,,,,,,
,90.44,3.0129,3503.0515,,,,,,,
,90.58,3.0176,3510.5442,,,,,,,
,90.72,3.0222,3517.4888,,,,,,,
,90.86,3.0268,3525.1292,,,,,,,
,91,3.0315,3532.9236,,,,,,,
,91.14,3.0362,3541.3652,,,,,,,
,91.28,3.0408,3549.1992,,,,,,,
,91.42,3.0455,3556.158,,,,,,,
,91.56,3.0502,3563.3574,,,,,,,
,91.7,3.0549,3569.1047,,,,,,,
,91.84,3.0596,3576.301,,,,,,,
,91.98,3.0642,3582.6138,,,,,,,
,92.12,3.0689,3589.7537,,,,,,,
,92.26,3.0735,3595.271,,,,,,,
,92.4,3.0781,3581.365,,,,,,,
,92.54,3.0829,3584.2947,,,,,,,
,92.68,3.0876,3586.5317,,,,,,,
,92.82,3.0922,3583.719,,,,,,,
,92.96,3.0969,3568.8286,,,,,,,
,93.1,3.1016,3562.4785,,,,,,,
,93.24,3.1061,3560.3794,,,,,,,
,93.38,3.1109,3560.9956,,,,,,,
,93.52,3.1155,3563.4617,,,,,,,
,93.66,3.1201,3567.1348,,,,,,,
,93.8,3.1249,3572.7708,,,,,,,
,93.94,3.1295,3577.6646,,,,,,,
,94.08,3.1342,3578.0396,,,,,,,
,94.22,3.1389,3583.2307,,,,,,,
,94.36,3.1435,3588.1123,,,,,,,
,94.5,3.1482,3594.2678,,,,,,,
,94.64,3.1528,3599.5918,,,,,,,
,94.78,3.1575,3603.7358,,,,,,,
,94.92,3.1622,3610.0393,,,,,,,
,95.06,3.1668,3614.4556,,,,,,,
,95.2,3.1715,3619.6963,,,,,,,
,95.34,3.1763,3626.1152,,,,,,,
,95.48,3.1809,3622.116,,,,,,,
,95.62,3.1855,3619.5977,,,,,,,
,95.76,3.1902,3618.9895,,,,,,,
,95.9,3.1948,3621.4502,,,,,,,
,96.04,3.1995,3624.7146,,,,,,,
,96.18,3.2042,3626.9353,,,,,,,
,96.32,3.2089,3630.4585,,,,,,,
,96.46,3.2136,3634.7424,,,,,,,
,96.6,3.2182,3638.5803,,,,,,,
,96.74,3.2229,3640.8989,,,,,,,
,96.88,3.2275,3631.5979,,,,,,,
,97.02,3.2322,3601.8203,,,,,,,
,97.16,3.2368,3599.1919,,,,,,,
,97.3,3.2415,3600.2998,,,,,,,
,97.44,3.2462,3600.3499,,,,,,,
,97.58,3.2508,3602.8057,,,,,,,
,97.72,3.2556,3598.21,,,,,,,
,97.86,3.2602,3577.1038,,,,,,,
,98,3.2648,3574.647,,,,,,,
,98.14,3.2695,3576.3127,,,,,,,
,98.28,3.2742,3573.7908,,,,,,,
,98.42,3.2788,3577.6304,,,,,,,
,98.56,3.2836,3583.4951,,,,,,,
,98.7,3.2882,3588.6589,,,,,,,
,98.84,3.2928,3590.9182,,,,,,,
,98.98,3.2976,3574.0535,,,,,,,
,99.12,3.3022,3576.6084,,,,,,,
,99.26,3.3068,3581.1836,,,,,,,
,99.4,3.3115,3497.9917,,,,,,,
,99.54,3.3161,3495.6875,,,,,,,
,99.68,3.3209,3498.5862,,,,,,,
,99.82,3.3255,3502.4075,,,,,,,
,99.96,3.3301,3506.749,,,,,,,
,100.1,3.3349,3513.5115,,,,,,,
,100.24,3.3396,3519.2354,,,,,,,
,100.38,3.3441,3525.3066,,,,,,,
,100.52,3.3489,3533.4829,,,,,,,
,100.66,3.3535,3518.6001,,,,,,,
,100.8,3.3581,3503.6384,,,,,,,
,100.94,3.3629,3506.7563,,,,,,,
,101.08,3.3675,3510.1492,,,,,,,
,101.22,3.3722,3515.1584,,,,,,,
,101.36,3.377,3521.4993,,,,,,,
,101.5,3.3815,3525.8999,,,,,,,
,101.64,3.3862,3533.543,,,,,,,
,101.78,3.3909,3539.7029,,,,,,,
,101.92,3.3955,3546.4924,,,,,,,
,102.06,3.4002,3518.2268,,,,,,,
,102.2,3.4048,3514.5344,,,,,,,
,102.34,3.4095,3517.8687,,,,,,,
,102.48,3.4142,3492.9883,,,,,,,
,102.62,3.4189,3492.7334,,,,,,,
,102.76,3.4235,3495.7751,,,,,,,
,102.9,3.4282,3500.8274,,,,,,,
,103.04,3.4328,3505.5422,,,,,,,
,103.18,3.4375,3511.4673,,,,,,,
,103.32,3.4422,3518.146,,,,,,,
,103.46,3.4469,3525.0403,,,,,,,
,103.6,3.4515,3530.2893,,,,,,,
,103.74,3.4562,3535.7112,,,,,,,
,103.88,3.4609,3541.4468,,,,,,,
,104.02,3.4655,3546.6287,,,,,,,
,104.16,3.4702,3551.0459,,,,,,,
,104.3,3.4749,3556.313,,,,,,,
,104.44,3.4795,3561.5251,,,,,,,
,104.58,3.4842,3566.4622,,,,,,,
,104.72,3.4889,3569.4233,,,,,,,
,104.86,3.4935,3574.0413,,,,,,,
,105,3.4983,3578.52,,,,,,,
,105.14,3.5028,3581.4067,,,,,,,
,105.28,3.5076,3582.676,,,,,,,
,105.42,3.5122,3582.8247,,,,,,,
,105.56,3.5168,3584.6423,,,,,,,
,105.7,3.5216,3589.2151,,,,,,,
,105.84,3.5262,3577.6711,,,,,,,
,105.98,3.5308,3579.4956,,,,,,,
,106.12,3.5356,3584.3074,,,,,,,
,106.26,3.5402,3588.3635,,,,,,,
,106.4,3.5449,3593.7351,,,,,,,
,106.54,3.5496,3599.1067,,,,,,,
,106.68,3.5541,3599.7515,,,,,,,
,106.82,3.5589,3601.9856,,,,,,,
,106.96,3.5636,3606.1619,,,,,,,
,107.1,3.5681,3608.2148,,,,,,,
,107.24,3.5729,3612.9082,,,,,,,
,107.38,3.5775,3616.4536,,,,,,,
,107.52,3.5822,3619.6746,,,,,,,
,107.66,3.5869,3611.2769,,,,,,,
,107.8,3.5915,3605.6287,,,,,,,
,107.94,3.5962,3605.0212,,,,,,,
,108.08,3.6009,3604.5234,,,,,,,
,108.22,3.6055,3601.3301,,,,,,,
,108.36,3.6102,3601.2974,,,,,,,
,108.5,3.615,3602.9937,,,,,,,
,108.64,3.6196,3603.9192,,,,,,,
,108.78,3.6242,3606.0361,,,,,,,
,108.92,3.6289,3609.0405,,,,,,,
,109.06,3.6336,3611.613,,,,,,,
,109.2,3.6381,3614.6846,,,,,,,
,109.34,3.6429,3618.3472,,,,,,,
,109.48,3.6475,3621.9302,,,,,,,
,109.62,3.6522,3618.843,,,,,,,
,109.76,3.6569,3606.7507,,,,,,,
,109.9,3.6615,3607.1848,,,,,,,
,110.04,3.6662,3609.2244,,,,,,,
,110.18,3.6708,3611.7163,,,,,,,
,110.32,3.6755,3614.8777,,,,,,,
,110.46,3.6802,3619.165,,,,,,,
,110.6,3.6849,3623.1323,,,,,,,
,110.74,3.6895,3626.7686,,,,,,,
,110.88,3.6943,3631.0911,,,,,,,
,111.02,3.6989,3635.1079,,,,,,,
,111.16,3.7035,3639.2993,,,,,,,
,111.3,3.7083,3644.6777,,,,,,,
,111.44,3.7129,3649.3342,,,,,,,
,111.58,3.7175,3648.6089,,,,,,,
,111.72,3.7223,3651.4539,,,,,,,
,111.86,3.7268,3654.5601,,,,,,,
,112,3.7316,3659.2913,,,,,,,
,112.14,3.7363,3663.6931,,,,,,,
,112.28,3.7408,3667.6914,,,,,,,
,112.42,3.7455,3672.5664,,,,,,,
,112.56,3.7502,3677.1084,,,,,,,
,112.7,3.7548,3679.824,,,,,,,
,112.84,3.7595,3676.7346,,,,,,,
,112.98,3.7642,3640.7415,,,,,,,
,113.12,3.7688,3637.7317,,,,,,,
,113.26,3.7736,3628.0833,,,,,,,
,113.4,3.7782,3625.75,,,,,,,
,113.54,3.7828,3626.7791,,,,,,,
,113.68,3.7876,3629.5029,,,,,,,
,113.82,3.7922,3630.7783,,,,,,,
,113.96,3.7968,3632.3076,,,,,,,
,114.1,3.8016,3635.3792,,,,,,,
,114.24,3.8062,3638.5754,,,,,,,
,114.38,3.8109,3642.6885,,,,,,,
,114.52,3.8156,3646.928,,,,,,,
,114.66,3.8202,3651.7263,,,,,,,
,114.8,3.8248,3640.1326,,,,,,,
,114.94,3.8295,3630.2051,,,,,,,
,115.08,3.8342,3630.7349,,,,,,,
,115.22,3.8388,3626.6863,,,,,,,
,115.36,3.8435,3628.7922,,,,,,,
,115.5,3.8482,3554.2988,,,,,,,
,115.64,3.8529,3516.5396,,,,,,,
,115.78,3.8576,3511.4551,,,,,,,
,115.92,3.8621,3510.6604,,,,,,,
,116.06,3.8669,3513.1685,,,,,,,
,116.2,3.8715,3506.5227,,,,,,,
,116.34,3.8761,3506.4451,,,,,,,
,116.48,3.8809,3509.7209,,,,,,,
,116.62,3.8856,3513.2087,,,,,,,
,116.76,3.8902,3516.6028,,,,,,,
,116.9,3.895,3522.4678,,,,,,,
,117.04,3.8996,3526.177,,,,,,,
,117.18,3.9042,3531.3037,,,,,,,
,117.32,3.9089,3534.6943,,,,,,,
,117.46,3.9135,3538.8901,,,,,,,
,117.6,3.9182,3544.3064,,,,,,,
,117.74,3.9229,3548.0735,,,,,,,
,117.88,3.9274,3551.2188,,,,,,,
,118.02,3.9323,3556.6831,,,,,,,
,118.16,3.9369,3560.7185,,,,,,,
,118.3,3.9415,3564.5291,,,,,,,
,118.44,3.9463,3569.7048,,,,,,,
,118.58,3.9508,3573.4128,,,,,,,
,118.72,3.9555,3578.0989,,,,,,,
,118.86,3.9603,3583.9377,,,,,,,
,119,3.9648,3587.9636,,,,,,,
,119.14,3.9695,3587.6169,,,,,,,
,119.28,3.9743,3589.0928,,,,,,,
,119.42,3.9789,3587.6006,,,,,,,
,119.56,3.9835,3588.7546,,,,,,,
,119.7,3.9882,3591.8308,,,,,,,
,119.84,3.9929,3594.2639,,,,,,,
,119.98,3.9975,3597.0227,,,,,,,
,120.12,4.0022,3600.3291,,,,,,,
,120.26,4.0069,3603.0977,,,,,,,
,120.4,4.0116,3606.6306,,,,,,,
,120.54,4.0162,3540.782,,,,,,,
,120.68,4.0208,3528.8125,,,,,,,
,120.82,4.0255,3525.5251,,,,,,,
,120.96,4.0302,3524.4939,,,,,,,
,121.1,4.0348,3524.7295,,,,,,,
,121.24,4.0395,3526.7305,,,,,,,
,121.38,4.0442,3527.8435,,,,,,,
,121.52,4.0488,3518.4897,,,,,,,
,121.66,4.0536,3517.2483,,,,,,,
,121.8,4.0582,3517.5881,,,,,,,
,121.94,4.0628,3519.3074,,,,,,,
,122.08,4.0676,3522.9983,,,,,,,
,122.22,4.0722,3526.3123,,,,,,,
,122.36,4.0768,3529.5598,,,,,,,
,122.5,4.0816,3534.5999,,,,,,,
,122.64,4.0862,3533.8257,,,,,,,
,122.78,4.0908,3537.2976,,,,,,,
,122.92,4.0956,3541.3188,,,,,,,
,123.06,4.1001,3544.8479,,,,,,,
,123.2,4.1049,3548.1467,,,,,,,
,123.34,4.1095,3550.1384,,,,,,,
,123.48,4.1141,3552.2764,,,,,,,
,123.62,4.1189,3556.249,,,,,,,
,123.76,4.1236,3559.0676,,,,,,,
,123.9,4.1282,3559.1953,,,,,,,
,124.04,4.133,3561.4407,,,,,,,
,124.18,4.1375,3551.3806,,,,,,,
,124.32,4.1422,3516.927,,,,,,,
,124.46,4.1469,3479.0491,,,,,,,
,124.6,4.1515,3469.417,,,,,,,
,124.74,4.1562,3466.7847,,,,,,,
,124.88,4.1609,3462.7095,,,,,,,
,125.02,4.1655,3461.0686,,,,,,,
,125.16,4.1702,3461.7388,,,,,,,
,125.3,4.1749,3461.6084,,,,,,,
,125.44,4.1795,3451.1855,,,,,,,
,125.58,4.1842,3445.4268,,,,,,,
,125.72,4.1888,3441.6963,,,,,,,
,125.86,4.1935,3438.9707,,,,,,,
,126,4.1982,3435.9912,,,,,,,
,126.14,4.2029,3424.0168,,,,,,,
,126.28,4.2075,3412.4429,,,,,,,
,126.42,4.2122,3409.8887,,,,,,,
,126.56,4.2169,3407.5471,,,,,,,
,126.7,4.2215,3406.0442,,,,,,,
,126.84,4.2262,3406.2632,,,,,,,
,126.98,4.2309,3406.5754,,,,,,,
,127.12,4.2355,3379.8496,,,,,,,
,127.26,4.2402,3363.5876,,,,,,,
,127.4,4.2449,3352.8306,,,,,,,
,127.54,4.2495,3347.6516,,,,,,,
,127.68,4.2543,3315.8474,,,,,,,
,127.82,4.2589,3311.7507,,,,,,,
,127.96,4.2635,3310.9792,,,,,,,
,128.1,4.2682,3311.6001,,,,,,,
,128.24,4.2728,3312.7056,,,,,,,
,128.38,4.2775,3313.6467,,,,,,,
,128.52,4.2822,3313.2004,,,,,,,
,128.66,4.2868,3313.3503,,,,,,,
,128.8,4.2916,3314.3335,,,,,,,
,128.94,4.2962,3312.241,,,,,,,
,129.08,4.3008,3309.7749,,,,,,,
,129.22,4.3056,3306.8972,,,,,,,
,129.36,4.3102,3305.3586,,,,,,,
,129.5,4.3148,3303.4031,,,,,,,
,129.64,4.3196,3302.616,,,,,,,
,129.78,4.3242,3300.3962,,,,,,,
,129.92,4.3289,3298.1221,,,,,,,
,130.06,4.3336,3298.2068,,,,,,,
,130.2,4.3382,3295.4026,,,,,,,
,130.34,4.3429,3291.1021,,,,,,,
,130.48,4.3475,3286.2576,,,,,,,
,130.62,4.3522,3281.8381,,,,,,,
,130.76,4.3569,3158.2463,,,,,,,
,130.9,4.3615,3127.6116,,,,,,,
,131.04,4.3662,3102.4873,,,,,,,
,131.18,4.3709,3084.2278,,,,,,,
,131.32,4.3755,3070.6392,,,,,,,
,131.46,4.3802,3061.1721,,,,,,,
,131.6,4.3849,3054.1616,,,,,,,
,131.74,4.3895,3046.9014,,,,,,,
,131.88,4.3942,3040.8621,,,,,,,
,132.02,4.3989,3034.7261,,,,,,,
,132.16,4.4036,3024.9331,,,,,,,
,132.3,4.4082,3015.6831,,,,,,,
,132.44,4.4129,3008.4016,,,,,,,
,132.58,4.4176,3002.4265,,,,,,,
,132.72,4.4222,2997.2219,,,,,,,
,132.86,4.4269,2992.3022,,,,,,,
,133,4.4315,2986.0879,,,,,,,
,133.14,4.4362,2981.3281,,,,,,,
,133.28,4.4409,2977.2688,,,,,,,
,133.42,4.4455,2973.7939,,,,,,,
,133.56,4.4502,2972.1035,,,,,,,
,133.7,4.4549,2971.793,,,,,,,
,133.84,4.4595,2972.0034,,,,,,,
,133.98,4.4642,2973.1602,,,,,,,
,134.12,4.4689,2972.4553,,,,,,,
,134.26,4.4734,2972.4626,,,,,,,
,134.4,4.4783,2973.9604,,,,,,,
,134.54,4.4829,2971.7678,,,,,,,
,134.68,4.4875,2968.3245,,,,,,,
,134.82,4.4923,2966.4785,,,,,,,
,134.96,4.4969,2964.7512,,,,,,,
,135.1,4.5015,2963.7539,,,,,,,
,135.24,4.5063,2964.6277,,,,,,,
,135.38,4.5108,2963.7207,,,,,,,
,135.52,4.5155,2963.1667,,,,,,,
,135.66,4.5203,2961.2336,,,,,,,
,135.8,4.5248,2958.8521,,,,,,,
,135.94,4.5296,2958.6555,,,,,,,
,136.08,4.5342,2955.5486,,,,,,,
,136.22,4.5388,2953.386,,,,,,,
,136.36,4.5436,2948.5476,,,,,,,
,136.5,4.5481,2942.4802,,,,,,,
,136.64,4.5528,2933.3521,,,,,,,
,136.78,4.5576,2928.918,,,,,,,
,136.92,4.5622,2921.8931,,,,,,,
,137.06,4.5669,2916.7593,,,,,,,
,137.2,4.5716,2912.3406,,,,,,,
,137.34,4.5762,2908.1052,,,,,,,
,137.48,4.5809,2905.1196,,,,,,,
,137.62,4.5855,2902.9919,,,,,,,
,137.76,4.5902,2899.7188,,,,,,,
,137.9,4.5948,2895.6877,,,,,,,
,138.04,4.5995,2892.209,,,,,,,
,138.18,4.6042,2889.5034,,,,,,,
,138.32,4.6089,2886.3606,,,,,,,
,138.46,4.6136,2883.5103,,,,,,,
,138.6,4.6182,2881.5737,,,,,,,
,138.74,4.6229,2879.6418,,,,,,,
,138.88,4.6275,2878.3154,,,,,,,
,139.02,4.6322,2876.8259,,,,,,,
,139.16,4.6368,2871.8196,,,,,,,
,139.3,4.6416,2868.4653,,,,,,,
,139.44,4.6461,2864.8533,,,,,,,
,139.58,4.651,2863.0527,,,,,,,
,139.72,4.6556,2860.1414,,,,,,,
,139.86,4.6601,2856.5154,,,,,,,
,140,4.6649,2852.7405,,,,,,,
,140.14,4.6695,2848.0388,,,,,,,
,140.28,4.6742,2843.3706,,,,,,,
,140.42,4.6789,2837.6318,,,,,,,
,140.56,4.6835,2831.4741,,,,,,,
,140.7,4.6882,2825.9104,,,,,,,
,140.84,4.6929,2821.71,,,,,,,
,140.98,4.6975,2814.9565,,,,,,,
,141.12,4.7022,2810.8667,,,,,,,
,141.26,4.7068,2808.4614,,,,,,,
,141.4,4.7115,2806.5339,,,,,,,
,141.54,4.7162,2803.7637,,,,,,,
,141.68,4.7209,2801.2744,,,,,,,
,141.82,4.7255,2798.9761,,,,,,,
,141.96,4.7303,2798.1814,,,,,,,
,142.1,4.7348,2796.53,,,,,,,
,142.24,4.7395,2795.5698,,,,,,,
,142.38,4.7443,2795.7876,,,,,,,
,142.52,4.7488,2794.98,,,,,,,
,142.66,4.7535,2794.0681,,,,,,,
,142.8,4.7582,2794.3147,,,,,,,
,142.94,4.7629,2794.6724,,,,,,,
,143.08,4.7675,2794.9243,,,,,,,
,143.22,4.7722,2795.9285,,,,,,,
,143.36,4.7769,2792.3035,,,,,,,
,143.5,4.7815,2792.3296,,,,,,,
,143.64,4.7862,2793.5618,,,,,,,
,143.78,4.7908,2795.3113,,,,,,,
,143.92,4.7955,2796.5994,,,,,,,
,144.06,4.8002,2797.9983,,,,,,,
,144.2,4.8048,2795.0928,,,,,,,
,144.34,4.8096,2794.8762,,,,,,,
,144.48,4.8142,2793.5237,,,,,,,
,144.62,4.8188,2792.0417,,,,,,,
,144.76,4.8235,2790.4795,,,,,,,
,144.9,4.8282,2789.6443,,,,,,,
,145.04,4.8328,2785.0503,,,,,,,
,145.18,4.8376,2785.2695,,,,,,,
,145.32,4.8422,2784.8899,,,,,,,
,145.46,4.8468,2784.4575,,,,,,,
,145.6,4.8516,2784.6133,,,,,,,
,145.74,4.8562,2783.7927,,,,,,,
,145.88,4.8609,2783.7217,,,,,,,
,146.02,4.8656,2784.2327,,,,,,,
,146.16,4.8701,2783.9443,,,,,,,
,146.3,4.8749,2784.5156,,,,,,,
,146.44,4.8795,2784.3662,,,,,,,
,146.58,4.8841,2783.332,,,,,,,
,146.72,4.8889,2784.6621,,,,,,,
,146.86,4.8936,2784.9595,,,,,,,
,147,4.8982,2781.6907,,,,,,,
,147.14,4.9029,2778.7922,,,,,,,
,147.28,4.9075,2774.7212,,,,,,,
,147.42,4.9122,2772.1831,,,,,,,
,147.56,4.9169,2770.3594,,,,,,,
,147.7,4.9215,2766.1223,,,,,,,
,147.84,4.9262,2763.2463,,,,,,,
,147.98,4.931,2760.0308,,,,,,,
,148.12,4.9356,2751.8789,,,,,,,
,148.26,4.9402,2736.7629,,,,,,,
,148.4,4.9448,2721.4038,,,,,,,
,148.54,4.9495,2712.3076,,,,,,,
,148.68,4.9542,2698.9807,,,,,,,
,148.82,4.9589,2538.7263,,,,,,,
,148.96,4.9635,2523.916,,,,,,,
,149.1,4.9682,2495.4927,,,,,,,
,149.24,4.9729,2408.0303,,,,,,,
,149.38,4.9775,2363.7949,,,,,,,
,149.52,4.9822,2335.5869,,,,,,,
,149.66,4.9869,1588.0226,,,,,,,
,149.8,4.9915,1583.217,,,,,,,
,149.94,4.9962,1576.0924,,,,,,,
,150.08,5.0009,1578.5552,,,,,,,
,150.22,5.0055,1581.6406,,,,,,,
,150.36,5.0103,1585.5667,,,,,,,
,150.5,5.0149,1588.3905,,,,,,,
,150.64,5.0195,1591.3547,,,,,,,
,150.78,5.0242,1587.7357,,,,,,,
,150.92,5.0289,1588.9325,,,,,,,
,151.06,5.0335,1592.1608,,,,,,,
,151.2,5.0382,1595.9043,,,,,,,
,151.34,5.0428,1598.7238,,,,,,,
,151.48,5.0476,1601.3628,,,,,,,
,151.62,5.0523,1521.589,,,,,,,
,151.76,5.0568,1514.7441,,,,,,,
,151.9,5.0616,1505.7562,,,,,,,
,152.04,5.0662,1503.0162,,,,,,,
,152.18,5.0708,1501.0814,,,,,,,
,152.32,5.0756,1503.0079,,,,,,,
,152.46,5.0802,1503.9528,,,,,,,
,152.6,5.0848,1505.0431,,,,,,,
,152.74,5.0896,1507.5151,,,,,,,
,152.88,5.0942,1509.0021,,,,,,,
,153.02,5.0988,1509.3812,,,,,,,
,153.16,5.1036,1510.1019,,,,,,,
,153.3,5.1082,1509.4958,,,,,,,
,153.44,5.1128,1503.2765,,,,,,,
,153.58,5.1176,1497.1575,,,,,,,
,153.72,5.1222,1495.2123,,,,,,,
,153.86,5.1269,1493.5585,,,,,,,
,154,5.1316,1488.3889,,,,,,,
,154.14,5.1362,1485.3801,,,,,,,
,154.28,5.1409,1480.9478,,,,,,,
,154.42,5.1455,1468.9834,,,,,,,
,154.56,5.1502,1462.5381,,,,,,,
,154.7,5.1549,1444.9778,,,,,,,
,154.84,5.1595,1439.2819,,,,,,,
,154.98,5.1642,1434.7209,,,,,,,
,155.12,5.1689,1429.6057,,,,,,,
,155.26,5.1736,1426.7025,,,,,,,
,155.4,5.1781,1423.7445,,,,,,,
,155.54,5.1829,1420.6281,,,,,,,
,155.68,5.1875,1418.8293,,,,,,,
,155.82,5.1922,1417.8733,,,,,,,
,155.96,5.1969,1416.4663,,,,,,,
,156.1,5.2016,1416.1997,,,,,,,
,156.24,5.2062,1416.259,,,,,,,
,156.38,5.211,1417.438,,,,,,,
,156.52,5.2156,1418.2095,,,,,,,
,156.66,5.2202,1416.9886,,,,,,,
,156.8,5.2249,1405.6366,,,,,,,
,156.94,5.2295,1345.8185,,,,,,,
,157.08,5.2342,1338.5759,,,,,,,
,157.22,5.2389,1334.4868,,,,,,,
,157.36,5.2435,1330.5364,,,,,,,
,157.5,5.2483,1329.1488,,,,,,,
,157.64,5.2529,1328.1722,,,,,,,
,157.78,5.2574,1327.6462,,,,,,,
,157.92,5.2622,1328.7885,,,,,,,
,158.06,5.2669,1330.1981,,,,,,,
,158.2,5.2715,1321.3904,,,,,,,
,158.34,5.2763,1322.1982,,,,,,,
,158.48,5.2808,1322.2126,,,,,,,
,158.62,5.2856,1323.8107,,,,,,,
,158.76,5.2903,1325.1952,,,,,,,
,158.9,5.2949,1325.9858,,,,,,,
,159.04,5.2995,1327.3079,,,,,,,
,159.18,5.3042,1328.9113,,,,,,,
,159.32,5.3088,1330.418,,,,,,,
,159.46,5.3136,1332.3376,,,,,,,
,159.6,5.3182,1333.3953,,,,,,,
,159.74,5.3229,1334.9366,,,,,,,
,159.88,5.3276,1336.662,,,,,,,
,160.02,5.3322,1336.6962,,,,,,,
,160.16,5.3368,1338.3489,,,,,,,
,160.3,5.3416,1340.2822,,,,,,,
,160.44,5.3462,1341.3572,,,,,,,
,160.58,5.3508,1342.1559,,,,,,,
,160.72,5.3555,1343.6975,,,,,,,
,160.86,5.3602,1345.0507,,,,,,,
,161,5.3649,1345.9343,,,,,,,
,161.14,5.3696,1346.5504,,,,,,,
,161.28,5.3742,1346.5743,,,,,,,
,161.42,5.3788,1347.2236,,,,,,,
,161.56,5.3836,1342.2388,,,,,,,
,161.7,5.3882,1342.1534,,,,,,,
,161.84,5.3928,1342.0625,,,,,,,
,161.98,5.3976,1339.9196,,,,,,,
,162.12,5.4022,1338.891,,,,,,,
,162.26,5.4069,1339.3652,,,,,,,
,162.4,5.4116,1339.5107,,,,,,,
,162.54,5.4161,1339.576,,,,,,,
,162.68,5.4209,1338.3571,,,,,,,
,162.82,5.4255,1338.9548,,,,,,,
,162.96,5.4301,1339.5776,,,,,,,
,163.1,5.4349,1341.3788,,,,,,,
,163.24,5.4395,1342.3163,,,,,,,
,163.38,5.4441,1343.0125,,,,,,,
,163.52,5.449,1345.7119,,,,,,,
,163.66,5.4535,1345.4729,,,,,,,
,163.8,5.4582,1346.6434,,,,,,,
,163.94,5.4629,1347.8182,,,,,,,
,164.08,5.4675,1347.2452,,,,,,,
,164.22,5.4722,1343.4417,,,,,,,
,164.36,5.4769,1343.0005,,,,,,,
,164.5,5.4815,1343.255,,,,,,,
,164.64,5.4862,1343.2751,,,,,,,
,164.78,5.4909,1343.785,,,,,,,
,164.92,5.4955,1344.2477,,,,,,,
,165.06,5.5002,1346.238,,,,,,,
,165.2,5.5048,1345.7294,,,,,,,
,165.34,5.5095,1346.0619,,,,,,,
,165.48,5.5142,1346.3873,,,,,,,
,165.62,5.5188,1342.7903,,,,,,,
,165.76,5.5235,1342.8,,,,,,,
,165.9,5.5283,1343.6676,,,,,,,
,166.04,5.5329,1344.1006,,,,,,,
,166.18,5.5375,1344.4631,,,,,,,
,166.32,5.5422,1345.0238,,,,,,,
,166.46,5.5469,1346.0521,,,,,,,
,166.6,5.5515,1346.6511,,,,,,,
,166.74,5.5562,1347.0499,,,,,,,
,166.88,5.5609,1347.4471,,,,,,,
,167.02,5.5655,1347.2203,,,,,,,
,167.16,5.5703,1346.8843,,,,,,,
,167.3,5.5749,1346.7015,,,,,,,
,167.44,5.5795,1346.5161,,,,,,,
,167.58,5.5842,1346.4751,,,,,,,
,167.72,5.5888,1331.3018,,,,,,,
,167.86,5.5935,1328.5839,,,,,,,
,168,5.5982,1327.156,,,,,,,
,168.14,5.6028,1324.9407,,,,,,,
,168.28,5.6076,1323.8074,,,,,,,
,168.42,5.6122,1313.0389,,,,,,,
,168.56,5.6168,1306.2722,,,,,,,
,168.7,5.6216,1303.603,,,,,,,
,168.84,5.6262,1301.0975,,,,,,,
,168.98,5.6308,1298.4597,,,,,,,
,169.12,5.6356,1294.7659,,,,,,,
,169.26,5.6402,1266.2786,,,,,,,
,169.4,5.6449,1239.5698,,,,,,,
,169.54,5.6496,1225.3932,,,,,,,
,169.68,5.6542,1219.0209,,,,,,,
,169.82,5.6589,1216.0802,,,,,,,
,169.96,5.6635,1213.3676,,,,,,,
,170.1,5.6682,1205.979,,,,,,,
,170.24,5.6729,1202.6415,,,,,,,
,170.38,5.6775,1198.2266,,,,,,,
,170.52,5.6822,1196.5946,,,,,,,
,170.66,5.687,1196.0505,,,,,,,
,170.8,5.6915,1195.5544,,,,,,,
,170.94,5.6962,1196.1759,,,,,,,
,171.08,5.7009,1196.566,,,,,,,
,171.22,5.7055,1196.5967,,,,,,,
,171.36,5.7102,1196.552,,,,,,,
,171.5,5.7149,1194.2729,,,,,,,
,171.64,5.7196,1192.9548,,,,,,,
,171.78,5.7242,1192.6046,,,,,,,
,171.92,5.7289,1192.037,,,,,,,
,172.06,5.7336,1192.1378,,,,,,,
,172.2,5.7382,1191.563,,,,,,,
,172.34,5.7428,1190.726,,,,,,,
,172.48,5.7475,1189.6576,,,,,,,
,172.62,5.7522,1189.9381,,,,,,,
,172.76,5.7569,1189.2213,,,,,,,
,172.9,5.7615,1186.8656,,,,,,,
,173.04,5.7662,1185.0884,,,,,,,
,173.18,5.7709,1183.8378,,,,,,,
,173.32,5.7755,1183.1084,,,,,,,
,173.46,5.7802,1179.8804,,,,,,,
,173.6,5.7849,1177.5958,,,,,,,
,173.74,5.7895,1175.385,,,,,,,
,173.88,5.7943,1172.6472,,,,,,,
,174.02,5.7989,1171.7665,,,,,,,
,174.16,5.8035,1169.6096,,,,,,,
,174.3,5.8083,1169.4288,,,,,,,
,174.44,5.8129,1168.5851,,,,,,,
,174.58,5.8175,1166.8903,,,,,,,
,174.72,5.8222,1156.5074,,,,,,,
,174.86,5.8268,1145.9073,,,,,,,
,175,5.8315,1141.0856,,,,,,,
,175.14,5.8362,1139.413,,,,,,,
,175.28,5.8408,1137.74,,,,,,,
,175.42,5.8456,1137.757,,,,,,,
,175.56,5.8502,1135.3472,,,,,,,
,175.7,5.8548,1130.6605,,,,,,,
,175.84,5.8596,1124.8693,,,,,,,
,175.98,5.8641,1120.373,,,,,,,
,176.12,5.8688,1118.2858,,,,,,,
,176.26,5.8736,1114.376,,,,,,,
,176.4,5.8781,1098.1829,,,,,,,
,176.54,5.8829,773.6523,,,,,,,
,176.68,5.8876,768.2484,,,,,,,
,176.82,5.8922,763.9503,,,,,,,
,176.96,5.8969,760.8553,,,,,,,
,177.1,5.9015,760.8309,,,,,,,
,177.24,5.9062,762.0417,,,,,,,
,177.38,5.9109,764.1494,,,,,,,
,177.52,5.9155,765.2913,,,,,,,
,177.66,5.9202,767.3723,,,,,,,
,177.8,5.9249,770.0779,,,,,,,
,177.94,5.9295,770.4319,,,,,,,
,178.08,5.9342,770.6948,,,,,,,
,178.22,5.9389,769.4559,,,,,,,
,178.36,5.9435,767.7436,,,,,,,
,178.5,5.9482,768.0259,,,,,,,
,178.64,5.9528,766.009,,,,,,,
,178.78,5.9576,764.1075,,,,,,,
,178.92,5.9622,764.1226,,,,,,,
,179.06,5.967,764.6984,,,,,,,
,179.2,5.9716,764.2906,,,,,,,
,179.34,5.9761,763.597,,,,,,,
,179.48,5.9809,762.5734,,,,,,,
,179.62,5.9855,762.3795,,,,,,,
,179.76,5.9901,762.0248,,,,,,,
,179.9,5.9949,762.4564,,,,,,,
,180.04,5.9995,761.0586,,,,,,,
,180.18,6.0042,752.5914,,,,,,,
,180.32,6.0089,741.83,,,,,,,
,180.46,6.0135,733.8531,,,,,,,
,180.6,6.0182,726.2916,,,,,,,
,180.74,6.0228,722.4154,,,,,,,
,180.88,6.0274,721.5515,,,,,,,
,181.02,6.0322,721.4412,,,,,,,
,181.16,6.0369,717.071,,,,,,,
,181.3,6.0415,712.8077,,,,,,,
,181.44,6.0463,708.1382,,,,,,,
,181.58,6.0509,703.7184,,,,,,,
,181.72,6.0555,701.7426,,,,,,,
,181.86,6.0603,698.5577,,,,,,,
,182,6.0648,695.1345,,,,,,,
,182.14,6.0695,693.746,,,,,,,
,182.28,6.0742,691.8632,,,,,,,
,182.42,6.0789,689.3077,,,,,,,
,182.56,6.0836,688.0671,,,,,,,
,182.7,6.0882,687.1368,,,,,,,
,182.84,6.0929,686.9434,,,,,,,
,182.98,6.0975,685.1581,,,,,,,
,183.12,6.1022,683.1868,,,,,,,
,183.26,6.1068,682.3818,,,,,,,
,183.4,6.1115,681.5308,,,,,,,
,183.54,6.1162,679.7893,,,,,,,
,183.68,6.1208,678.3197,,,,,,,
,183.82,6.1256,668.1481,,,,,,,
,183.96,6.1302,663.423,,,,,,,
,184.1,6.1348,659.9852,,,,,,,
,184.24,6.1395,656.4327,,,,,,,
,184.38,6.1442,654.0264,,,,,,,
,184.52,6.1488,652.2618,,,,,,,
,184.66,6.1536,649.7346,,,,,,,
,184.8,6.1582,647.1273,,,,,,,
,184.94,6.1628,643.7864,,,,,,,
,185.08,6.1676,643.2294,,,,,,,
,185.22,6.1722,575.3001,,,,,,,
,185.36,6.1768,571.6342,,,,,,,
,185.5,6.1815,569.4985,,,,,,,
,185.64,6.1861,566.1491,,,,,,,
,185.78,6.1909,566.7165,,,,,,,
,185.92,6.1955,565.9632,,,,,,,
,186.06,6.2001,565.2405,,,,,,,
,186.2,6.205,566.0835,,,,,,,
,186.34,6.2096,565.307,,,,,,,
,186.48,6.2141,562.7367,,,,,,,
,186.62,6.2189,561.0416,,,,,,,
,186.76,6.2235,560.119,,,,,,,
,186.9,6.2281,559.5413,,,,,,,
,187.04,6.2329,558.8575,,,,,,,
,187.18,6.2375,557.8437,,,,,,,
,187.32,6.2422,556.7931,,,,,,,
,187.46,6.247,554.9012,,,,,,,
,187.6,6.2515,538.4969,,,,,,,
,187.74,6.2562,536.1387,,,,,,,
,187.88,6.2609,534.7299,,,,,,,
,188.02,6.2655,534.5113,,,,,,,
,188.16,6.2702,534.7689,,,,,,,
,188.3,6.2748,534.1837,,,,,,,
,188.44,6.2795,534.3648,,,,,,,
,188.58,6.2843,534.7039,,,,,,,
,188.72,6.2889,534.3124,,,,,,,
,188.86,6.2935,533.2992,,,,,,,
,189,6.2982,533.2186,,,,,,,
,189.14,6.3028,532.9117,,,,,,,
,189.28,6.3075,531.6522,,,,,,,
,189.42,6.3122,530.0145,,,,,,,
,189.56,6.3169,529.2142,,,,,,,
,189.7,6.3215,529.0651,,,,,,,
,189.84,6.3262,528.275,,,,,,,
,189.98,6.3309,527.29,,,,,,,
,190.12,6.3355,527.3619,,,,,,,
,190.26,6.3402,526.1763,,,,,,,
,190.4,6.3449,524.1965,,,,,,,
,190.54,6.3495,521.8159,,,,,,,
,190.68,6.3542,519.0255,,,,,,,
,190.82,6.3588,516.4598,,,,,,,
,190.96,6.3635,514.8354,,,,,,,
,191.1,6.3682,513.2802,,,,,,,
,191.24,6.3728,510.9962,,,,,,,
,191.38,6.3775,509.0655,,,,,,,
,191.52,6.3822,506.7582,,,,,,,
,191.66,6.3868,505.8485,,,,,,,
,191.8,6.3916,505.2001,,,,,,,
,191.94,6.3962,503.5352,,,,,,,
,192.08,6.4008,502.7614,,,,,,,
,192.22,6.4056,503.42,,,,,,,
,192.36,6.4102,503.0388,,,,,,,
,192.5,6.4149,494.6743,,,,,,,
,192.64,6.4196,493.7577,,,,,,,
,192.78,6.4241,493.2882,,,,,,,
,192.92,6.4289,492.7227,,,,,,,
,193.06,6.4336,492.5506,,,,,,,
,193.2,6.4381,492.3789,,,,,,,
,193.34,6.4429,492.697,,,,,,,
,193.48,6.4475,492.9917,,,,,,,
,193.62,6.4521,492.3967,,,,,,,
,193.76,6.4569,492.9319,,,,,,,
,193.9,6.4615,492.2104,,,,,,,
,194.04,6.4662,492.0944,,,,,,,
,194.18,6.4709,492.5695,,,,,,,
,194.32,6.4755,492.3623,,,,,,,
,194.46,6.4802,491.5915,,,,,,,
,194.6,6.485,481.6384,,,,,,,
,194.74,6.4896,478.028,,,,,,,
,194.88,6.4942,476.5978,,,,,,,
,195.02,6.4989,474.4706,,,,,,,
,195.16,6.5035,473.8506,,,,,,,
,195.3,6.5081,472.9251,,,,,,,
,195.44,6.5129,472.1075,,,,,,,
,195.58,6.5176,471.6384,,,,,,,
,195.72,6.5222,471.268,,,,,,,
,195.86,6.5269,470.8747,,,,,,,
,196,6.5315,469.2643,,,,,,,
,196.14,6.5362,466.9733,,,,,,,
,196.28,6.5409,465.0879,,,,,,,
,196.42,6.5455,464.1911,,,,,,,
,196.56,6.5501,463.308,,,,,,,
,196.7,6.5549,462.5144,,,,,,,
,196.84,6.5595,460.8373,,,,,,,
,196.98,6.5643,460.8064,,,,,,,
,197.12,6.5689,460.5464,,,,,,,
,197.26,6.5735,459.8297,,,,,,,
,197.4,6.5782,460.0338,,,,,,,
,197.54,6.5829,459.9398,,,,,,,
,197.68,6.5875,459.3764,,,,,,,
,197.82,6.5923,459.3514,,,,,,,
,197.96,6.5968,458.8397,,,,,,,
,198.1,6.6015,458.638,,,,,,,
,198.24,6.6063,458.4297,,,,,,,
,198.38,6.6108,457.9017,,,,,,,
,198.52,6.6155,458.1081,,,,,,,
,198.66,6.6202,457.8118,,,,,,,
,198.8,6.6248,457.9889,,,,,,,
,198.94,6.6296,457.9112,,,,,,,
,199.08,6.6342,458.2648,,,,,,,
,199.22,6.6388,458.3149,,,,,,,
,199.36,6.6436,459.0704,,,,,,,
,199.5,6.6482,457.25,,,,,,,
,199.64,6.6528,457.3046,,,,,,,
,199.78,6.6576,457.3494,,,,,,,
,199.92,6.6622,457.5861,,,,,,,
,200.06,6.6668,457.9574,,,,,,,
,200.2,6.6715,458.1289,,,,,,,
,200.34,6.6762,457.6279,,,,,,,
,200.48,6.6809,458.1432,,,,,,,
,200.62,6.6856,457.5854,,,,,,,
,200.76,6.6902,457.8431,,,,,,,
,200.9,6.6948,458.2341,,,,,,,
,201.04,6.6995,457.9171,,,,,,,
,201.18,6.7042,457.9972,,,,,,,
,201.32,6.7088,457.9016,,,,,,,
,201.46,6.7135,456.4475,,,,,,,
,201.6,6.7182,453.9584,,,,,,,
,201.74,6.7229,452.788,,,,,,,
,201.88,6.7276,447.4043,,,,,,,
,202.02,6.7322,408.3733,,,,,,,
,202.16,6.7369,407.4781,,,,,,,
,202.3,6.7415,406.4448,,,,,,,
,202.44,6.7461,405.8021,,,,,,,
,202.58,6.7509,406.0197,,,,,,,
,202.72,6.7556,405.6821,,,,,,,
,202.86,6.7601,405.3503,,,,,,,
,203,6.765,406.0605,,,,,,,
,203.14,6.7695,406.2195,,,,,,,
,203.28,6.7742,405.9552,,,,,,,
,203.42,6.7789,398.7121,,,,,,,
,203.56,6.7835,395.1972,,,,,,,
,203.7,6.7882,392.5921,,,,,,,
,203.84,6.7929,367.9699,,,,,,,
,203.98,6.7975,366.1698,,,,,,,
,203.996,6.798,366.1369,,,,,,,