File: Chassis/Inserts testing/shear testing_NO_CL/insert_test_150kN_samp2_20250915_165541_1.csv
Results Table 2
,Specimen label,Rate 1,Fixture separation,Geometry,Length,Thickness,Width,Diameter
,,(mm/min),(mm),,(mm),(mm),(mm),(mm)
"1","","2.00","101.60","Rectangular","101.60","12.70","75.69",""

1,Time,Displacement,Force
,(s),(mm),(N)
"","0.0000","0.0000","-0.0028"
"","0.0800","0.0007","0.3128"
"","0.1600","0.0032","1.2987"
"","0.2400","0.0065","1.5643"
"","0.3200","0.0091","1.6641"
"","0.4000","0.0117","2.0129"
"","0.4800","0.0144","2.0466"
"","0.5600","0.0171","1.8713"
"","0.6400","0.0197","2.1565"
"","0.7200","0.0224","2.1896"
"","0.8000","0.0251","2.5449"
"","0.8800","0.0278","2.7392"
"","0.9600","0.0304","2.7905"
"","1.0400","0.0331","2.9701"
"","1.1200","0.0357","2.8733"
"","1.2000","0.0384","3.6644"
"","1.2800","0.0412","4.0779"
"","1.3600","0.0438","5.0761"
"","1.4400","0.0465","5.5156"
"","1.5200","0.0491","5.3873"
"","1.6000","0.0517","5.4651"
"","1.6800","0.0545","5.3930"
"","1.7600","0.0571","5.5786"
"","1.8400","0.0597","5.4746"
"","1.9200","0.0624","5.6137"
"","2.0000","0.0650","5.4498"
"","2.0800","0.0678","5.6101"
"","2.1600","0.0705","5.7464"
"","2.2400","0.0731","5.7660"
"","2.3200","0.0758","6.0755"
"","2.4000","0.0784","6.3268"
"","2.4800","0.0811","6.2430"
"","2.5600","0.0838","6.1972"
"","2.6400","0.0864","6.4764"
"","2.7200","0.0890","6.2722"
"","2.8000","0.0917","6.4123"
"","2.8800","0.0944","6.3054"
"","2.9600","0.0971","6.5702"
"","3.0400","0.0997","6.5097"
"","3.1200","0.1024","6.3841"
"","3.2000","0.1050","6.2293"
"","3.2800","0.1078","6.4128"
"","3.3600","0.1104","6.3722"
"","3.4400","0.1131","6.7969"
"","3.5200","0.1157","6.4548"
"","3.6000","0.1184","6.3288"
"","3.6800","0.1211","6.5797"
"","3.7600","0.1238","6.3469"
"","3.8400","0.1264","6.6038"
"","3.9200","0.1291","6.9637"
"","4.0000","0.1317","6.5229"
"","4.0800","0.1344","6.4501"
"","4.1600","0.1371","6.4481"
"","4.2400","0.1397","6.5185"
"","4.3200","0.1424","6.6881"
"","4.4000","0.1450","6.5369"
"","4.4800","0.1478","6.8980"
"","4.5600","0.1504","6.3868"
"","4.6400","0.1531","6.7937"
"","4.7200","0.1557","6.8606"
"","4.8000","0.1584","6.9474"
"","4.8800","0.1612","6.8968"
"","4.9600","0.1638","6.8535"
"","5.0400","0.1664","7.0091"
"","5.1200","0.1691","6.8484"
"","5.2000","0.1717","7.0980"
"","5.2800","0.1744","6.7891"
"","5.3600","0.1771","6.8080"
"","5.4400","0.1797","6.6254"
"","5.5200","0.1824","6.9684"
"","5.6000","0.1850","7.0181"
"","5.6800","0.1877","7.0924"
"","5.7600","0.1904","6.9965"
"","5.8400","0.1931","7.1719"
"","5.9200","0.1957","7.1705"
"","6.0000","0.1984","6.8460"
"","6.0800","0.2012","6.8711"
"","6.1600","0.2038","7.0788"
"","6.2400","0.2065","7.0005"
"","6.3200","0.2091","7.0350"
"","6.4000","0.2117","7.8144"
"","6.4800","0.2145","7.6922"
"","6.5600","0.2171","8.3823"
"","6.6400","0.2197","9.7183"
"","6.7200","0.2224","12.4829"
"","6.8000","0.2250","16.5073"
"","6.8800","0.2278","20.5087"
"","6.9600","0.2304","24.7351"
"","7.0400","0.2331","28.9388"
"","7.1200","0.2357","33.3672"
"","7.2000","0.2384","37.6323"
"","7.2800","0.2411","42.9141"
"","7.3600","0.2438","47.4951"
"","7.4400","0.2464","52.6534"
"","7.5200","0.2490","57.9303"
"","7.6000","0.2517","63.4870"
"","7.6800","0.2544","69.2507"
"","7.7600","0.2571","74.8376"
"","7.8400","0.2597","80.6113"
"","7.9200","0.2623","86.4534"
"","8.0000","0.2651","92.7616"
"","8.0800","0.2678","99.1213"
"","8.1600","0.2704","104.6901"
"","8.2400","0.2731","111.9359"
"","8.3200","0.2757","118.4045"
"","8.4000","0.2784","125.6901"
"","8.4800","0.2812","133.7842"
"","8.5600","0.2838","140.5634"
"","8.6400","0.2864","148.1464"
"","8.7200","0.2891","155.7229"
"","8.8000","0.2917","163.1323"
"","8.8800","0.2944","171.4716"
"","8.9600","0.2971","179.4335"
"","9.0400","0.2997","188.2960"
"","9.1200","0.3024","197.5166"
"","9.2000","0.3051","207.4347"
"","9.2800","0.3078","217.7154"
"","9.3600","0.3104","228.1599"
"","9.4400","0.3131","238.7802"
"","9.5200","0.3157","249.0318"
"","9.6000","0.3184","260.0156"
"","9.6800","0.3212","270.9977"
"","9.7600","0.3238","281.4108"
"","9.8400","0.3265","292.2724"
"","9.9200","0.3290","302.5686"
"","10.0000","0.3317","313.7133"
"","10.0800","0.3345","324.9146"
"","10.1600","0.3371","335.3467"
"","10.2400","0.3397","346.7370"
"","10.3200","0.3424","357.2224"
"","10.4000","0.3450","368.0773"
"","10.4800","0.3478","380.3409"
"","10.5600","0.3504","392.8351"
"","10.6400","0.3530","405.2004"
"","10.7200","0.3557","417.7139"
"","10.8000","0.3584","430.0948"
"","10.8800","0.3612","442.6527"
"","10.9600","0.3638","454.0327"
"","11.0400","0.3664","465.7461"
"","11.1200","0.3690","477.1711"
"","11.2000","0.3718","489.9083"
"","11.2800","0.3744","502.3601"
"","11.3600","0.3771","515.2665"
"","11.4400","0.3798","529.0634"
"","11.5200","0.3823","541.8422"
"","11.6000","0.3851","555.9722"
"","11.6800","0.3878","569.5807"
"","11.7600","0.3904","582.5397"
"","11.8400","0.3931","596.3348"
"","11.9200","0.3957","609.4372"
"","12.0000","0.3984","622.9982"
"","12.0800","0.4012","637.0730"
"","12.1600","0.4038","649.8309"
"","12.2400","0.4064","663.1919"
"","12.3200","0.4091","675.2948"
"","12.4000","0.4117","687.8703"
"","12.4800","0.4145","700.7158"
"","12.5600","0.4171","713.1179"
"","12.6400","0.4197","725.1106"
"","12.7200","0.4224","737.1165"
"","12.8000","0.4250","748.9912"
"","12.8800","0.4278","761.2587"
"","12.9600","0.4304","772.6581"
"","13.0400","0.4331","784.7300"
"","13.1200","0.4357","795.3079"
"","13.2000","0.4384","807.2796"
"","13.2800","0.4412","818.8573"
"","13.3600","0.4438","830.0967"
"","13.4400","0.4465","841.8792"
"","13.5200","0.4490","853.3114"
"","13.6000","0.4517","865.6536"
"","13.6800","0.4545","878.1599"
"","13.7600","0.4570","889.6458"
"","13.8400","0.4597","902.4116"
"","13.9200","0.4624","914.8172"
"","14.0000","0.4650","926.9859"
"","14.0800","0.4678","940.7654"
"","14.1600","0.4704","952.9983"
"","14.2400","0.4731","965.1586"
"","14.3200","0.4757","978.0084"
"","14.4000","0.4784","991.0259"
"","14.4800","0.4812","995.2774"
"","14.5600","0.4838","1007.8176"
"","14.6400","0.4864","1020.5237"
"","14.7200","0.4890","1032.9998"
"","14.8000","0.4917","1046.4038"
"","14.8800","0.4944","1058.9458"
"","14.9600","0.4971","1071.2283"
"","15.0400","0.4998","1084.0453"
"","15.1200","0.5023","1095.7466"
"","15.2000","0.5051","1108.9951"
"","15.2800","0.5078","1121.1564"
"","15.3600","0.5104","1132.4138"
"","15.4400","0.5131","1144.7593"
"","15.5200","0.5157","1156.3372"
"","15.6000","0.5184","1168.6018"
"","15.6800","0.5212","1180.6044"
"","15.7600","0.5238","1192.2316"
"","15.8400","0.5264","1203.3474"
"","15.9200","0.5291","1214.3507"
"","16.0000","0.5317","1226.1486"
"","16.0800","0.5345","1238.6378"
"","16.1600","0.5371","1250.5042"
"","16.2400","0.5397","1263.2137"
"","16.3200","0.5424","1276.3778"
"","16.4000","0.5451","1289.7860"
"","16.4800","0.5478","1303.2679"
"","16.5600","0.5504","1316.4336"
"","16.6400","0.5531","1329.7648"
"","16.7200","0.5557","1342.5839"
"","16.8000","0.5585","1356.1891"
"","16.8800","0.5612","1368.8325"
"","16.9600","0.5638","1381.1462"
"","17.0400","0.5664","1394.9215"
"","17.1200","0.5690","1407.9960"
"","17.2000","0.5717","1422.7598"
"","17.2800","0.5745","1436.9071"
"","17.3600","0.5770","1450.2506"
"","17.4400","0.5798","1464.5430"
"","17.5200","0.5824","1477.8015"
"","17.6000","0.5850","1491.6332"
"","17.6800","0.5878","1506.7219"
"","17.7600","0.5904","1520.3289"
"","17.8400","0.5931","1534.1796"
"","17.9200","0.5957","1548.5442"
"","18.0000","0.5984","1563.1061"
"","18.0800","0.6012","1578.0719"
"","18.1600","0.6038","1590.9036"
"","18.2400","0.6064","1604.9772"
"","18.3200","0.6090","1618.7535"
"","18.4000","0.6118","1633.4385"
"","18.4800","0.6144","1647.8359"
"","18.5600","0.6171","1662.1826"
"","18.6400","0.6197","1676.6843"
"","18.7200","0.6223","1690.4640"
"","18.8000","0.6251","1705.3341"
"","18.8800","0.6278","1720.3857"
"","18.9600","0.6304","1733.1134"
"","19.0400","0.6331","1747.8098"
"","19.1200","0.6357","1760.1851"
"","19.2000","0.6384","1775.0603"
"","19.2800","0.6412","1789.0989"
"","19.3600","0.6437","1802.9684"
"","19.4400","0.6464","1817.8468"
"","19.5200","0.6491","1832.7211"
"","19.6000","0.6517","1847.8503"
"","19.6800","0.6545","1863.0675"
"","19.7600","0.6571","1877.6456"
"","19.8400","0.6597","1892.7607"
"","19.9200","0.6624","1907.7811"
"","20.0000","0.6651","1923.8262"
"","20.0800","0.6678","1938.9503"
"","20.1600","0.6704","1954.0323"
"","20.2400","0.6731","1969.1660"
"","20.3200","0.6757","1984.0430"
"","20.4000","0.6785","1999.8215"
"","20.4800","0.6811","2015.2003"
"","20.5600","0.6838","2030.3940"
"","20.6400","0.6864","2045.4274"
"","20.7200","0.6890","2060.5012"
"","20.8000","0.6918","2076.2424"
"","20.8800","0.6945","2092.2104"
"","20.9600","0.6970","2106.5608"
"","21.0400","0.6998","2122.5034"
"","21.1200","0.7024","2137.4617"
"","21.2000","0.7051","2153.2947"
"","21.2800","0.7078","2169.4490"
"","21.3600","0.7104","2184.4861"
"","21.4400","0.7131","2200.1394"
"","21.5200","0.7157","2215.3362"
"","21.6000","0.7184","2231.0952"
"","21.6800","0.7212","2247.1689"
"","21.7600","0.7238","2261.9336"
"","21.8400","0.7264","2276.8943"
"","21.9200","0.7290","2292.4041"
"","22.0000","0.7318","2308.5938"
"","22.0800","0.7344","2323.8840"
"","22.1600","0.7371","2339.6057"
"","22.2400","0.7397","2355.5217"
"","22.3200","0.7423","2370.7266"
"","22.4000","0.7451","2387.2246"
"","22.4800","0.7478","2402.3467"
"","22.5600","0.7504","2418.0859"
"","22.6400","0.7531","2433.2634"
"","22.7200","0.7557","2449.1162"
"","22.8000","0.7585","2465.3223"
"","22.8800","0.7612","2480.9673"
"","22.9600","0.7637","2495.5208"
"","23.0400","0.7664","2511.4780"
"","23.1200","0.7691","2526.6104"
"","23.2000","0.7717","2542.4749"
"","23.2800","0.7745","2558.5034"
"","23.3600","0.7771","2572.9092"
"","23.4400","0.7797","2587.8870"
"","23.5200","0.7824","2603.7095"
"","23.6000","0.7851","2619.3579"
"","23.6800","0.7878","2634.9585"
"","23.7600","0.7904","2650.6804"
"","23.8400","0.7931","2665.2178"
"","23.9200","0.7958","2680.1521"
"","24.0000","0.7985","2692.3069"
"","24.0800","0.8011","2702.9033"
"","24.1600","0.8038","2717.4033"
"","24.2400","0.8064","2731.6841"
"","24.3200","0.8090","2746.5571"
"","24.4000","0.8118","2762.3857"
"","24.4800","0.8144","2777.6953"
"","24.5600","0.8170","2792.0156"
"","24.6400","0.8197","2807.1589"
"","24.7200","0.8223","2821.9368"
"","24.8000","0.8251","2837.9800"
"","24.8800","0.8278","2853.0945"
"","24.9600","0.8304","2867.5342"
"","25.0400","0.8331","2882.8660"
"","25.1200","0.8358","2898.5784"
"","25.2000","0.8384","2913.6240"
"","25.2800","0.8412","2928.8154"
"","25.3600","0.8438","2943.1365"
"","25.4400","0.8463","2956.7932"
"","25.5200","0.8491","2972.8516"
"","25.6000","0.8518","2987.6936"
"","25.6800","0.8544","3002.1895"
"","25.7600","0.8571","3016.8018"
"","25.8400","0.8597","3030.9180"
"","25.9200","0.8623","3045.6265"
"","26.0000","0.8651","3060.9988"
"","26.0800","0.8678","3073.2439"
"","26.1600","0.8704","3086.0598"
"","26.2400","0.8731","3099.4407"
"","26.3200","0.8757","3112.6606"
"","26.4000","0.8785","3128.2144"
"","26.4800","0.8812","3142.5056"
"","26.5600","0.8837","3155.7046"
"","26.6400","0.8864","3169.2571"
"","26.7200","0.8891","3183.1880"
"","26.8000","0.8917","3197.5156"
"","26.8800","0.8945","3212.5632"
"","26.9600","0.8970","3226.0840"
"","27.0400","0.8997","3240.5933"
"","27.1200","0.9024","3253.0427"
"","27.2000","0.9051","3265.9675"
"","27.2800","0.9078","3280.1860"
"","27.3600","0.9104","3293.7065"
"","27.4400","0.9130","3306.7424"
"","27.5200","0.9158","3320.1011"
"","27.6000","0.9185","3333.8911"
"","27.6800","0.9211","3347.2322"
"","27.7600","0.9238","3360.7595"
"","27.8400","0.9264","3373.3096"
"","27.9200","0.9290","3387.3337"
"","28.0000","0.9318","3402.2063"
"","28.0800","0.9344","3415.7488"
"","28.1600","0.9371","3429.7544"
"","28.2400","0.9397","3443.3601"
"","28.3200","0.9423","3456.8528"
"","28.4000","0.9451","3471.4553"
"","28.4800","0.9478","3485.1714"
"","28.5600","0.9504","3498.3318"
"","28.6400","0.9531","3512.2061"
"","28.7200","0.9558","3525.5171"
"","28.8000","0.9584","3538.6826"
"","28.8800","0.9612","3552.7739"
"","28.9600","0.9638","3565.0437"
"","29.0400","0.9664","3577.7710"
"","29.1200","0.9691","3591.0847"
"","29.2000","0.9718","3603.7820"
"","29.2800","0.9744","3616.7034"
"","29.3600","0.9771","3630.0620"
"","29.4400","0.9797","3642.3794"
"","29.5200","0.9824","3656.1575"
"","29.6000","0.9851","3668.7998"
"","29.6800","0.9878","3680.6506"
"","29.7600","0.9904","3694.2354"
"","29.8400","0.9931","3706.6865"
"","29.9200","0.9957","3720.0852"
"","30.0000","0.9985","3734.3826"
"","30.0800","1.0011","3746.1284"
"","30.1600","1.0038","3759.1060"
"","30.2400","1.0064","3772.0901"
"","30.3200","1.0091","3784.5532"
"","30.4000","1.0118","3797.8403"
"","30.4800","1.0144","3810.2908"
"","30.5600","1.0170","3822.1143"
"","30.6400","1.0197","3830.1357"
"","30.7200","1.0224","3841.9316"
"","30.8000","1.0251","3854.4316"
"","30.8800","1.0278","3867.1836"
"","30.9600","1.0305","3879.1987"
"","31.0400","1.0330","3889.9753"
"","31.1200","1.0358","3896.6768"
"","31.2000","1.0385","3908.4910"
"","31.2800","1.0411","3919.7148"
"","31.3600","1.0438","3932.0137"
"","31.4400","1.0464","3942.8003"
"","31.5200","1.0490","3953.6116"
"","31.6000","1.0518","3966.2595"
"","31.6800","1.0544","3977.3079"
"","31.7600","1.0571","3988.4680"
"","31.8400","1.0597","3998.3193"
"","31.9200","1.0624","4008.7002"
"","32.0000","1.0651","4020.8882"
"","32.0800","1.0678","4031.8669"
"","32.1600","1.0704","4042.9019"
"","32.2400","1.0731","4054.3267"
"","32.3200","1.0758","4065.8252"
"","32.4000","1.0785","4077.3999"
"","32.4800","1.0812","4087.8838"
"","32.5600","1.0838","4098.6597"
"","32.6400","1.0864","4108.6079"
"","32.7200","1.0891","4112.8232"
"","32.8000","1.0918","4123.3696"
"","32.8800","1.0944","4133.4722"
"","32.9600","1.0971","4143.8740"
"","33.0400","1.0997","4153.5674"
"","33.1200","1.1024","4164.6646"
"","33.2000","1.1051","4175.9727"
"","33.2800","1.1077","4185.6562"
"","33.3600","1.1104","4197.8115"
"","33.4400","1.1130","4206.9688"
"","33.5200","1.1157","4218.2329"
"","33.6000","1.1185","4229.1064"
"","33.6800","1.1211","4237.4858"
"","33.7600","1.1238","4245.9404"
"","33.8400","1.1264","4255.6714"
"","33.9200","1.1291","4264.4585"
"","34.0000","1.1318","4275.4849"
"","34.0800","1.1344","4286.2305"
"","34.1600","1.1370","4296.7793"
"","34.2400","1.1397","4306.5786"
"","34.3200","1.1424","4317.7266"
"","34.4000","1.1451","4327.8145"
"","34.4800","1.1478","4336.1201"
"","34.5600","1.1505","4343.3848"
"","34.6400","1.1530","4349.2051"
"","34.7200","1.1558","4356.1143"
"","34.8000","1.1585","4350.2866"
"","34.8800","1.1611","4350.7612"
"","34.9600","1.1638","4356.1426"
"","35.0400","1.1664","4362.2515"
"","35.1200","1.1691","4370.4399"
"","35.2000","1.1718","4379.1519"
"","35.2800","1.1744","4387.1279"
"","35.3600","1.1771","4395.1992"
"","35.4400","1.1797","4404.3628"
"","35.5200","1.1824","4412.0713"
"","35.6000","1.1851","4421.0078"
"","35.6800","1.1878","4429.8403"
"","35.7600","1.1904","4439.2114"
"","35.8400","1.1930","4447.7451"
"","35.9200","1.1958","4457.7754"
"","36.0000","1.1985","4467.3843"
"","36.0800","1.2011","4476.4209"
"","36.1600","1.2038","4485.5850"
"","36.2400","1.2064","4494.4780"
"","36.3200","1.2091","4504.3491"
"","36.4000","1.2118","4513.7935"
"","36.4800","1.2144","4522.8262"
"","36.5600","1.2171","4532.3892"
"","36.6400","1.2197","4540.8379"
"","36.7200","1.2224","4550.7612"
"","36.8000","1.2251","4560.3804"
"","36.8800","1.2277","4568.9609"
"","36.9600","1.2304","4578.1133"
"","37.0400","1.2330","4586.5640"
"","37.1200","1.2358","4596.1768"
"","37.2000","1.2385","4605.5566"
"","37.2800","1.2411","4606.5928"
"","37.3600","1.2438","4613.3223"
"","37.4400","1.2464","4622.2437"
"","37.5200","1.2491","4630.9976"
"","37.6000","1.2518","4640.3306"
"","37.6800","1.2544","4648.1499"
"","37.7600","1.2571","4656.5356"
"","37.8400","1.2597","4664.3867"
"","37.9200","1.2624","4673.3604"
"","38.0000","1.2651","4681.2988"
"","38.0800","1.2678","4689.1284"
"","38.1600","1.2704","4697.1685"
"","38.2400","1.2730","4703.9854"
"","38.3200","1.2758","4710.9492"
"","38.4000","1.2785","4716.8579"
"","38.4800","1.2811","4722.6475"
"","38.5600","1.2838","4729.0347"
"","38.6400","1.2863","4734.6201"
"","38.7200","1.2891","4737.3691"
"","38.8000","1.2918","4743.8301"
"","38.8800","1.2944","4749.2070"
"","38.9600","1.2971","4756.8018"
"","39.0400","1.2997","4763.1338"
"","39.1200","1.3024","4764.4082"
"","39.2000","1.3051","4772.3584"
"","39.2800","1.3078","4778.4102"
"","39.3600","1.3104","4785.2017"
"","39.4400","1.3131","4789.2793"
"","39.5200","1.3158","4793.8057"
"","39.6000","1.3185","4800.6484"
"","39.6800","1.3211","4806.8550"
"","39.7600","1.3237","4813.0312"
"","39.8400","1.3264","4820.0615"
"","39.9200","1.3291","4827.2661"
"","40.0000","1.3317","4834.3398"
"","40.0800","1.3344","4841.2769"
"","40.1600","1.3371","4848.8159"
"","40.2400","1.3397","4855.5259"
"","40.3200","1.3424","4863.1641"
"","40.4000","1.3451","4871.0024"
"","40.4800","1.3477","4877.6978"
"","40.5600","1.3504","4885.1816"
"","40.6400","1.3530","4891.9512"
"","40.7200","1.3558","4899.9146"
"","40.8000","1.3585","4907.4072"
"","40.8800","1.3611","4914.1089"
"","40.9600","1.3638","4921.5015"
"","41.0400","1.3664","4928.7095"
"","41.1200","1.3690","4935.8208"
"","41.2000","1.3718","4943.8857"
"","41.2800","1.3744","4950.2393"
"","41.3600","1.3770","4957.8906"
"","41.4400","1.3797","4964.9048"
"","41.5200","1.3824","4972.4712"
"","41.6000","1.3851","4980.1055"
"","41.6800","1.3878","4986.5435"
"","41.7600","1.3904","4992.3755"
"","41.8400","1.3930","4981.9854"
"","41.9200","1.3958","4991.1396"
"","42.0000","1.3985","4992.5894"
"","42.0800","1.4011","4996.8843"
"","42.1600","1.4038","5002.5273"
"","42.2400","1.4063","5007.6318"
"","42.3200","1.4091","5013.6147"
"","42.4000","1.4118","5019.4106"
"","42.4800","1.4144","5024.4648"
"","42.5600","1.4171","5030.4370"
"","42.6400","1.4197","5036.1885"
"","42.7200","1.4224","5042.3545"
"","42.8000","1.4251","5048.9136"
"","42.8800","1.4277","5054.1250"
"","42.9600","1.4304","5060.0142"
"","43.0400","1.4331","5065.7056"
"","43.1200","1.4358","5071.4595"
"","43.2000","1.4385","5075.8218"
"","43.2800","1.4411","5078.9883"
"","43.3600","1.4437","5083.8125"
"","43.4400","1.4464","5089.8267"
"","43.5200","1.4491","5096.3633"
"","43.6000","1.4517","5101.9473"
"","43.6800","1.4544","5107.8481"
"","43.7600","1.4571","5113.3911"
"","43.8400","1.4597","5119.2168"
"","43.9200","1.4624","5126.0957"
"","44.0000","1.4651","5131.6768"
"","44.0800","1.4677","5137.5166"
"","44.1600","1.4704","5143.5718"
"","44.2400","1.4730","5148.9458"
"","44.3200","1.4758","5152.7998"
"","44.4000","1.4785","5157.1514"
"","44.4800","1.4811","5162.6616"
"","44.5600","1.4837","5168.2295"
"","44.6400","1.4864","5173.6851"
"","44.7200","1.4891","5179.3623"
"","44.8000","1.4918","5185.5576"
"","44.8800","1.4944","5190.6675"
"","44.9600","1.4970","5196.3564"
"","45.0400","1.4997","5202.2573"
"","45.1200","1.5024","5208.4712"
"","45.2000","1.5051","5213.9165"
"","45.2800","1.5078","5218.9775"
"","45.3600","1.5103","5223.7637"
"","45.4400","1.5131","5229.5078"
"","45.5200","1.5158","5235.9570"
"","45.6000","1.5184","5240.3022"
"","45.6800","1.5211","5245.7021"
"","45.7600","1.5238","5250.7744"
"","45.8400","1.5263","5255.4526"
"","45.9200","1.5291","5261.2476"
"","46.0000","1.5318","5266.8506"
"","46.0800","1.5344","5271.0176"
"","46.1600","1.5371","5276.4736"
"","46.2400","1.5397","5281.2246"
"","46.3200","1.5424","5286.5723"
"","46.4000","1.5452","5292.6807"
"","46.4800","1.5477","5296.9897"
"","46.5600","1.5504","5302.9194"
"","46.6400","1.5531","5307.5435"
"","46.7200","1.5557","5312.8184"
"","46.8000","1.5585","5319.1689"
"","46.8800","1.5611","5323.8159"
"","46.9600","1.5637","5328.2466"
"","47.0400","1.5664","5333.4199"
"","47.1200","1.5691","5338.4341"
"","47.2000","1.5717","5343.3721"
"","47.2800","1.5744","5336.7798"
"","47.3600","1.5770","5341.5093"
"","47.4400","1.5797","5346.6484"
"","47.5200","1.5825","5351.7412"
"","47.6000","1.5851","5356.0254"
"","47.6800","1.5878","5360.4155"
"","47.7600","1.5904","5364.7622"
"","47.8400","1.5930","5368.7061"
"","47.9200","1.5958","5374.5063"
"","48.0000","1.5985","5376.4971"
"","48.0800","1.6011","5379.8159"
"","48.1600","1.6038","5383.7275"
"","48.2400","1.6064","5384.9746"
"","48.3200","1.6091","5386.6797"
"","48.4000","1.6118","5390.5264"
"","48.4800","1.6144","5393.5400"
"","48.5600","1.6170","5396.8721"
"","48.6400","1.6197","5400.4473"
"","48.7200","1.6224","5403.8174"
"","48.8000","1.6251","5407.3330"
"","48.8800","1.6278","5410.7036"
"","48.9600","1.6304","5413.1890"
"","49.0400","1.6331","5417.0845"
"","49.1200","1.6358","5421.4497"
"","49.2000","1.6384","5423.6382"
"","49.2800","1.6411","5427.5059"
"","49.3600","1.6437","5430.1147"
"","49.4400","1.6464","5433.2944"
"","49.5200","1.6491","5436.9849"
"","49.6000","1.6518","5440.0962"
"","49.6800","1.6544","5443.3672"
"","49.7600","1.6571","5446.4097"
"","49.8400","1.6597","5446.6255"
"","49.9200","1.6624","5450.0239"
"","50.0000","1.6651","5452.7656"
"","50.0800","1.6677","5455.6958"
"","50.1600","1.6704","5458.4072"
"","50.2400","1.6731","5461.1646"
"","50.3200","1.6758","5463.8691"
"","50.4000","1.6785","5466.2910"
"","50.4800","1.6811","5468.6885"
"","50.5600","1.6837","5470.5039"
"","50.6400","1.6864","5473.4873"
"","50.7200","1.6891","5477.0254"
"","50.8000","1.6917","5479.4233"
"","50.8800","1.6944","5480.1753"
"","50.9600","1.6970","5476.1050"
"","51.0400","1.6997","5477.2593"
"","51.1200","1.7025","5479.6816"
"","51.2000","1.7051","5481.5640"
"","51.2800","1.7078","5484.8169"
"","51.3600","1.7104","5487.6221"
"","51.4400","1.7130","5490.1392"
"","51.5200","1.7158","5494.3276"
"","51.6000","1.7185","5497.5444"
"","51.6800","1.7211","5499.9551"
"","51.7600","1.7237","5502.5210"
"","51.8400","1.7264","5505.5723"
"","51.9200","1.7291","5508.8716"
"","52.0000","1.7318","5512.4043"
"","52.0800","1.7344","5513.9946"
"","52.1600","1.7370","5516.1611"
"","52.2400","1.7397","5520.1758"
"","52.3200","1.7424","5523.3545"
"","52.4000","1.7451","5526.2808"
"","52.4800","1.7478","5529.7002"
"","52.5600","1.7504","5532.2070"
"","52.6400","1.7531","5535.8193"
"","52.7200","1.7558","5539.4194"
"","52.8000","1.7584","5541.6768"
"","52.8800","1.7611","5544.7524"
"","52.9600","1.7637","5547.0254"
"","53.0400","1.7664","5549.8936"
"","53.1200","1.7691","5552.9951"
"","53.2000","1.7717","5555.2383"
"","53.2800","1.7744","5557.8228"
"","53.3600","1.7770","5560.1089"
"","53.4400","1.7797","5562.8374"
"","53.5200","1.7825","5565.7319"
"","53.6000","1.7851","5568.0801"
"","53.6800","1.7877","5569.8389"
"","53.7600","1.7904","5572.4233"
"","53.8400","1.7931","5575.1265"
"","53.9200","1.7958","5577.7988"
"","54.0000","1.7985","5579.5776"
"","54.0800","1.8011","5580.9165"
"","54.1600","1.8037","5581.9282"
"","54.2400","1.8064","5584.9429"
"","54.3200","1.8091","5587.1812"
"","54.4000","1.8117","5588.8682"
"","54.4800","1.8144","5591.1636"
"","54.5600","1.8170","5592.3022"
"","54.6400","1.8197","5594.2793"
"","54.7200","1.8225","5597.4043"
"","54.8000","1.8251","5598.5239"
"","54.8800","1.8278","5601.1299"
"","54.9600","1.8304","5602.9214"
"","55.0400","1.8330","5604.4893"
"","55.1200","1.8358","5607.8096"
"","55.2000","1.8385","5609.7588"
"","55.2800","1.8411","5611.4346"
"","55.3600","1.8437","5613.4131"
"","55.4400","1.8464","5615.9551"
"","55.5200","1.8491","5618.5854"
"","55.6000","1.8517","5620.7817"
"","55.6800","1.8544","5622.6846"
"","55.7600","1.8570","5623.6665"
"","55.8400","1.8597","5576.0444"
"","55.9200","1.8624","5556.2666"
"","56.0000","1.8651","5550.8516"
"","56.0800","1.8678","5532.6787"
"","56.1600","1.8704","5524.6455"
"","56.2400","1.8731","5520.9282"
"","56.3200","1.8758","5518.3618"
"","56.4000","1.8784","5515.8623"
"","56.4800","1.8811","5514.4233"
"","56.5600","1.8837","5512.7134"
"","56.6400","1.8864","5513.0029"
"","56.7200","1.8891","5507.0562"
"","56.8000","1.8917","5504.0610"
"","56.8800","1.8944","5503.1875"
"","56.9600","1.8970","5501.4810"
"","57.0400","1.8997","5497.3408"
"","57.1200","1.9025","5496.0908"
"","57.2000","1.9051","5495.7231"
"","57.2800","1.9077","5495.7798"
"","57.3600","1.9104","5496.7778"
"","57.4400","1.9131","5498.6069"
"","57.5200","1.9158","5500.4282"
"","57.6000","1.9185","5501.6274"
"","57.6800","1.9211","5502.7144"
"","57.7600","1.9237","5503.9639"
"","57.8400","1.9264","5505.9883"
"","57.9200","1.9291","5508.2100"
"","58.0000","1.9317","5509.1504"
"","58.0800","1.9344","5510.8726"
"","58.1600","1.9370","5509.0068"
"","58.2400","1.9397","5499.8315"
"","58.3200","1.9425","5497.6611"
"","58.4000","1.9450","5495.6470"
"","58.4800","1.9478","5495.6274"
"","58.5600","1.9504","5495.4424"
"","58.6400","1.9531","5495.4189"
"","58.7200","1.9559","5497.1016"
"","58.8000","1.9584","5496.4023"
"","58.8800","1.9611","5496.2490"
"","58.9600","1.9637","5495.8252"
"","59.0400","1.9664","5494.9414"
"","59.1200","1.9691","5491.1504"
"","59.2000","1.9717","5489.4170"
"","59.2800","1.9744","5487.7197"
"","59.3600","1.9770","5486.5952"
"","59.4400","1.9798","5486.5024"
"","59.5200","1.9824","5486.2261"
"","59.6000","1.9851","5485.3447"
"","59.6800","1.9878","5484.2295"
"","59.7600","1.9904","5482.8076"
"","59.8400","1.9931","5482.3638"
"","59.9200","1.9958","5481.3027"
"","60.0000","1.9984","5479.5620"
"","60.0800","2.0011","5477.3716"
"","60.1600","2.0037","5470.6016"
"","60.2400","2.0064","5456.2363"
"","60.3200","2.0091","5446.2295"
"","60.4000","2.0117","5435.9712"
"","60.4800","2.0144","5428.2173"
"","60.5600","2.0170","5418.6030"
"","60.6400","2.0197","5407.6968"
"","60.7200","2.0225","5398.3618"
"","60.8000","2.0251","5385.1465"
"","60.8800","2.0277","5368.7471"
"","60.9600","2.0304","5351.4473"
"","61.0400","2.0331","5336.4346"
"","61.1200","2.0358","5325.0259"
"","61.2000","2.0385","5314.4980"
"","61.2800","2.0411","5295.2129"
"","61.3600","2.0437","5283.1870"
"","61.4400","2.0464","5274.0903"
"","61.5200","2.0491","5265.3062"
"","61.6000","2.0517","5257.4370"
"","61.6800","2.0544","5250.2925"
"","61.7600","2.0570","5241.6533"
"","61.8400","2.0598","5236.2295"
"","61.9200","2.0624","5229.4214"
"","62.0000","2.0651","5223.2651"
"","62.0800","2.0678","5218.7778"
"","62.1600","2.0704","5211.6426"
"","62.2400","2.0731","5208.0381"
"","62.3200","2.0759","5200.6777"
"","62.4000","2.0784","5194.3379"
"","62.4800","2.0811","5190.9697"
"","62.5600","2.0837","5185.6719"
"","62.6400","2.0864","5178.5068"
"","62.7200","2.0892","5172.8115"
"","62.8000","2.0917","5166.7949"
"","62.8800","2.0944","5162.3721"
"","62.9600","2.0970","5157.9990"
"","63.0400","2.0997","5153.2168"
"","63.1200","2.1024","5142.5195"
"","63.2000","2.1051","5132.9492"
"","63.2800","2.1077","5123.7197"
"","63.3600","2.1104","5116.4507"
"","63.4400","2.1131","5111.8242"
"","63.5200","2.1158","5107.0669"
"","63.6000","2.1185","5102.4653"
"","63.6800","2.1211","5098.1787"
"","63.7600","2.1237","5093.1074"
"","63.8400","2.1264","5088.1919"
"","63.9200","2.1291","5080.1523"
"","64.0000","2.1317","5071.4033"
"","64.0800","2.1344","5055.4185"
"","64.1600","2.1370","5033.4414"
"","64.2400","2.1397","5019.8047"
"","64.3200","2.1425","5007.1724"
"","64.4000","2.1451","4992.7114"
"","64.4800","2.1477","4979.5864"
"","64.5600","2.1504","4967.3242"
"","64.6400","2.1531","4954.2529"
"","64.7200","2.1558","4936.6904"
"","64.8000","2.1585","4911.6187"
"","64.8800","2.1610","4892.2261"
"","64.9600","2.1637","4810.7275"
"","65.0400","2.1664","4770.7861"
"","65.1200","2.1691","4742.7568"
"","65.2000","2.1717","4721.4385"
"","65.2800","2.1744","4703.6357"
"","65.3600","2.1770","4688.8193"
"","65.4400","2.1798","4677.7319"
"","65.5200","2.1825","4667.5649"
"","65.6000","2.1851","4653.4351"
"","65.6800","2.1878","4620.9600"
"","65.7600","2.1903","4607.5542"
"","65.8400","2.1931","4599.3628"
"","65.9200","2.1959","4590.2192"
"","66.0000","2.1984","4580.8569"
"","66.0800","2.2011","4574.9785"
"","66.1600","2.2037","4569.2734"
"","66.2400","2.2064","4565.3052"
"","66.3200","2.2091","4562.2119"
"","66.4000","2.2117","4559.0684"
"","66.4800","2.2144","4554.4702"
"","66.5600","2.2170","4552.0933"
"","66.6400","2.2198","4551.1162"
"","66.7200","2.2225","4550.2280"
"","66.8000","2.2251","4549.7314"
"","66.8800","2.2277","4548.4336"
"","66.9600","2.2304","4547.9277"
"","67.0400","2.2331","4548.5063"
"","67.1200","2.2358","4547.9048"
"","67.2000","2.2384","4540.7065"
"","67.2800","2.2411","4538.5615"
"","67.3600","2.2437","4537.3887"
"","67.4400","2.2464","4538.3472"
"","67.5200","2.2491","4538.5366"
"","67.6000","2.2517","4538.2920"
"","67.6800","2.2544","4539.5669"
"","67.7600","2.2570","4540.4268"
"","67.8400","2.2597","4541.9556"
"","67.9200","2.2625","4543.4570"
"","68.0000","2.2651","4544.2373"
"","68.0800","2.2677","4545.9399"
"","68.1600","2.2704","4547.4009"
"","68.2400","2.2731","4549.1021"
"","68.3200","2.2759","4550.6846"
"","68.4000","2.2785","4550.6001"
"","68.4800","2.2810","4551.1650"
"","68.5600","2.2837","4552.8735"
"","68.6400","2.2864","4554.7026"
"","68.7200","2.2891","4555.8677"
"","68.8000","2.2917","4557.1494"
"","68.8800","2.2944","4558.4067"
"","68.9600","2.2970","4559.1865"
"","69.0400","2.2998","4560.6665"
"","69.1200","2.3024","4561.2402"
"","69.2000","2.3051","4561.8613"
"","69.2800","2.3078","4562.7671"
"","69.3600","2.3104","4562.6748"
"","69.4400","2.3131","4558.3516"
"","69.5200","2.3158","4558.8516"
"","69.6000","2.3184","4554.5654"
"","69.6800","2.3211","4541.9800"
"","69.7600","2.3237","4538.2710"
"","69.8400","2.3264","4522.3687"
"","69.9200","2.3291","4498.4507"
"","70.0000","2.3317","4486.2075"
"","70.0800","2.3343","4467.4644"
"","70.1600","2.3370","4356.8120"
"","70.2400","2.3398","4333.2354"
"","70.3200","2.3424","4313.8184"
"","70.4000","2.3451","4301.0176"
"","70.4800","2.3477","4257.5483"
"","70.5600","2.3504","4235.8198"
"","70.6400","2.3532","4219.8032"
"","70.7200","2.3558","4209.9443"
"","70.8000","2.3585","4202.5303"
"","70.8800","2.3611","4193.2061"
"","70.9600","2.3637","4187.5503"
"","71.0400","2.3664","4184.5566"
"","71.1200","2.3691","4178.9575"
"","71.2000","2.3717","4149.7871"
"","71.2800","2.3744","4143.0698"
"","71.3600","2.3770","4139.3188"
"","71.4400","2.3798","4138.4976"
"","71.5200","2.3825","4136.6895"
"","71.6000","2.3851","4135.0352"
"","71.6800","2.3877","4135.2827"
"","71.7600","2.3904","4136.2544"
"","71.8400","2.3931","4136.9023"
"","71.9200","2.3958","4138.2739"
"","72.0000","2.3984","4139.8472"
"","72.0800","2.4010","4141.2329"
"","72.1600","2.4037","4141.8232"
"","72.2400","2.4064","4141.5430"
"","72.3200","2.4091","4142.1528"
"","72.4000","2.4117","4144.2339"
"","72.4800","2.4144","4146.0181"
"","72.5600","2.4170","4141.3574"
"","72.6400","2.4198","4140.8726"
"","72.7200","2.4224","4140.7949"
"","72.8000","2.4251","4141.2383"
"","72.8800","2.4277","4142.6714"
"","72.9600","2.4304","4144.7725"
"","73.0400","2.4332","4147.6841"
"","73.1200","2.4358","4149.8770"
"","73.2000","2.4384","4151.1060"
"","73.2800","2.4411","4153.3550"
"","73.3600","2.4437","4155.9536"
"","73.4400","2.4464","4159.1284"
"","73.5200","2.4491","4161.5259"
"","73.6000","2.4517","4163.3384"
"","73.6800","2.4544","4166.0161"
"","73.7600","2.4570","4168.6641"
"","73.8400","2.4598","4171.8857"
"","73.9200","2.4624","4156.7163"
"","74.0000","2.4651","4154.1353"
"","74.0800","2.4677","4153.2915"
"","74.1600","2.4704","4150.8403"
"","74.2400","2.4732","4151.3354"
"","74.3200","2.4758","4149.2056"
"","74.4000","2.4784","4148.1885"
"","74.4800","2.4811","4146.6274"
"","74.5600","2.4837","4123.6396"
"","74.6400","2.4865","4103.5967"
"","74.7200","2.4891","4097.7041"
"","74.8000","2.4917","4093.6204"
"","74.8800","2.4944","4090.7061"
"","74.9600","2.4970","4087.8513"
"","75.0400","2.4998","4085.0044"
"","75.1200","2.5025","4083.9832"
"","75.2000","2.5050","4083.8320"
"","75.2800","2.5077","4084.7031"
"","75.3600","2.5104","4085.3723"
"","75.4400","2.5131","4086.0845"
"","75.5200","2.5159","4087.8337"
"","75.6000","2.5185","4088.5066"
"","75.6800","2.5210","4089.3420"
"","75.7600","2.5238","4090.5637"
"","75.8400","2.5264","4092.6353"
"","75.9200","2.5291","4094.4060"
"","76.0000","2.5318","4096.5771"
"","76.0800","2.5343","4098.0801"
"","76.1600","2.5370","4100.3315"
"","76.2400","2.5398","4101.7759"
"","76.3200","2.5424","4103.0298"
"","76.4000","2.5451","4105.6729"
"","76.4800","2.5477","4105.1934"
"","76.5600","2.5504","4106.1484"
"","76.6400","2.5532","4108.5137"
"","76.7200","2.5558","4109.3438"
"","76.8000","2.5584","4110.1670"
"","76.8800","2.5610","4110.6694"
"","76.9600","2.5637","4112.8560"
"","77.0400","2.5665","4114.7271"
"","77.1200","2.5691","4116.3545"
"","77.2000","2.5717","4117.8174"
"","77.2800","2.5744","4086.5532"
"","77.3600","2.5770","4083.7761"
"","77.4400","2.5798","4083.0798"
"","77.5200","2.5824","4083.5120"
"","77.6000","2.5851","4082.1963"
"","77.6800","2.5877","4081.5996"
"","77.7600","2.5904","4082.9412"
"","77.8400","2.5932","4084.8672"
"","77.9200","2.5958","4080.7932"
"","78.0000","2.5985","4081.3577"
"","78.0800","2.6010","4081.4138"
"","78.1600","2.6037","4082.4722"
"","78.2400","2.6065","4084.3738"
"","78.3200","2.6091","4085.5686"
"","78.4000","2.6118","4087.4280"
"","78.4800","2.6144","4088.4722"
"","78.5600","2.6170","4090.9160"
"","78.6400","2.6198","4090.8098"
"","78.7200","2.6224","4085.8430"
"","78.8000","2.6251","4087.3831"
"","78.8800","2.6277","4088.7092"
"","78.9600","2.6304","4090.1824"
"","79.0400","2.6331","4092.5095"
"","79.1200","2.6358","4094.0100"
"","79.2000","2.6384","4095.2903"
"","79.2800","2.6410","4097.1479"
"","79.3600","2.6438","4099.4062"
"","79.4400","2.6464","4101.6655"
"","79.5200","2.6491","4103.6885"
"","79.6000","2.6518","4086.7456"
"","79.6800","2.6543","4086.5215"
"","79.7600","2.6571","4088.1619"
"","79.8400","2.6598","4089.7815"
"","79.9200","2.6624","4088.9763"
"","80.0000","2.6651","4090.7568"
"","80.0800","2.6677","4091.5618"
"","80.1600","2.6704","4090.0820"
"","80.2400","2.6732","4090.0220"
"","80.3200","2.6758","4088.1201"
"","80.4000","2.6784","4088.0830"
"","80.4800","2.6811","4088.7664"
"","80.5600","2.6837","4089.2795"
"","80.6400","2.6865","4090.0042"
"","80.7200","2.6891","4090.7437"
"","80.8000","2.6917","4091.1411"
"","80.8800","2.6944","4092.4280"
"","80.9600","2.6971","4094.4526"
"","81.0400","2.6997","4095.7454"
"","81.1200","2.7024","4097.5986"
"","81.2000","2.7051","4098.0239"
"","81.2800","2.7077","4094.8196"
"","81.3600","2.7104","4096.3853"
"","81.4400","2.7132","4097.4653"
"","81.5200","2.7158","4098.2363"
"","81.6000","2.7185","4099.7007"
"","81.6800","2.7210","4099.3979"
"","81.7600","2.7237","4099.9980"
"","81.8400","2.7264","4100.9053"
"","81.9200","2.7290","4100.9048"
"","82.0000","2.7318","4102.2627"
"","82.0800","2.7344","4101.8628"
"","82.1600","2.7370","4103.3140"
"","82.2400","2.7398","4105.0107"
"","82.3200","2.7424","4105.8140"
"","82.4000","2.7451","4107.2104"
"","82.4800","2.7477","4108.9048"
"","82.5600","2.7504","4111.0054"
"","82.6400","2.7532","4113.2065"
"","82.7200","2.7558","4109.7896"
"","82.8000","2.7584","4106.7114"
"","82.8800","2.7610","4105.1797"
"","82.9600","2.7638","4106.4043"
"","83.0400","2.7664","4106.3540"
"","83.1200","2.7690","4105.0513"
"","83.2000","2.7718","4105.0342"
"","83.2800","2.7743","4104.3105"
"","83.3600","2.7771","4105.0347"
"","83.4400","2.7798","4105.4985"
"","83.5200","2.7824","4105.3115"
"","83.6000","2.7851","4106.5952"
"","83.6800","2.7877","4107.1904"
"","83.7600","2.7904","4108.4644"
"","83.8400","2.7932","4110.4541"
"","83.9200","2.7957","4110.6919"
"","84.0000","2.7984","4111.0557"
"","84.0800","2.8011","4110.2861"
"","84.1600","2.8037","4110.2837"
"","84.2400","2.8065","4110.6733"
"","84.3200","2.8091","4110.5869"
"","84.4000","2.8117","4111.5435"
"","84.4800","2.8144","4112.7373"
"","84.5600","2.8171","4114.4912"
"","84.6400","2.8198","4114.8608"
"","84.7200","2.8224","4115.5234"
"","84.8000","2.8251","4115.8711"
"","84.8800","2.8277","4114.6992"
"","84.9600","2.8305","4114.1519"
"","85.0400","2.8332","4112.8599"
"","85.1200","2.8358","4111.6924"
"","85.2000","2.8384","4110.5791"
"","85.2800","2.8410","4109.7690"
"","85.3600","2.8438","4108.9365"
"","85.4400","2.8465","4108.8545"
"","85.5200","2.8490","4106.7593"
"","85.6000","2.8518","4105.3135"
"","85.6800","2.8544","4102.5811"
"","85.7600","2.8570","4100.4141"
"","85.8400","2.8598","4098.9761"
"","85.9200","2.8624","4094.9727"
"","86.0000","2.8651","4092.9458"
"","86.0800","2.8677","4090.7322"
"","86.1600","2.8704","4089.0637"
"","86.2400","2.8732","4087.4983"
"","86.3200","2.8758","4085.4106"
"","86.4000","2.8784","4083.1772"
"","86.4800","2.8810","4080.6143"
"","86.5600","2.8838","4079.9783"
"","86.6400","2.8864","4079.3276"
"","86.7200","2.8891","4078.8025"
"","86.8000","2.8917","4078.0913"
"","86.8800","2.8943","4076.9617"
"","86.9600","2.8971","4077.0601"
"","87.0400","2.8998","4076.8831"
"","87.1200","2.9024","4044.4626"
"","87.2000","2.9051","4033.2566"
"","87.2800","2.9077","4029.2793"
"","87.3600","2.9104","4026.8982"
"","87.4400","2.9132","4024.8628"
"","87.5200","2.9157","4021.9050"
"","87.6000","2.9184","4020.5217"
"","87.6800","2.9211","4019.1975"
"","87.7600","2.9237","4018.0210"
"","87.8400","2.9265","4016.8745"
"","87.9200","2.9290","4014.9099"
"","88.0000","2.9317","4013.9197"
"","88.0800","2.9344","4013.5002"
"","88.1600","2.9371","4012.9514"
"","88.2400","2.9398","4012.8098"
"","88.3200","2.9424","4012.1953"
"","88.4000","2.9451","3945.3689"
"","88.4800","2.9477","3935.6538"
"","88.5600","2.9505","3925.8887"
"","88.6400","2.9532","3921.0303"
"","88.7200","2.9558","3914.5029"
"","88.8000","2.9584","3909.0842"
"","88.8800","2.9610","3905.4658"
"","88.9600","2.9638","3903.6614"
"","89.0400","2.9665","3901.1082"
"","89.1200","2.9690","3897.9456"
"","89.2000","2.9718","3897.2354"
"","89.2800","2.9744","3896.1794"
"","89.3600","2.9771","3895.8611"
"","89.4400","2.9798","3896.7324"
"","89.5200","2.9824","3896.9868"
"","89.6000","2.9851","3897.4316"
"","89.6800","2.9877","3897.5476"
"","89.7600","2.9904","3897.8889"
"","89.8400","2.9932","3897.7805"
"","89.9200","2.9958","3897.6123"
"","90.0000","2.9984","3897.0854"
"","90.0800","3.0011","3898.2585"
"","90.1600","3.0038","3899.5898"
"","90.2400","3.0064","3900.6450"
"","90.3200","3.0091","3894.1829"
"","90.4000","3.0117","3851.3855"
"","90.4800","3.0144","3844.8215"
"","90.5600","3.0171","3839.4795"
"","90.6400","3.0198","3835.0798"
"","90.7200","3.0224","3831.8120"
"","90.8000","3.0251","3830.4841"
"","90.8800","3.0277","3829.3730"
"","90.9600","3.0305","3829.8047"
"","91.0400","3.0332","3829.8826"
"","91.1200","3.0357","3829.3188"
"","91.2000","3.0384","3830.1353"
"","91.2800","3.0411","3830.2207"
"","91.3600","3.0437","3830.6130"
"","91.4400","3.0465","3831.0505"
"","91.5200","3.0491","3829.2922"
"","91.6000","3.0517","3829.0740"
"","91.6800","3.0544","3829.9338"
"","91.7600","3.0571","3830.3208"
"","91.8400","3.0598","3827.7615"
"","91.9200","3.0624","3827.6184"
"","92.0000","3.0650","3827.1040"
"","92.0800","3.0677","3827.7827"
"","92.1600","3.0705","3828.4868"
"","92.2400","3.0731","3828.9048"
"","92.3200","3.0758","3823.0657"
"","92.4000","3.0784","3821.1299"
"","92.4800","3.0810","3820.4377"
"","92.5600","3.0838","3821.1929"
"","92.6400","3.0864","3822.1086"
"","92.7200","3.0890","3822.5886"
"","92.8000","3.0917","3823.8804"
"","92.8800","3.0944","3824.8826"
"","92.9600","3.0971","3826.3486"
"","93.0400","3.0998","3827.7214"
"","93.1200","3.1024","3828.7737"
"","93.2000","3.1051","3830.3264"
"","93.2800","3.1077","3831.5876"
"","93.3600","3.1104","3832.9988"
"","93.4400","3.1132","3834.2180"
"","93.5200","3.1158","3834.4673"
"","93.6000","3.1184","3835.1621"
"","93.6800","3.1210","3833.5999"
"","93.7600","3.1238","3834.0725"
"","93.8400","3.1264","3834.7576"
"","93.9200","3.1291","3834.1870"
"","94.0000","3.1317","3832.4963"
"","94.0800","3.1344","3832.4243"
"","94.1600","3.1371","3832.9832"
"","94.2400","3.1398","3832.5042"
"","94.3200","3.1424","3831.9775"
"","94.4000","3.1451","3832.0635"
"","94.4800","3.1477","3832.1443"
"","94.5600","3.1505","3832.7720"
"","94.6400","3.1532","3793.5137"
"","94.7200","3.1557","3769.2319"
"","94.8000","3.1584","3763.3831"
"","94.8800","3.1611","3759.8269"
"","94.9600","3.1638","3758.1335"
"","95.0400","3.1664","3756.0386"
"","95.1200","3.1690","3754.6394"
"","95.2000","3.1717","3754.1492"
"","95.2800","3.1744","3754.3279"
"","95.3600","3.1771","3754.1404"
"","95.4400","3.1798","3754.9329"
"","95.5200","3.1825","3755.8079"
"","95.6000","3.1850","3755.6682"
"","95.6800","3.1878","3755.9246"
"","95.7600","3.1905","3757.0715"
"","95.8400","3.1931","3756.7268"
"","95.9200","3.1958","3758.0151"
"","96.0000","3.1984","3758.7695"
"","96.0800","3.2010","3760.0232"
"","96.1600","3.2038","3762.2837"
"","96.2400","3.2064","3728.4758"
"","96.3200","3.2091","3721.9802"
"","96.4000","3.2117","3717.9119"
"","96.4800","3.2144","3715.1851"
"","96.5600","3.2171","3697.5149"
"","96.6400","3.2198","3683.3682"
"","96.7200","3.2224","3676.7654"
"","96.8000","3.2251","3672.3252"
"","96.8800","3.2278","3669.9587"
"","96.9600","3.2305","3668.1694"
"","97.0400","3.2332","3665.4731"
"","97.1200","3.2358","3663.1301"
"","97.2000","3.2384","3660.8516"
"","97.2800","3.2411","3659.7488"
"","97.3600","3.2438","3658.4702"
"","97.4400","3.2464","3654.8643"
"","97.5200","3.2491","3651.7764"
"","97.6000","3.2517","3646.2119"
"","97.6800","3.2544","3639.5017"
"","97.7600","3.2571","3632.7183"
"","97.8400","3.2597","3622.9426"
"","97.9200","3.2624","3613.4268"
"","98.0000","3.2651","3605.0242"
"","98.0800","3.2677","3597.9353"
"","98.1600","3.2705","3592.4934"
"","98.2400","3.2731","3586.8738"
"","98.3200","3.2758","3582.8545"
"","98.4000","3.2784","3578.9827"
"","98.4800","3.2811","3577.2578"
"","98.5600","3.2838","3576.7415"
"","98.6400","3.2864","3575.4658"
"","98.7200","3.2890","3574.6946"
"","98.8000","3.2917","3574.2271"
"","98.8800","3.2944","3567.0801"
"","98.9600","3.2971","3566.0112"
"","99.0400","3.2998","3566.1963"
"","99.1200","3.3024","3565.5073"
"","99.2000","3.3050","3565.4722"
"","99.2800","3.3078","3566.4917"
"","99.3600","3.3105","3567.1194"
"","99.4400","3.3131","3566.8792"
"","99.5200","3.3158","3567.8188"
"","99.6000","3.3184","3567.0413"
"","99.6800","3.3210","3568.2854"
"","99.7600","3.3238","3568.7368"
"","99.8400","3.3264","3568.3181"
"","99.9200","3.3291","3569.1594"
"","100.0000","3.3317","3568.2009"
"","100.0800","3.3343","3567.4553"
"","100.1600","3.3371","3568.7708"
"","100.2400","3.3398","3565.9617"
"","100.3200","3.3424","3565.2925"
"","100.4000","3.3451","3564.9929"
"","100.4800","3.3478","3565.3538"
"","100.5600","3.3505","3561.8584"
"","100.6400","3.3531","3561.2510"
"","100.7200","3.3558","3560.2285"
"","100.8000","3.3584","3557.5061"
"","100.8800","3.3611","3557.6145"
"","100.9600","3.3637","3517.9231"
"","101.0400","3.3664","3459.5615"
"","101.1200","3.3691","3447.4692"
"","101.2000","3.3717","3438.9795"
"","101.2800","3.3744","3434.8252"
"","101.3600","3.3771","3431.9858"
"","101.4400","3.3797","3430.2065"
"","101.5200","3.3824","3428.2861"
"","101.6000","3.3851","3427.7615"
"","101.6800","3.3877","3428.5361"
"","101.7600","3.3905","3428.5977"
"","101.8400","3.3931","3427.6868"
"","101.9200","3.3958","3427.6653"
"","102.0000","3.3984","3427.3408"
"","102.0800","3.4011","3427.0723"
"","102.1600","3.4038","3427.0986"
"","102.2400","3.4064","3426.7241"
"","102.3200","3.4090","3427.2639"
"","102.4000","3.4117","3428.5376"
"","102.4800","3.4144","3426.9956"
"","102.5600","3.4171","3423.0952"
"","102.6400","3.4198","3422.2048"
"","102.7200","3.4225","3422.3000"
"","102.8000","3.4250","3422.2280"
"","102.8800","3.4278","3423.4915"
"","102.9600","3.4305","3425.6138"
"","103.0400","3.4331","3426.3726"
"","103.1200","3.4358","3428.9163"
"","103.2000","3.4384","3430.0154"
"","103.2800","3.4411","3431.7012"
"","103.3600","3.4438","3432.9932"
"","103.4400","3.4464","3433.6841"
"","103.5200","3.4491","3435.5593"
"","103.6000","3.4517","3437.0647"
"","103.6800","3.4544","3438.6763"
"","103.7600","3.4571","3441.3362"
"","103.8400","3.4598","3443.3862"
"","103.9200","3.4624","3445.0376"
"","104.0000","3.4651","3446.8735"
"","104.0800","3.4678","3449.1648"
"","104.1600","3.4705","3451.1326"
"","104.2400","3.4731","3452.2322"
"","104.3200","3.4758","3451.1738"
"","104.4000","3.4784","3450.5090"
"","104.4800","3.4811","3448.9880"
"","104.5600","3.4838","3448.2141"
"","104.6400","3.4864","3447.6238"
"","104.7200","3.4891","3447.9290"
"","104.8000","3.4917","3448.2324"
"","104.8800","3.4944","3449.4814"
"","104.9600","3.4971","3450.6550"
"","105.0400","3.4997","3450.3296"
"","105.1200","3.5024","3451.9187"
"","105.2000","3.5051","3409.4712"
"","105.2800","3.5078","3397.0918"
"","105.3600","3.5105","3392.4746"
"","105.4400","3.5131","3388.0740"
"","105.5200","3.5158","3386.7732"
"","105.6000","3.5184","3386.2075"
"","105.6800","3.5211","3385.8818"
"","105.7600","3.5238","3386.8010"
"","105.8400","3.5264","3387.0432"
"","105.9200","3.5290","3387.6169"
"","106.0000","3.5317","3389.2332"
"","106.0800","3.5344","3390.1958"
"","106.1600","3.5371","3384.8391"
"","106.2400","3.5398","3382.2366"
"","106.3200","3.5424","3379.8394"
"","106.4000","3.5450","3368.8303"
"","106.4800","3.5478","3364.2976"
"","106.5600","3.5505","3362.2969"
"","106.6400","3.5531","3359.3940"
"","106.7200","3.5558","3358.4016"
"","106.8000","3.5583","3356.8000"
"","106.8800","3.5611","3357.4023"
"","106.9600","3.5638","3355.9575"
"","107.0400","3.5664","3353.9541"
"","107.1200","3.5691","3354.4019"
"","107.2000","3.5717","3354.5054"
"","107.2800","3.5744","3355.7178"
"","107.3600","3.5771","3357.0149"
"","107.4400","3.5798","3357.0979"
"","107.5200","3.5824","3357.9392"
"","107.6000","3.5850","3341.8743"
"","107.6800","3.5878","3324.0969"
"","107.7600","3.5905","3316.3921"
"","107.8400","3.5931","3302.1116"
"","107.9200","3.5957","3294.6948"
"","108.0000","3.5984","3287.4880"
"","108.0800","3.6011","3279.4917"
"","108.1600","3.6038","3272.2810"
"","108.2400","3.6064","3265.2197"
"","108.3200","3.6091","3246.8577"
"","108.4000","3.6117","3238.4631"
"","108.4800","3.6144","3234.9451"
"","108.5600","3.6171","3232.0422"
"","108.6400","3.6197","3227.3521"
"","108.7200","3.6224","3224.4089"
"","108.8000","3.6250","3218.6624"
"","108.8800","3.6278","3217.4880"
"","108.9600","3.6305","3217.1807"
"","109.0400","3.6331","3216.6050"
"","109.1200","3.6358","3214.3152"
"","109.2000","3.6384","3213.5630"
"","109.2800","3.6411","3213.2542"
"","109.3600","3.6438","3213.7336"
"","109.4400","3.6464","3214.3325"
"","109.5200","3.6491","3214.4333"
"","109.6000","3.6517","3214.4414"
"","109.6800","3.6544","3214.8743"
"","109.7600","3.6571","3214.7893"
"","109.8400","3.6598","3211.6479"
"","109.9200","3.6624","3210.7104"
"","110.0000","3.6651","3210.3237"
"","110.0800","3.6678","3210.6638"
"","110.1600","3.6705","3209.4163"
"","110.2400","3.6731","3199.1233"
"","110.3200","3.6758","3192.3040"
"","110.4000","3.6783","3188.5835"
"","110.4800","3.6811","3187.2869"
"","110.5600","3.6838","3185.0051"
"","110.6400","3.6864","3182.9219"
"","110.7200","3.6891","3182.9622"
"","110.8000","3.6917","3182.3545"
"","110.8800","3.6944","3181.8484"
"","110.9600","3.6971","3182.4365"
"","111.0400","3.6997","3181.3174"
"","111.1200","3.7024","3181.7253"
"","111.2000","3.7051","3182.7000"
"","111.2800","3.7078","3183.9480"
"","111.3600","3.7105","3185.0408"
"","111.4400","3.7131","3184.1992"
"","111.5200","3.7157","3180.7190"
"","111.6000","3.7184","3159.8289"
"","111.6800","3.7211","3028.5017"
"","111.7600","3.7238","2515.4495"
"","111.8400","3.7264","2523.9810"
"","111.9200","3.7291","2521.7380"
"","112.0000","3.7317","2522.2351"
"","112.0800","3.7344","2524.4873"
"","112.1600","3.7371","2526.4612"
"","112.2400","3.7398","2529.2024"
"","112.3200","3.7424","2532.3772"
"","112.4000","3.7450","2535.1326"
"","112.4800","3.7478","2538.8982"
"","112.5600","3.7505","2541.8403"
"","112.6400","3.7531","2543.7371"
"","112.7200","3.7558","2540.5977"
"","112.8000","3.7584","2535.8865"
"","112.8800","3.7611","2535.0730"
"","112.9600","3.7638","2535.5217"
"","113.0400","3.7664","2536.5508"
"","113.1200","3.7690","2537.4766"
"","113.2000","3.7717","2538.7451"
"","113.2800","3.7744","2540.0049"
"","113.3600","3.7771","2539.7395"
"","113.4400","3.7798","2537.3862"
"","113.5200","3.7824","2535.2175"
"","113.6000","3.7851","2534.5532"
"","113.6800","3.7878","2534.7322"
"","113.7600","3.7905","2534.4185"
"","113.8400","3.7931","2533.8162"
"","113.9200","3.7958","2533.3218"
"","114.0000","3.7983","2515.3152"
"","114.0800","3.8011","2482.3025"
"","114.1600","3.8038","2481.6807"
"","114.2400","3.8064","2481.3440"
"","114.3200","3.8091","2482.6282"
"","114.4000","3.8117","2483.3240"
"","114.4800","3.8144","2485.5894"
"","114.5600","3.8171","2483.2615"
"","114.6400","3.8197","2483.9917"
"","114.7200","3.8224","2485.5186"
"","114.8000","3.8251","2486.9548"
"","114.8800","3.8278","2487.8596"
"","114.9600","3.8305","2489.5046"
"","115.0400","3.8331","2489.4775"
"","115.1200","3.8357","2490.6943"
"","115.2000","3.8384","2492.8098"
"","115.2800","3.8411","2495.2659"
"","115.3600","3.8437","2496.8306"
"","115.4400","3.8464","2499.2505"
"","115.5200","3.8491","2500.8635"
"","115.6000","3.8517","2503.0823"
"","115.6800","3.8544","2505.1572"
"","115.7600","3.8571","2506.2864"
"","115.8400","3.8598","2508.3533"
"","115.9200","3.8624","2509.9014"
"","116.0000","3.8650","2504.2886"
"","116.0800","3.8678","2495.3516"
"","116.1600","3.8705","2489.4946"
"","116.2400","3.8730","2490.2175"
"","116.3200","3.8758","2491.3701"
"","116.4000","3.8784","2492.7546"
"","116.4800","3.8811","2493.8103"
"","116.5600","3.8838","2485.1707"
"","116.6400","3.8864","2483.3977"
"","116.7200","3.8890","2483.9619"
"","116.8000","3.8917","2483.8701"
"","116.8460","3.8933","2483.7957"